[2025-07-12T01:35:11.619+0000] {processor.py:161} INFO - Started process (PID=60) to work on /opt/airflow/dags/flight_etl_dag.py
[2025-07-12T01:35:11.621+0000] {processor.py:830} INFO - Processing file /opt/airflow/dags/flight_etl_dag.py for tasks to queue
[2025-07-12T01:35:11.625+0000] {logging_mixin.py:188} INFO - [2025-07-12T01:35:11.625+0000] {dagbag.py:538} INFO - Filling up the DagBag from /opt/airflow/dags/flight_etl_dag.py
[2025-07-12T01:35:12.481+0000] {logging_mixin.py:188} INFO - [2025-07-12T01:35:12.464+0000] {dagbag.py:348} ERROR - Failed to import: /opt/airflow/dags/flight_etl_dag.py
Traceback (most recent call last):
  File "/home/airflow/.local/lib/python3.8/site-packages/requests/models.py", line 971, in json
    return complexjson.loads(self.text, **kwargs)
  File "/usr/local/lib/python3.8/json/__init__.py", line 357, in loads
    return _default_decoder.decode(s)
  File "/usr/local/lib/python3.8/json/decoder.py", line 337, in decode
    obj, end = self.raw_decode(s, idx=_w(s, 0).end())
  File "/usr/local/lib/python3.8/json/decoder.py", line 355, in raw_decode
    raise JSONDecodeError("Expecting value", s, err.value) from None
json.decoder.JSONDecodeError: Expecting value: line 1 column 1 (char 0)

During handling of the above exception, another exception occurred:

Traceback (most recent call last):
  File "/home/airflow/.local/lib/python3.8/site-packages/airflow/models/dagbag.py", line 344, in parse
    loader.exec_module(new_module)
  File "<frozen importlib._bootstrap_external>", line 843, in exec_module
  File "<frozen importlib._bootstrap>", line 219, in _call_with_frames_removed
  File "/opt/airflow/dags/flight_etl_dag.py", line 8, in <module>
    from extract import extract
  File "/opt/airflow/extract.py", line 21, in <module>
    extract()
  File "/opt/airflow/extract.py", line 7, in extract
    data=response.json()
  File "/home/airflow/.local/lib/python3.8/site-packages/requests/models.py", line 975, in json
    raise RequestsJSONDecodeError(e.msg, e.doc, e.pos)
requests.exceptions.JSONDecodeError: Expecting value: line 1 column 1 (char 0)
[2025-07-12T01:35:12.485+0000] {processor.py:842} WARNING - No viable dags retrieved from /opt/airflow/dags/flight_etl_dag.py
[2025-07-12T01:35:12.511+0000] {processor.py:183} INFO - Processing /opt/airflow/dags/flight_etl_dag.py took 0.899 seconds
[2025-07-12T01:35:42.947+0000] {processor.py:161} INFO - Started process (PID=123) to work on /opt/airflow/dags/flight_etl_dag.py
[2025-07-12T01:35:42.948+0000] {processor.py:830} INFO - Processing file /opt/airflow/dags/flight_etl_dag.py for tasks to queue
[2025-07-12T01:35:42.951+0000] {logging_mixin.py:188} INFO - [2025-07-12T01:35:42.951+0000] {dagbag.py:538} INFO - Filling up the DagBag from /opt/airflow/dags/flight_etl_dag.py
[2025-07-12T01:35:43.652+0000] {logging_mixin.py:188} INFO - [2025-07-12T01:35:43.629+0000] {dagbag.py:348} ERROR - Failed to import: /opt/airflow/dags/flight_etl_dag.py
Traceback (most recent call last):
  File "/home/airflow/.local/lib/python3.8/site-packages/requests/models.py", line 971, in json
    return complexjson.loads(self.text, **kwargs)
  File "/usr/local/lib/python3.8/json/__init__.py", line 357, in loads
    return _default_decoder.decode(s)
  File "/usr/local/lib/python3.8/json/decoder.py", line 337, in decode
    obj, end = self.raw_decode(s, idx=_w(s, 0).end())
  File "/usr/local/lib/python3.8/json/decoder.py", line 355, in raw_decode
    raise JSONDecodeError("Expecting value", s, err.value) from None
json.decoder.JSONDecodeError: Expecting value: line 1 column 1 (char 0)

During handling of the above exception, another exception occurred:

Traceback (most recent call last):
  File "/home/airflow/.local/lib/python3.8/site-packages/airflow/models/dagbag.py", line 344, in parse
    loader.exec_module(new_module)
  File "<frozen importlib._bootstrap_external>", line 843, in exec_module
  File "<frozen importlib._bootstrap>", line 219, in _call_with_frames_removed
  File "/opt/airflow/dags/flight_etl_dag.py", line 8, in <module>
    from extract import extract
  File "/opt/airflow/extract.py", line 21, in <module>
    extract()
  File "/opt/airflow/extract.py", line 7, in extract
    data=response.json()
  File "/home/airflow/.local/lib/python3.8/site-packages/requests/models.py", line 975, in json
    raise RequestsJSONDecodeError(e.msg, e.doc, e.pos)
requests.exceptions.JSONDecodeError: Expecting value: line 1 column 1 (char 0)
[2025-07-12T01:35:43.657+0000] {processor.py:842} WARNING - No viable dags retrieved from /opt/airflow/dags/flight_etl_dag.py
[2025-07-12T01:35:43.694+0000] {processor.py:183} INFO - Processing /opt/airflow/dags/flight_etl_dag.py took 0.751 seconds
[2025-07-12T01:36:14.406+0000] {processor.py:161} INFO - Started process (PID=181) to work on /opt/airflow/dags/flight_etl_dag.py
[2025-07-12T01:36:14.407+0000] {processor.py:830} INFO - Processing file /opt/airflow/dags/flight_etl_dag.py for tasks to queue
[2025-07-12T01:36:14.409+0000] {logging_mixin.py:188} INFO - [2025-07-12T01:36:14.409+0000] {dagbag.py:538} INFO - Filling up the DagBag from /opt/airflow/dags/flight_etl_dag.py
[2025-07-12T01:36:15.053+0000] {logging_mixin.py:188} INFO - [2025-07-12T01:36:15.041+0000] {dagbag.py:348} ERROR - Failed to import: /opt/airflow/dags/flight_etl_dag.py
Traceback (most recent call last):
  File "/home/airflow/.local/lib/python3.8/site-packages/requests/models.py", line 971, in json
    return complexjson.loads(self.text, **kwargs)
  File "/usr/local/lib/python3.8/json/__init__.py", line 357, in loads
    return _default_decoder.decode(s)
  File "/usr/local/lib/python3.8/json/decoder.py", line 337, in decode
    obj, end = self.raw_decode(s, idx=_w(s, 0).end())
  File "/usr/local/lib/python3.8/json/decoder.py", line 355, in raw_decode
    raise JSONDecodeError("Expecting value", s, err.value) from None
json.decoder.JSONDecodeError: Expecting value: line 1 column 1 (char 0)

During handling of the above exception, another exception occurred:

Traceback (most recent call last):
  File "/home/airflow/.local/lib/python3.8/site-packages/airflow/models/dagbag.py", line 344, in parse
    loader.exec_module(new_module)
  File "<frozen importlib._bootstrap_external>", line 843, in exec_module
  File "<frozen importlib._bootstrap>", line 219, in _call_with_frames_removed
  File "/opt/airflow/dags/flight_etl_dag.py", line 8, in <module>
    from extract import extract
  File "/opt/airflow/extract.py", line 21, in <module>
    extract()
  File "/opt/airflow/extract.py", line 7, in extract
    data=response.json()
  File "/home/airflow/.local/lib/python3.8/site-packages/requests/models.py", line 975, in json
    raise RequestsJSONDecodeError(e.msg, e.doc, e.pos)
requests.exceptions.JSONDecodeError: Expecting value: line 1 column 1 (char 0)
[2025-07-12T01:36:15.056+0000] {processor.py:842} WARNING - No viable dags retrieved from /opt/airflow/dags/flight_etl_dag.py
[2025-07-12T01:36:15.079+0000] {processor.py:183} INFO - Processing /opt/airflow/dags/flight_etl_dag.py took 0.677 seconds
[2025-07-12T01:36:45.375+0000] {processor.py:161} INFO - Started process (PID=240) to work on /opt/airflow/dags/flight_etl_dag.py
[2025-07-12T01:36:45.377+0000] {processor.py:830} INFO - Processing file /opt/airflow/dags/flight_etl_dag.py for tasks to queue
[2025-07-12T01:36:45.380+0000] {logging_mixin.py:188} INFO - [2025-07-12T01:36:45.379+0000] {dagbag.py:538} INFO - Filling up the DagBag from /opt/airflow/dags/flight_etl_dag.py
[2025-07-12T01:36:45.975+0000] {logging_mixin.py:188} INFO - [2025-07-12T01:36:45.960+0000] {dagbag.py:348} ERROR - Failed to import: /opt/airflow/dags/flight_etl_dag.py
Traceback (most recent call last):
  File "/home/airflow/.local/lib/python3.8/site-packages/requests/models.py", line 971, in json
    return complexjson.loads(self.text, **kwargs)
  File "/usr/local/lib/python3.8/json/__init__.py", line 357, in loads
    return _default_decoder.decode(s)
  File "/usr/local/lib/python3.8/json/decoder.py", line 337, in decode
    obj, end = self.raw_decode(s, idx=_w(s, 0).end())
  File "/usr/local/lib/python3.8/json/decoder.py", line 355, in raw_decode
    raise JSONDecodeError("Expecting value", s, err.value) from None
json.decoder.JSONDecodeError: Expecting value: line 1 column 1 (char 0)

During handling of the above exception, another exception occurred:

Traceback (most recent call last):
  File "/home/airflow/.local/lib/python3.8/site-packages/airflow/models/dagbag.py", line 344, in parse
    loader.exec_module(new_module)
  File "<frozen importlib._bootstrap_external>", line 843, in exec_module
  File "<frozen importlib._bootstrap>", line 219, in _call_with_frames_removed
  File "/opt/airflow/dags/flight_etl_dag.py", line 8, in <module>
    from extract import extract
  File "/opt/airflow/extract.py", line 21, in <module>
    extract()
  File "/opt/airflow/extract.py", line 7, in extract
    data=response.json()
  File "/home/airflow/.local/lib/python3.8/site-packages/requests/models.py", line 975, in json
    raise RequestsJSONDecodeError(e.msg, e.doc, e.pos)
requests.exceptions.JSONDecodeError: Expecting value: line 1 column 1 (char 0)
[2025-07-12T01:36:45.979+0000] {processor.py:842} WARNING - No viable dags retrieved from /opt/airflow/dags/flight_etl_dag.py
[2025-07-12T01:36:46.004+0000] {processor.py:183} INFO - Processing /opt/airflow/dags/flight_etl_dag.py took 0.633 seconds
[2025-07-12T01:37:16.119+0000] {processor.py:161} INFO - Started process (PID=298) to work on /opt/airflow/dags/flight_etl_dag.py
[2025-07-12T01:37:16.122+0000] {processor.py:830} INFO - Processing file /opt/airflow/dags/flight_etl_dag.py for tasks to queue
[2025-07-12T01:37:16.128+0000] {logging_mixin.py:188} INFO - [2025-07-12T01:37:16.127+0000] {dagbag.py:538} INFO - Filling up the DagBag from /opt/airflow/dags/flight_etl_dag.py
[2025-07-12T01:37:16.868+0000] {logging_mixin.py:188} INFO - [2025-07-12T01:37:16.834+0000] {dagbag.py:348} ERROR - Failed to import: /opt/airflow/dags/flight_etl_dag.py
Traceback (most recent call last):
  File "/home/airflow/.local/lib/python3.8/site-packages/requests/models.py", line 971, in json
    return complexjson.loads(self.text, **kwargs)
  File "/usr/local/lib/python3.8/json/__init__.py", line 357, in loads
    return _default_decoder.decode(s)
  File "/usr/local/lib/python3.8/json/decoder.py", line 337, in decode
    obj, end = self.raw_decode(s, idx=_w(s, 0).end())
  File "/usr/local/lib/python3.8/json/decoder.py", line 355, in raw_decode
    raise JSONDecodeError("Expecting value", s, err.value) from None
json.decoder.JSONDecodeError: Expecting value: line 1 column 1 (char 0)

During handling of the above exception, another exception occurred:

Traceback (most recent call last):
  File "/home/airflow/.local/lib/python3.8/site-packages/airflow/models/dagbag.py", line 344, in parse
    loader.exec_module(new_module)
  File "<frozen importlib._bootstrap_external>", line 843, in exec_module
  File "<frozen importlib._bootstrap>", line 219, in _call_with_frames_removed
  File "/opt/airflow/dags/flight_etl_dag.py", line 8, in <module>
    from extract import extract
  File "/opt/airflow/extract.py", line 21, in <module>
    extract()
  File "/opt/airflow/extract.py", line 7, in extract
    data=response.json()
  File "/home/airflow/.local/lib/python3.8/site-packages/requests/models.py", line 975, in json
    raise RequestsJSONDecodeError(e.msg, e.doc, e.pos)
requests.exceptions.JSONDecodeError: Expecting value: line 1 column 1 (char 0)
[2025-07-12T01:37:16.875+0000] {processor.py:842} WARNING - No viable dags retrieved from /opt/airflow/dags/flight_etl_dag.py
[2025-07-12T01:37:16.928+0000] {processor.py:183} INFO - Processing /opt/airflow/dags/flight_etl_dag.py took 0.816 seconds
[2025-07-12T01:38:30.429+0000] {processor.py:161} INFO - Started process (PID=60) to work on /opt/airflow/dags/flight_etl_dag.py
[2025-07-12T01:38:30.432+0000] {processor.py:830} INFO - Processing file /opt/airflow/dags/flight_etl_dag.py for tasks to queue
[2025-07-12T01:38:30.438+0000] {logging_mixin.py:188} INFO - [2025-07-12T01:38:30.437+0000] {dagbag.py:538} INFO - Filling up the DagBag from /opt/airflow/dags/flight_etl_dag.py
[2025-07-12T01:38:31.071+0000] {logging_mixin.py:188} INFO - [2025-07-12T01:38:31.048+0000] {dagbag.py:348} ERROR - Failed to import: /opt/airflow/dags/flight_etl_dag.py
Traceback (most recent call last):
  File "/home/airflow/.local/lib/python3.8/site-packages/requests/models.py", line 971, in json
    return complexjson.loads(self.text, **kwargs)
  File "/usr/local/lib/python3.8/json/__init__.py", line 357, in loads
    return _default_decoder.decode(s)
  File "/usr/local/lib/python3.8/json/decoder.py", line 337, in decode
    obj, end = self.raw_decode(s, idx=_w(s, 0).end())
  File "/usr/local/lib/python3.8/json/decoder.py", line 355, in raw_decode
    raise JSONDecodeError("Expecting value", s, err.value) from None
json.decoder.JSONDecodeError: Expecting value: line 1 column 1 (char 0)

During handling of the above exception, another exception occurred:

Traceback (most recent call last):
  File "/home/airflow/.local/lib/python3.8/site-packages/airflow/models/dagbag.py", line 344, in parse
    loader.exec_module(new_module)
  File "<frozen importlib._bootstrap_external>", line 843, in exec_module
  File "<frozen importlib._bootstrap>", line 219, in _call_with_frames_removed
  File "/opt/airflow/dags/flight_etl_dag.py", line 8, in <module>
    from extract import extract
  File "/opt/airflow/extract.py", line 21, in <module>
    extract()
  File "/opt/airflow/extract.py", line 7, in extract
    data=response.json()
  File "/home/airflow/.local/lib/python3.8/site-packages/requests/models.py", line 975, in json
    raise RequestsJSONDecodeError(e.msg, e.doc, e.pos)
requests.exceptions.JSONDecodeError: Expecting value: line 1 column 1 (char 0)
[2025-07-12T01:38:31.075+0000] {processor.py:842} WARNING - No viable dags retrieved from /opt/airflow/dags/flight_etl_dag.py
[2025-07-12T01:38:31.112+0000] {processor.py:183} INFO - Processing /opt/airflow/dags/flight_etl_dag.py took 0.687 seconds
[2025-07-12T01:39:01.881+0000] {processor.py:161} INFO - Started process (PID=122) to work on /opt/airflow/dags/flight_etl_dag.py
[2025-07-12T01:39:01.883+0000] {processor.py:830} INFO - Processing file /opt/airflow/dags/flight_etl_dag.py for tasks to queue
[2025-07-12T01:39:01.886+0000] {logging_mixin.py:188} INFO - [2025-07-12T01:39:01.885+0000] {dagbag.py:538} INFO - Filling up the DagBag from /opt/airflow/dags/flight_etl_dag.py
[2025-07-12T01:39:02.583+0000] {logging_mixin.py:188} INFO - [2025-07-12T01:39:02.565+0000] {dagbag.py:348} ERROR - Failed to import: /opt/airflow/dags/flight_etl_dag.py
Traceback (most recent call last):
  File "/home/airflow/.local/lib/python3.8/site-packages/requests/models.py", line 971, in json
    return complexjson.loads(self.text, **kwargs)
  File "/usr/local/lib/python3.8/json/__init__.py", line 357, in loads
    return _default_decoder.decode(s)
  File "/usr/local/lib/python3.8/json/decoder.py", line 337, in decode
    obj, end = self.raw_decode(s, idx=_w(s, 0).end())
  File "/usr/local/lib/python3.8/json/decoder.py", line 355, in raw_decode
    raise JSONDecodeError("Expecting value", s, err.value) from None
json.decoder.JSONDecodeError: Expecting value: line 1 column 1 (char 0)

During handling of the above exception, another exception occurred:

Traceback (most recent call last):
  File "/home/airflow/.local/lib/python3.8/site-packages/airflow/models/dagbag.py", line 344, in parse
    loader.exec_module(new_module)
  File "<frozen importlib._bootstrap_external>", line 843, in exec_module
  File "<frozen importlib._bootstrap>", line 219, in _call_with_frames_removed
  File "/opt/airflow/dags/flight_etl_dag.py", line 8, in <module>
    from extract import extract
  File "/opt/airflow/extract.py", line 21, in <module>
    extract()
  File "/opt/airflow/extract.py", line 7, in extract
    data=response.json()
  File "/home/airflow/.local/lib/python3.8/site-packages/requests/models.py", line 975, in json
    raise RequestsJSONDecodeError(e.msg, e.doc, e.pos)
requests.exceptions.JSONDecodeError: Expecting value: line 1 column 1 (char 0)
[2025-07-12T01:39:02.587+0000] {processor.py:842} WARNING - No viable dags retrieved from /opt/airflow/dags/flight_etl_dag.py
[2025-07-12T01:39:02.617+0000] {processor.py:183} INFO - Processing /opt/airflow/dags/flight_etl_dag.py took 0.740 seconds
[2025-07-12T01:39:32.782+0000] {processor.py:161} INFO - Started process (PID=182) to work on /opt/airflow/dags/flight_etl_dag.py
[2025-07-12T01:39:32.783+0000] {processor.py:830} INFO - Processing file /opt/airflow/dags/flight_etl_dag.py for tasks to queue
[2025-07-12T01:39:32.785+0000] {logging_mixin.py:188} INFO - [2025-07-12T01:39:32.785+0000] {dagbag.py:538} INFO - Filling up the DagBag from /opt/airflow/dags/flight_etl_dag.py
[2025-07-12T01:39:33.439+0000] {logging_mixin.py:188} INFO - [2025-07-12T01:39:33.425+0000] {dagbag.py:348} ERROR - Failed to import: /opt/airflow/dags/flight_etl_dag.py
Traceback (most recent call last):
  File "/home/airflow/.local/lib/python3.8/site-packages/requests/models.py", line 971, in json
    return complexjson.loads(self.text, **kwargs)
  File "/usr/local/lib/python3.8/json/__init__.py", line 357, in loads
    return _default_decoder.decode(s)
  File "/usr/local/lib/python3.8/json/decoder.py", line 337, in decode
    obj, end = self.raw_decode(s, idx=_w(s, 0).end())
  File "/usr/local/lib/python3.8/json/decoder.py", line 355, in raw_decode
    raise JSONDecodeError("Expecting value", s, err.value) from None
json.decoder.JSONDecodeError: Expecting value: line 1 column 1 (char 0)

During handling of the above exception, another exception occurred:

Traceback (most recent call last):
  File "/home/airflow/.local/lib/python3.8/site-packages/airflow/models/dagbag.py", line 344, in parse
    loader.exec_module(new_module)
  File "<frozen importlib._bootstrap_external>", line 843, in exec_module
  File "<frozen importlib._bootstrap>", line 219, in _call_with_frames_removed
  File "/opt/airflow/dags/flight_etl_dag.py", line 8, in <module>
    from extract import extract
  File "/opt/airflow/extract.py", line 21, in <module>
    extract()
  File "/opt/airflow/extract.py", line 7, in extract
    data=response.json()
  File "/home/airflow/.local/lib/python3.8/site-packages/requests/models.py", line 975, in json
    raise RequestsJSONDecodeError(e.msg, e.doc, e.pos)
requests.exceptions.JSONDecodeError: Expecting value: line 1 column 1 (char 0)
[2025-07-12T01:39:33.442+0000] {processor.py:842} WARNING - No viable dags retrieved from /opt/airflow/dags/flight_etl_dag.py
[2025-07-12T01:39:33.468+0000] {processor.py:183} INFO - Processing /opt/airflow/dags/flight_etl_dag.py took 0.690 seconds
[2025-07-12T01:40:04.243+0000] {processor.py:161} INFO - Started process (PID=239) to work on /opt/airflow/dags/flight_etl_dag.py
[2025-07-12T01:40:04.245+0000] {processor.py:830} INFO - Processing file /opt/airflow/dags/flight_etl_dag.py for tasks to queue
[2025-07-12T01:40:04.248+0000] {logging_mixin.py:188} INFO - [2025-07-12T01:40:04.247+0000] {dagbag.py:538} INFO - Filling up the DagBag from /opt/airflow/dags/flight_etl_dag.py
[2025-07-12T01:40:04.779+0000] {logging_mixin.py:188} INFO - [2025-07-12T01:40:04.765+0000] {dagbag.py:348} ERROR - Failed to import: /opt/airflow/dags/flight_etl_dag.py
Traceback (most recent call last):
  File "/home/airflow/.local/lib/python3.8/site-packages/requests/models.py", line 971, in json
    return complexjson.loads(self.text, **kwargs)
  File "/usr/local/lib/python3.8/json/__init__.py", line 357, in loads
    return _default_decoder.decode(s)
  File "/usr/local/lib/python3.8/json/decoder.py", line 337, in decode
    obj, end = self.raw_decode(s, idx=_w(s, 0).end())
  File "/usr/local/lib/python3.8/json/decoder.py", line 355, in raw_decode
    raise JSONDecodeError("Expecting value", s, err.value) from None
json.decoder.JSONDecodeError: Expecting value: line 1 column 1 (char 0)

During handling of the above exception, another exception occurred:

Traceback (most recent call last):
  File "/home/airflow/.local/lib/python3.8/site-packages/airflow/models/dagbag.py", line 344, in parse
    loader.exec_module(new_module)
  File "<frozen importlib._bootstrap_external>", line 843, in exec_module
  File "<frozen importlib._bootstrap>", line 219, in _call_with_frames_removed
  File "/opt/airflow/dags/flight_etl_dag.py", line 8, in <module>
    from extract import extract
  File "/opt/airflow/extract.py", line 21, in <module>
    extract()
  File "/opt/airflow/extract.py", line 7, in extract
    data=response.json()
  File "/home/airflow/.local/lib/python3.8/site-packages/requests/models.py", line 975, in json
    raise RequestsJSONDecodeError(e.msg, e.doc, e.pos)
requests.exceptions.JSONDecodeError: Expecting value: line 1 column 1 (char 0)
[2025-07-12T01:40:04.783+0000] {processor.py:842} WARNING - No viable dags retrieved from /opt/airflow/dags/flight_etl_dag.py
[2025-07-12T01:40:04.810+0000] {processor.py:183} INFO - Processing /opt/airflow/dags/flight_etl_dag.py took 0.572 seconds
[2025-07-12T01:40:34.933+0000] {processor.py:161} INFO - Started process (PID=298) to work on /opt/airflow/dags/flight_etl_dag.py
[2025-07-12T01:40:34.935+0000] {processor.py:830} INFO - Processing file /opt/airflow/dags/flight_etl_dag.py for tasks to queue
[2025-07-12T01:40:34.939+0000] {logging_mixin.py:188} INFO - [2025-07-12T01:40:34.938+0000] {dagbag.py:538} INFO - Filling up the DagBag from /opt/airflow/dags/flight_etl_dag.py
[2025-07-12T01:40:35.591+0000] {logging_mixin.py:188} INFO - [2025-07-12T01:40:35.570+0000] {dagbag.py:348} ERROR - Failed to import: /opt/airflow/dags/flight_etl_dag.py
Traceback (most recent call last):
  File "/home/airflow/.local/lib/python3.8/site-packages/requests/models.py", line 971, in json
    return complexjson.loads(self.text, **kwargs)
  File "/usr/local/lib/python3.8/json/__init__.py", line 357, in loads
    return _default_decoder.decode(s)
  File "/usr/local/lib/python3.8/json/decoder.py", line 337, in decode
    obj, end = self.raw_decode(s, idx=_w(s, 0).end())
  File "/usr/local/lib/python3.8/json/decoder.py", line 355, in raw_decode
    raise JSONDecodeError("Expecting value", s, err.value) from None
json.decoder.JSONDecodeError: Expecting value: line 1 column 1 (char 0)

During handling of the above exception, another exception occurred:

Traceback (most recent call last):
  File "/home/airflow/.local/lib/python3.8/site-packages/airflow/models/dagbag.py", line 344, in parse
    loader.exec_module(new_module)
  File "<frozen importlib._bootstrap_external>", line 843, in exec_module
  File "<frozen importlib._bootstrap>", line 219, in _call_with_frames_removed
  File "/opt/airflow/dags/flight_etl_dag.py", line 8, in <module>
    from extract import extract
  File "/opt/airflow/extract.py", line 21, in <module>
    extract()
  File "/opt/airflow/extract.py", line 7, in extract
    data=response.json()
  File "/home/airflow/.local/lib/python3.8/site-packages/requests/models.py", line 975, in json
    raise RequestsJSONDecodeError(e.msg, e.doc, e.pos)
requests.exceptions.JSONDecodeError: Expecting value: line 1 column 1 (char 0)
[2025-07-12T01:40:35.595+0000] {processor.py:842} WARNING - No viable dags retrieved from /opt/airflow/dags/flight_etl_dag.py
[2025-07-12T01:40:35.633+0000] {processor.py:183} INFO - Processing /opt/airflow/dags/flight_etl_dag.py took 0.708 seconds
[2025-07-12T01:41:06.103+0000] {processor.py:161} INFO - Started process (PID=355) to work on /opt/airflow/dags/flight_etl_dag.py
[2025-07-12T01:41:06.105+0000] {processor.py:830} INFO - Processing file /opt/airflow/dags/flight_etl_dag.py for tasks to queue
[2025-07-12T01:41:06.107+0000] {logging_mixin.py:188} INFO - [2025-07-12T01:41:06.107+0000] {dagbag.py:538} INFO - Filling up the DagBag from /opt/airflow/dags/flight_etl_dag.py
[2025-07-12T01:41:06.744+0000] {logging_mixin.py:188} INFO - [2025-07-12T01:41:06.717+0000] {dagbag.py:348} ERROR - Failed to import: /opt/airflow/dags/flight_etl_dag.py
Traceback (most recent call last):
  File "/home/airflow/.local/lib/python3.8/site-packages/requests/models.py", line 971, in json
    return complexjson.loads(self.text, **kwargs)
  File "/usr/local/lib/python3.8/json/__init__.py", line 357, in loads
    return _default_decoder.decode(s)
  File "/usr/local/lib/python3.8/json/decoder.py", line 337, in decode
    obj, end = self.raw_decode(s, idx=_w(s, 0).end())
  File "/usr/local/lib/python3.8/json/decoder.py", line 355, in raw_decode
    raise JSONDecodeError("Expecting value", s, err.value) from None
json.decoder.JSONDecodeError: Expecting value: line 1 column 1 (char 0)

During handling of the above exception, another exception occurred:

Traceback (most recent call last):
  File "/home/airflow/.local/lib/python3.8/site-packages/airflow/models/dagbag.py", line 344, in parse
    loader.exec_module(new_module)
  File "<frozen importlib._bootstrap_external>", line 843, in exec_module
  File "<frozen importlib._bootstrap>", line 219, in _call_with_frames_removed
  File "/opt/airflow/dags/flight_etl_dag.py", line 8, in <module>
    from extract import extract
  File "/opt/airflow/extract.py", line 21, in <module>
    extract()
  File "/opt/airflow/extract.py", line 7, in extract
    data=response.json()
  File "/home/airflow/.local/lib/python3.8/site-packages/requests/models.py", line 975, in json
    raise RequestsJSONDecodeError(e.msg, e.doc, e.pos)
requests.exceptions.JSONDecodeError: Expecting value: line 1 column 1 (char 0)
[2025-07-12T01:41:06.749+0000] {processor.py:842} WARNING - No viable dags retrieved from /opt/airflow/dags/flight_etl_dag.py
[2025-07-12T01:41:06.773+0000] {processor.py:183} INFO - Processing /opt/airflow/dags/flight_etl_dag.py took 0.673 seconds
[2025-07-12T01:41:36.930+0000] {processor.py:161} INFO - Started process (PID=413) to work on /opt/airflow/dags/flight_etl_dag.py
[2025-07-12T01:41:36.933+0000] {processor.py:830} INFO - Processing file /opt/airflow/dags/flight_etl_dag.py for tasks to queue
[2025-07-12T01:41:36.939+0000] {logging_mixin.py:188} INFO - [2025-07-12T01:41:36.938+0000] {dagbag.py:538} INFO - Filling up the DagBag from /opt/airflow/dags/flight_etl_dag.py
[2025-07-12T01:41:37.642+0000] {logging_mixin.py:188} INFO - [2025-07-12T01:41:37.597+0000] {dagbag.py:348} ERROR - Failed to import: /opt/airflow/dags/flight_etl_dag.py
Traceback (most recent call last):
  File "/home/airflow/.local/lib/python3.8/site-packages/requests/models.py", line 971, in json
    return complexjson.loads(self.text, **kwargs)
  File "/usr/local/lib/python3.8/json/__init__.py", line 357, in loads
    return _default_decoder.decode(s)
  File "/usr/local/lib/python3.8/json/decoder.py", line 337, in decode
    obj, end = self.raw_decode(s, idx=_w(s, 0).end())
  File "/usr/local/lib/python3.8/json/decoder.py", line 355, in raw_decode
    raise JSONDecodeError("Expecting value", s, err.value) from None
json.decoder.JSONDecodeError: Expecting value: line 1 column 1 (char 0)

During handling of the above exception, another exception occurred:

Traceback (most recent call last):
  File "/home/airflow/.local/lib/python3.8/site-packages/airflow/models/dagbag.py", line 344, in parse
    loader.exec_module(new_module)
  File "<frozen importlib._bootstrap_external>", line 843, in exec_module
  File "<frozen importlib._bootstrap>", line 219, in _call_with_frames_removed
  File "/opt/airflow/dags/flight_etl_dag.py", line 8, in <module>
    from extract import extract
  File "/opt/airflow/extract.py", line 21, in <module>
    extract()
  File "/opt/airflow/extract.py", line 7, in extract
    data=response.json()
  File "/home/airflow/.local/lib/python3.8/site-packages/requests/models.py", line 975, in json
    raise RequestsJSONDecodeError(e.msg, e.doc, e.pos)
requests.exceptions.JSONDecodeError: Expecting value: line 1 column 1 (char 0)
[2025-07-12T01:41:37.650+0000] {processor.py:842} WARNING - No viable dags retrieved from /opt/airflow/dags/flight_etl_dag.py
[2025-07-12T01:41:37.698+0000] {processor.py:183} INFO - Processing /opt/airflow/dags/flight_etl_dag.py took 0.776 seconds
[2025-07-12T01:42:08.328+0000] {processor.py:161} INFO - Started process (PID=469) to work on /opt/airflow/dags/flight_etl_dag.py
[2025-07-12T01:42:08.330+0000] {processor.py:830} INFO - Processing file /opt/airflow/dags/flight_etl_dag.py for tasks to queue
[2025-07-12T01:42:08.334+0000] {logging_mixin.py:188} INFO - [2025-07-12T01:42:08.334+0000] {dagbag.py:538} INFO - Filling up the DagBag from /opt/airflow/dags/flight_etl_dag.py
[2025-07-12T01:42:08.898+0000] {logging_mixin.py:188} INFO - [2025-07-12T01:42:08.881+0000] {dagbag.py:348} ERROR - Failed to import: /opt/airflow/dags/flight_etl_dag.py
Traceback (most recent call last):
  File "/home/airflow/.local/lib/python3.8/site-packages/requests/models.py", line 971, in json
    return complexjson.loads(self.text, **kwargs)
  File "/usr/local/lib/python3.8/json/__init__.py", line 357, in loads
    return _default_decoder.decode(s)
  File "/usr/local/lib/python3.8/json/decoder.py", line 337, in decode
    obj, end = self.raw_decode(s, idx=_w(s, 0).end())
  File "/usr/local/lib/python3.8/json/decoder.py", line 355, in raw_decode
    raise JSONDecodeError("Expecting value", s, err.value) from None
json.decoder.JSONDecodeError: Expecting value: line 1 column 1 (char 0)

During handling of the above exception, another exception occurred:

Traceback (most recent call last):
  File "/home/airflow/.local/lib/python3.8/site-packages/airflow/models/dagbag.py", line 344, in parse
    loader.exec_module(new_module)
  File "<frozen importlib._bootstrap_external>", line 843, in exec_module
  File "<frozen importlib._bootstrap>", line 219, in _call_with_frames_removed
  File "/opt/airflow/dags/flight_etl_dag.py", line 8, in <module>
    from extract import extract
  File "/opt/airflow/extract.py", line 21, in <module>
    extract()
  File "/opt/airflow/extract.py", line 7, in extract
    data=response.json()
  File "/home/airflow/.local/lib/python3.8/site-packages/requests/models.py", line 975, in json
    raise RequestsJSONDecodeError(e.msg, e.doc, e.pos)
requests.exceptions.JSONDecodeError: Expecting value: line 1 column 1 (char 0)
[2025-07-12T01:42:08.901+0000] {processor.py:842} WARNING - No viable dags retrieved from /opt/airflow/dags/flight_etl_dag.py
[2025-07-12T01:42:08.922+0000] {processor.py:183} INFO - Processing /opt/airflow/dags/flight_etl_dag.py took 0.601 seconds
[2025-07-12T01:42:38.968+0000] {processor.py:161} INFO - Started process (PID=527) to work on /opt/airflow/dags/flight_etl_dag.py
[2025-07-12T01:42:38.970+0000] {processor.py:830} INFO - Processing file /opt/airflow/dags/flight_etl_dag.py for tasks to queue
[2025-07-12T01:42:38.972+0000] {logging_mixin.py:188} INFO - [2025-07-12T01:42:38.972+0000] {dagbag.py:538} INFO - Filling up the DagBag from /opt/airflow/dags/flight_etl_dag.py
[2025-07-12T01:42:39.755+0000] {logging_mixin.py:188} INFO - [2025-07-12T01:42:39.727+0000] {dagbag.py:348} ERROR - Failed to import: /opt/airflow/dags/flight_etl_dag.py
Traceback (most recent call last):
  File "/home/airflow/.local/lib/python3.8/site-packages/requests/models.py", line 971, in json
    return complexjson.loads(self.text, **kwargs)
  File "/usr/local/lib/python3.8/json/__init__.py", line 357, in loads
    return _default_decoder.decode(s)
  File "/usr/local/lib/python3.8/json/decoder.py", line 337, in decode
    obj, end = self.raw_decode(s, idx=_w(s, 0).end())
  File "/usr/local/lib/python3.8/json/decoder.py", line 355, in raw_decode
    raise JSONDecodeError("Expecting value", s, err.value) from None
json.decoder.JSONDecodeError: Expecting value: line 1 column 1 (char 0)

During handling of the above exception, another exception occurred:

Traceback (most recent call last):
  File "/home/airflow/.local/lib/python3.8/site-packages/airflow/models/dagbag.py", line 344, in parse
    loader.exec_module(new_module)
  File "<frozen importlib._bootstrap_external>", line 843, in exec_module
  File "<frozen importlib._bootstrap>", line 219, in _call_with_frames_removed
  File "/opt/airflow/dags/flight_etl_dag.py", line 8, in <module>
    from extract import extract
  File "/opt/airflow/extract.py", line 21, in <module>
    extract()
  File "/opt/airflow/extract.py", line 7, in extract
    data=response.json()
  File "/home/airflow/.local/lib/python3.8/site-packages/requests/models.py", line 975, in json
    raise RequestsJSONDecodeError(e.msg, e.doc, e.pos)
requests.exceptions.JSONDecodeError: Expecting value: line 1 column 1 (char 0)
[2025-07-12T01:42:39.760+0000] {processor.py:842} WARNING - No viable dags retrieved from /opt/airflow/dags/flight_etl_dag.py
[2025-07-12T01:42:39.801+0000] {processor.py:183} INFO - Processing /opt/airflow/dags/flight_etl_dag.py took 0.838 seconds
[2025-07-12T01:43:10.010+0000] {processor.py:161} INFO - Started process (PID=585) to work on /opt/airflow/dags/flight_etl_dag.py
[2025-07-12T01:43:10.011+0000] {processor.py:830} INFO - Processing file /opt/airflow/dags/flight_etl_dag.py for tasks to queue
[2025-07-12T01:43:10.014+0000] {logging_mixin.py:188} INFO - [2025-07-12T01:43:10.014+0000] {dagbag.py:538} INFO - Filling up the DagBag from /opt/airflow/dags/flight_etl_dag.py
[2025-07-12T01:43:10.791+0000] {logging_mixin.py:188} INFO - [2025-07-12T01:43:10.758+0000] {dagbag.py:348} ERROR - Failed to import: /opt/airflow/dags/flight_etl_dag.py
Traceback (most recent call last):
  File "/home/airflow/.local/lib/python3.8/site-packages/requests/models.py", line 971, in json
    return complexjson.loads(self.text, **kwargs)
  File "/usr/local/lib/python3.8/json/__init__.py", line 357, in loads
    return _default_decoder.decode(s)
  File "/usr/local/lib/python3.8/json/decoder.py", line 337, in decode
    obj, end = self.raw_decode(s, idx=_w(s, 0).end())
  File "/usr/local/lib/python3.8/json/decoder.py", line 355, in raw_decode
    raise JSONDecodeError("Expecting value", s, err.value) from None
json.decoder.JSONDecodeError: Expecting value: line 1 column 1 (char 0)

During handling of the above exception, another exception occurred:

Traceback (most recent call last):
  File "/home/airflow/.local/lib/python3.8/site-packages/airflow/models/dagbag.py", line 344, in parse
    loader.exec_module(new_module)
  File "<frozen importlib._bootstrap_external>", line 843, in exec_module
  File "<frozen importlib._bootstrap>", line 219, in _call_with_frames_removed
  File "/opt/airflow/dags/flight_etl_dag.py", line 8, in <module>
    from extract import extract
  File "/opt/airflow/extract.py", line 21, in <module>
    extract()
  File "/opt/airflow/extract.py", line 7, in extract
    data=response.json()
  File "/home/airflow/.local/lib/python3.8/site-packages/requests/models.py", line 975, in json
    raise RequestsJSONDecodeError(e.msg, e.doc, e.pos)
requests.exceptions.JSONDecodeError: Expecting value: line 1 column 1 (char 0)
[2025-07-12T01:43:10.798+0000] {processor.py:842} WARNING - No viable dags retrieved from /opt/airflow/dags/flight_etl_dag.py
[2025-07-12T01:43:10.853+0000] {processor.py:183} INFO - Processing /opt/airflow/dags/flight_etl_dag.py took 0.849 seconds
[2025-07-12T01:43:41.558+0000] {processor.py:161} INFO - Started process (PID=641) to work on /opt/airflow/dags/flight_etl_dag.py
[2025-07-12T01:43:41.560+0000] {processor.py:830} INFO - Processing file /opt/airflow/dags/flight_etl_dag.py for tasks to queue
[2025-07-12T01:43:41.563+0000] {logging_mixin.py:188} INFO - [2025-07-12T01:43:41.563+0000] {dagbag.py:538} INFO - Filling up the DagBag from /opt/airflow/dags/flight_etl_dag.py
[2025-07-12T01:43:42.315+0000] {logging_mixin.py:188} INFO - [2025-07-12T01:43:42.296+0000] {dagbag.py:348} ERROR - Failed to import: /opt/airflow/dags/flight_etl_dag.py
Traceback (most recent call last):
  File "/home/airflow/.local/lib/python3.8/site-packages/requests/models.py", line 971, in json
    return complexjson.loads(self.text, **kwargs)
  File "/usr/local/lib/python3.8/json/__init__.py", line 357, in loads
    return _default_decoder.decode(s)
  File "/usr/local/lib/python3.8/json/decoder.py", line 337, in decode
    obj, end = self.raw_decode(s, idx=_w(s, 0).end())
  File "/usr/local/lib/python3.8/json/decoder.py", line 355, in raw_decode
    raise JSONDecodeError("Expecting value", s, err.value) from None
json.decoder.JSONDecodeError: Expecting value: line 1 column 1 (char 0)

During handling of the above exception, another exception occurred:

Traceback (most recent call last):
  File "/home/airflow/.local/lib/python3.8/site-packages/airflow/models/dagbag.py", line 344, in parse
    loader.exec_module(new_module)
  File "<frozen importlib._bootstrap_external>", line 843, in exec_module
  File "<frozen importlib._bootstrap>", line 219, in _call_with_frames_removed
  File "/opt/airflow/dags/flight_etl_dag.py", line 8, in <module>
    from extract import extract
  File "/opt/airflow/extract.py", line 21, in <module>
    extract()
  File "/opt/airflow/extract.py", line 7, in extract
    data=response.json()
  File "/home/airflow/.local/lib/python3.8/site-packages/requests/models.py", line 975, in json
    raise RequestsJSONDecodeError(e.msg, e.doc, e.pos)
requests.exceptions.JSONDecodeError: Expecting value: line 1 column 1 (char 0)
[2025-07-12T01:43:42.319+0000] {processor.py:842} WARNING - No viable dags retrieved from /opt/airflow/dags/flight_etl_dag.py
[2025-07-12T01:43:42.355+0000] {processor.py:183} INFO - Processing /opt/airflow/dags/flight_etl_dag.py took 0.802 seconds
[2025-07-12T01:44:12.497+0000] {processor.py:161} INFO - Started process (PID=700) to work on /opt/airflow/dags/flight_etl_dag.py
[2025-07-12T01:44:12.499+0000] {processor.py:830} INFO - Processing file /opt/airflow/dags/flight_etl_dag.py for tasks to queue
[2025-07-12T01:44:12.502+0000] {logging_mixin.py:188} INFO - [2025-07-12T01:44:12.502+0000] {dagbag.py:538} INFO - Filling up the DagBag from /opt/airflow/dags/flight_etl_dag.py
[2025-07-12T01:44:13.146+0000] {logging_mixin.py:188} INFO - [2025-07-12T01:44:13.129+0000] {dagbag.py:348} ERROR - Failed to import: /opt/airflow/dags/flight_etl_dag.py
Traceback (most recent call last):
  File "/home/airflow/.local/lib/python3.8/site-packages/requests/models.py", line 971, in json
    return complexjson.loads(self.text, **kwargs)
  File "/usr/local/lib/python3.8/json/__init__.py", line 357, in loads
    return _default_decoder.decode(s)
  File "/usr/local/lib/python3.8/json/decoder.py", line 337, in decode
    obj, end = self.raw_decode(s, idx=_w(s, 0).end())
  File "/usr/local/lib/python3.8/json/decoder.py", line 355, in raw_decode
    raise JSONDecodeError("Expecting value", s, err.value) from None
json.decoder.JSONDecodeError: Expecting value: line 1 column 1 (char 0)

During handling of the above exception, another exception occurred:

Traceback (most recent call last):
  File "/home/airflow/.local/lib/python3.8/site-packages/airflow/models/dagbag.py", line 344, in parse
    loader.exec_module(new_module)
  File "<frozen importlib._bootstrap_external>", line 843, in exec_module
  File "<frozen importlib._bootstrap>", line 219, in _call_with_frames_removed
  File "/opt/airflow/dags/flight_etl_dag.py", line 8, in <module>
    from extract import extract
  File "/opt/airflow/extract.py", line 21, in <module>
    extract()
  File "/opt/airflow/extract.py", line 7, in extract
    data=response.json()
  File "/home/airflow/.local/lib/python3.8/site-packages/requests/models.py", line 975, in json
    raise RequestsJSONDecodeError(e.msg, e.doc, e.pos)
requests.exceptions.JSONDecodeError: Expecting value: line 1 column 1 (char 0)
[2025-07-12T01:44:13.149+0000] {processor.py:842} WARNING - No viable dags retrieved from /opt/airflow/dags/flight_etl_dag.py
[2025-07-12T01:44:13.191+0000] {processor.py:183} INFO - Processing /opt/airflow/dags/flight_etl_dag.py took 0.699 seconds
[2025-07-12T01:44:43.341+0000] {processor.py:161} INFO - Started process (PID=760) to work on /opt/airflow/dags/flight_etl_dag.py
[2025-07-12T01:44:43.344+0000] {processor.py:830} INFO - Processing file /opt/airflow/dags/flight_etl_dag.py for tasks to queue
[2025-07-12T01:44:43.347+0000] {logging_mixin.py:188} INFO - [2025-07-12T01:44:43.347+0000] {dagbag.py:538} INFO - Filling up the DagBag from /opt/airflow/dags/flight_etl_dag.py
[2025-07-12T01:44:44.179+0000] {logging_mixin.py:188} INFO - [2025-07-12T01:44:44.151+0000] {dagbag.py:348} ERROR - Failed to import: /opt/airflow/dags/flight_etl_dag.py
Traceback (most recent call last):
  File "/home/airflow/.local/lib/python3.8/site-packages/requests/models.py", line 971, in json
    return complexjson.loads(self.text, **kwargs)
  File "/usr/local/lib/python3.8/json/__init__.py", line 357, in loads
    return _default_decoder.decode(s)
  File "/usr/local/lib/python3.8/json/decoder.py", line 337, in decode
    obj, end = self.raw_decode(s, idx=_w(s, 0).end())
  File "/usr/local/lib/python3.8/json/decoder.py", line 355, in raw_decode
    raise JSONDecodeError("Expecting value", s, err.value) from None
json.decoder.JSONDecodeError: Expecting value: line 1 column 1 (char 0)

During handling of the above exception, another exception occurred:

Traceback (most recent call last):
  File "/home/airflow/.local/lib/python3.8/site-packages/airflow/models/dagbag.py", line 344, in parse
    loader.exec_module(new_module)
  File "<frozen importlib._bootstrap_external>", line 843, in exec_module
  File "<frozen importlib._bootstrap>", line 219, in _call_with_frames_removed
  File "/opt/airflow/dags/flight_etl_dag.py", line 8, in <module>
    from extract import extract
  File "/opt/airflow/extract.py", line 21, in <module>
    extract()
  File "/opt/airflow/extract.py", line 7, in extract
    data=response.json()
  File "/home/airflow/.local/lib/python3.8/site-packages/requests/models.py", line 975, in json
    raise RequestsJSONDecodeError(e.msg, e.doc, e.pos)
requests.exceptions.JSONDecodeError: Expecting value: line 1 column 1 (char 0)
[2025-07-12T01:44:44.186+0000] {processor.py:842} WARNING - No viable dags retrieved from /opt/airflow/dags/flight_etl_dag.py
[2025-07-12T01:44:44.232+0000] {processor.py:183} INFO - Processing /opt/airflow/dags/flight_etl_dag.py took 0.897 seconds
[2025-07-12T01:45:14.480+0000] {processor.py:161} INFO - Started process (PID=816) to work on /opt/airflow/dags/flight_etl_dag.py
[2025-07-12T01:45:14.483+0000] {processor.py:830} INFO - Processing file /opt/airflow/dags/flight_etl_dag.py for tasks to queue
[2025-07-12T01:45:14.487+0000] {logging_mixin.py:188} INFO - [2025-07-12T01:45:14.486+0000] {dagbag.py:538} INFO - Filling up the DagBag from /opt/airflow/dags/flight_etl_dag.py
[2025-07-12T01:45:15.206+0000] {logging_mixin.py:188} INFO - [2025-07-12T01:45:15.174+0000] {dagbag.py:348} ERROR - Failed to import: /opt/airflow/dags/flight_etl_dag.py
Traceback (most recent call last):
  File "/home/airflow/.local/lib/python3.8/site-packages/requests/models.py", line 971, in json
    return complexjson.loads(self.text, **kwargs)
  File "/usr/local/lib/python3.8/json/__init__.py", line 357, in loads
    return _default_decoder.decode(s)
  File "/usr/local/lib/python3.8/json/decoder.py", line 337, in decode
    obj, end = self.raw_decode(s, idx=_w(s, 0).end())
  File "/usr/local/lib/python3.8/json/decoder.py", line 355, in raw_decode
    raise JSONDecodeError("Expecting value", s, err.value) from None
json.decoder.JSONDecodeError: Expecting value: line 1 column 1 (char 0)

During handling of the above exception, another exception occurred:

Traceback (most recent call last):
  File "/home/airflow/.local/lib/python3.8/site-packages/airflow/models/dagbag.py", line 344, in parse
    loader.exec_module(new_module)
  File "<frozen importlib._bootstrap_external>", line 843, in exec_module
  File "<frozen importlib._bootstrap>", line 219, in _call_with_frames_removed
  File "/opt/airflow/dags/flight_etl_dag.py", line 8, in <module>
    from extract import extract
  File "/opt/airflow/extract.py", line 21, in <module>
    extract()
  File "/opt/airflow/extract.py", line 7, in extract
    data=response.json()
  File "/home/airflow/.local/lib/python3.8/site-packages/requests/models.py", line 975, in json
    raise RequestsJSONDecodeError(e.msg, e.doc, e.pos)
requests.exceptions.JSONDecodeError: Expecting value: line 1 column 1 (char 0)
[2025-07-12T01:45:15.214+0000] {processor.py:842} WARNING - No viable dags retrieved from /opt/airflow/dags/flight_etl_dag.py
[2025-07-12T01:45:15.261+0000] {processor.py:183} INFO - Processing /opt/airflow/dags/flight_etl_dag.py took 0.785 seconds
[2025-07-12T01:45:46.187+0000] {processor.py:161} INFO - Started process (PID=874) to work on /opt/airflow/dags/flight_etl_dag.py
[2025-07-12T01:45:46.189+0000] {processor.py:830} INFO - Processing file /opt/airflow/dags/flight_etl_dag.py for tasks to queue
[2025-07-12T01:45:46.192+0000] {logging_mixin.py:188} INFO - [2025-07-12T01:45:46.192+0000] {dagbag.py:538} INFO - Filling up the DagBag from /opt/airflow/dags/flight_etl_dag.py
[2025-07-12T01:45:47.044+0000] {logging_mixin.py:188} INFO - [2025-07-12T01:45:46.882+0000] {dagbag.py:348} ERROR - Failed to import: /opt/airflow/dags/flight_etl_dag.py
Traceback (most recent call last):
  File "/home/airflow/.local/lib/python3.8/site-packages/requests/models.py", line 971, in json
    return complexjson.loads(self.text, **kwargs)
  File "/usr/local/lib/python3.8/json/__init__.py", line 357, in loads
    return _default_decoder.decode(s)
  File "/usr/local/lib/python3.8/json/decoder.py", line 337, in decode
    obj, end = self.raw_decode(s, idx=_w(s, 0).end())
  File "/usr/local/lib/python3.8/json/decoder.py", line 355, in raw_decode
    raise JSONDecodeError("Expecting value", s, err.value) from None
json.decoder.JSONDecodeError: Expecting value: line 1 column 1 (char 0)

During handling of the above exception, another exception occurred:

Traceback (most recent call last):
  File "/home/airflow/.local/lib/python3.8/site-packages/airflow/models/dagbag.py", line 344, in parse
    loader.exec_module(new_module)
  File "<frozen importlib._bootstrap_external>", line 843, in exec_module
  File "<frozen importlib._bootstrap>", line 219, in _call_with_frames_removed
  File "/opt/airflow/dags/flight_etl_dag.py", line 8, in <module>
    from extract import extract
  File "/opt/airflow/extract.py", line 21, in <module>
    extract()
  File "/opt/airflow/extract.py", line 7, in extract
    data=response.json()
  File "/home/airflow/.local/lib/python3.8/site-packages/requests/models.py", line 975, in json
    raise RequestsJSONDecodeError(e.msg, e.doc, e.pos)
requests.exceptions.JSONDecodeError: Expecting value: line 1 column 1 (char 0)
[2025-07-12T01:45:47.053+0000] {processor.py:842} WARNING - No viable dags retrieved from /opt/airflow/dags/flight_etl_dag.py
[2025-07-12T01:45:47.082+0000] {processor.py:183} INFO - Processing /opt/airflow/dags/flight_etl_dag.py took 0.900 seconds
[2025-07-12T01:46:17.730+0000] {processor.py:161} INFO - Started process (PID=932) to work on /opt/airflow/dags/flight_etl_dag.py
[2025-07-12T01:46:17.732+0000] {processor.py:830} INFO - Processing file /opt/airflow/dags/flight_etl_dag.py for tasks to queue
[2025-07-12T01:46:17.735+0000] {logging_mixin.py:188} INFO - [2025-07-12T01:46:17.735+0000] {dagbag.py:538} INFO - Filling up the DagBag from /opt/airflow/dags/flight_etl_dag.py
[2025-07-12T01:46:18.490+0000] {logging_mixin.py:188} INFO - [2025-07-12T01:46:18.457+0000] {dagbag.py:348} ERROR - Failed to import: /opt/airflow/dags/flight_etl_dag.py
Traceback (most recent call last):
  File "/home/airflow/.local/lib/python3.8/site-packages/requests/models.py", line 971, in json
    return complexjson.loads(self.text, **kwargs)
  File "/usr/local/lib/python3.8/json/__init__.py", line 357, in loads
    return _default_decoder.decode(s)
  File "/usr/local/lib/python3.8/json/decoder.py", line 337, in decode
    obj, end = self.raw_decode(s, idx=_w(s, 0).end())
  File "/usr/local/lib/python3.8/json/decoder.py", line 355, in raw_decode
    raise JSONDecodeError("Expecting value", s, err.value) from None
json.decoder.JSONDecodeError: Expecting value: line 1 column 1 (char 0)

During handling of the above exception, another exception occurred:

Traceback (most recent call last):
  File "/home/airflow/.local/lib/python3.8/site-packages/airflow/models/dagbag.py", line 344, in parse
    loader.exec_module(new_module)
  File "<frozen importlib._bootstrap_external>", line 843, in exec_module
  File "<frozen importlib._bootstrap>", line 219, in _call_with_frames_removed
  File "/opt/airflow/dags/flight_etl_dag.py", line 8, in <module>
    from extract import extract
  File "/opt/airflow/extract.py", line 21, in <module>
    extract()
  File "/opt/airflow/extract.py", line 7, in extract
    data=response.json()
  File "/home/airflow/.local/lib/python3.8/site-packages/requests/models.py", line 975, in json
    raise RequestsJSONDecodeError(e.msg, e.doc, e.pos)
requests.exceptions.JSONDecodeError: Expecting value: line 1 column 1 (char 0)
[2025-07-12T01:46:18.512+0000] {processor.py:842} WARNING - No viable dags retrieved from /opt/airflow/dags/flight_etl_dag.py
[2025-07-12T01:46:18.544+0000] {processor.py:183} INFO - Processing /opt/airflow/dags/flight_etl_dag.py took 0.819 seconds
[2025-07-12T01:46:49.367+0000] {processor.py:161} INFO - Started process (PID=990) to work on /opt/airflow/dags/flight_etl_dag.py
[2025-07-12T01:46:49.372+0000] {processor.py:830} INFO - Processing file /opt/airflow/dags/flight_etl_dag.py for tasks to queue
[2025-07-12T01:46:49.375+0000] {logging_mixin.py:188} INFO - [2025-07-12T01:46:49.375+0000] {dagbag.py:538} INFO - Filling up the DagBag from /opt/airflow/dags/flight_etl_dag.py
[2025-07-12T01:46:50.112+0000] {logging_mixin.py:188} INFO - [2025-07-12T01:46:50.097+0000] {dagbag.py:348} ERROR - Failed to import: /opt/airflow/dags/flight_etl_dag.py
Traceback (most recent call last):
  File "/home/airflow/.local/lib/python3.8/site-packages/requests/models.py", line 971, in json
    return complexjson.loads(self.text, **kwargs)
  File "/usr/local/lib/python3.8/json/__init__.py", line 357, in loads
    return _default_decoder.decode(s)
  File "/usr/local/lib/python3.8/json/decoder.py", line 337, in decode
    obj, end = self.raw_decode(s, idx=_w(s, 0).end())
  File "/usr/local/lib/python3.8/json/decoder.py", line 355, in raw_decode
    raise JSONDecodeError("Expecting value", s, err.value) from None
json.decoder.JSONDecodeError: Expecting value: line 1 column 1 (char 0)

During handling of the above exception, another exception occurred:

Traceback (most recent call last):
  File "/home/airflow/.local/lib/python3.8/site-packages/airflow/models/dagbag.py", line 344, in parse
    loader.exec_module(new_module)
  File "<frozen importlib._bootstrap_external>", line 843, in exec_module
  File "<frozen importlib._bootstrap>", line 219, in _call_with_frames_removed
  File "/opt/airflow/dags/flight_etl_dag.py", line 8, in <module>
    from extract import extract
  File "/opt/airflow/extract.py", line 21, in <module>
    extract()
  File "/opt/airflow/extract.py", line 7, in extract
    data=response.json()
  File "/home/airflow/.local/lib/python3.8/site-packages/requests/models.py", line 975, in json
    raise RequestsJSONDecodeError(e.msg, e.doc, e.pos)
requests.exceptions.JSONDecodeError: Expecting value: line 1 column 1 (char 0)
[2025-07-12T01:46:50.117+0000] {processor.py:842} WARNING - No viable dags retrieved from /opt/airflow/dags/flight_etl_dag.py
[2025-07-12T01:46:50.157+0000] {processor.py:183} INFO - Processing /opt/airflow/dags/flight_etl_dag.py took 0.796 seconds
[2025-07-12T01:47:20.320+0000] {processor.py:161} INFO - Started process (PID=1050) to work on /opt/airflow/dags/flight_etl_dag.py
[2025-07-12T01:47:20.322+0000] {processor.py:830} INFO - Processing file /opt/airflow/dags/flight_etl_dag.py for tasks to queue
[2025-07-12T01:47:20.324+0000] {logging_mixin.py:188} INFO - [2025-07-12T01:47:20.324+0000] {dagbag.py:538} INFO - Filling up the DagBag from /opt/airflow/dags/flight_etl_dag.py
[2025-07-12T01:47:20.966+0000] {logging_mixin.py:188} INFO - [2025-07-12T01:47:20.930+0000] {dagbag.py:348} ERROR - Failed to import: /opt/airflow/dags/flight_etl_dag.py
Traceback (most recent call last):
  File "/home/airflow/.local/lib/python3.8/site-packages/requests/models.py", line 971, in json
    return complexjson.loads(self.text, **kwargs)
  File "/usr/local/lib/python3.8/json/__init__.py", line 357, in loads
    return _default_decoder.decode(s)
  File "/usr/local/lib/python3.8/json/decoder.py", line 337, in decode
    obj, end = self.raw_decode(s, idx=_w(s, 0).end())
  File "/usr/local/lib/python3.8/json/decoder.py", line 355, in raw_decode
    raise JSONDecodeError("Expecting value", s, err.value) from None
json.decoder.JSONDecodeError: Expecting value: line 1 column 1 (char 0)

During handling of the above exception, another exception occurred:

Traceback (most recent call last):
  File "/home/airflow/.local/lib/python3.8/site-packages/airflow/models/dagbag.py", line 344, in parse
    loader.exec_module(new_module)
  File "<frozen importlib._bootstrap_external>", line 843, in exec_module
  File "<frozen importlib._bootstrap>", line 219, in _call_with_frames_removed
  File "/opt/airflow/dags/flight_etl_dag.py", line 8, in <module>
    from extract import extract
  File "/opt/airflow/extract.py", line 21, in <module>
    extract()
  File "/opt/airflow/extract.py", line 7, in extract
    data=response.json()
  File "/home/airflow/.local/lib/python3.8/site-packages/requests/models.py", line 975, in json
    raise RequestsJSONDecodeError(e.msg, e.doc, e.pos)
requests.exceptions.JSONDecodeError: Expecting value: line 1 column 1 (char 0)
[2025-07-12T01:47:20.972+0000] {processor.py:842} WARNING - No viable dags retrieved from /opt/airflow/dags/flight_etl_dag.py
[2025-07-12T01:47:21.004+0000] {processor.py:183} INFO - Processing /opt/airflow/dags/flight_etl_dag.py took 0.688 seconds
[2025-07-12T01:47:51.564+0000] {processor.py:161} INFO - Started process (PID=1106) to work on /opt/airflow/dags/flight_etl_dag.py
[2025-07-12T01:47:51.567+0000] {processor.py:830} INFO - Processing file /opt/airflow/dags/flight_etl_dag.py for tasks to queue
[2025-07-12T01:47:51.569+0000] {logging_mixin.py:188} INFO - [2025-07-12T01:47:51.569+0000] {dagbag.py:538} INFO - Filling up the DagBag from /opt/airflow/dags/flight_etl_dag.py
[2025-07-12T01:47:52.198+0000] {logging_mixin.py:188} INFO - [2025-07-12T01:47:52.179+0000] {dagbag.py:348} ERROR - Failed to import: /opt/airflow/dags/flight_etl_dag.py
Traceback (most recent call last):
  File "/home/airflow/.local/lib/python3.8/site-packages/requests/models.py", line 971, in json
    return complexjson.loads(self.text, **kwargs)
  File "/usr/local/lib/python3.8/json/__init__.py", line 357, in loads
    return _default_decoder.decode(s)
  File "/usr/local/lib/python3.8/json/decoder.py", line 337, in decode
    obj, end = self.raw_decode(s, idx=_w(s, 0).end())
  File "/usr/local/lib/python3.8/json/decoder.py", line 355, in raw_decode
    raise JSONDecodeError("Expecting value", s, err.value) from None
json.decoder.JSONDecodeError: Expecting value: line 1 column 1 (char 0)

During handling of the above exception, another exception occurred:

Traceback (most recent call last):
  File "/home/airflow/.local/lib/python3.8/site-packages/airflow/models/dagbag.py", line 344, in parse
    loader.exec_module(new_module)
  File "<frozen importlib._bootstrap_external>", line 843, in exec_module
  File "<frozen importlib._bootstrap>", line 219, in _call_with_frames_removed
  File "/opt/airflow/dags/flight_etl_dag.py", line 8, in <module>
    from extract import extract
  File "/opt/airflow/extract.py", line 21, in <module>
    extract()
  File "/opt/airflow/extract.py", line 7, in extract
    data=response.json()
  File "/home/airflow/.local/lib/python3.8/site-packages/requests/models.py", line 975, in json
    raise RequestsJSONDecodeError(e.msg, e.doc, e.pos)
requests.exceptions.JSONDecodeError: Expecting value: line 1 column 1 (char 0)
[2025-07-12T01:47:52.202+0000] {processor.py:842} WARNING - No viable dags retrieved from /opt/airflow/dags/flight_etl_dag.py
[2025-07-12T01:47:52.233+0000] {processor.py:183} INFO - Processing /opt/airflow/dags/flight_etl_dag.py took 0.673 seconds
[2025-07-12T01:48:22.341+0000] {processor.py:161} INFO - Started process (PID=1164) to work on /opt/airflow/dags/flight_etl_dag.py
[2025-07-12T01:48:22.343+0000] {processor.py:830} INFO - Processing file /opt/airflow/dags/flight_etl_dag.py for tasks to queue
[2025-07-12T01:48:22.345+0000] {logging_mixin.py:188} INFO - [2025-07-12T01:48:22.345+0000] {dagbag.py:538} INFO - Filling up the DagBag from /opt/airflow/dags/flight_etl_dag.py
[2025-07-12T01:48:23.100+0000] {logging_mixin.py:188} INFO - [2025-07-12T01:48:23.079+0000] {dagbag.py:348} ERROR - Failed to import: /opt/airflow/dags/flight_etl_dag.py
Traceback (most recent call last):
  File "/home/airflow/.local/lib/python3.8/site-packages/requests/models.py", line 971, in json
    return complexjson.loads(self.text, **kwargs)
  File "/usr/local/lib/python3.8/json/__init__.py", line 357, in loads
    return _default_decoder.decode(s)
  File "/usr/local/lib/python3.8/json/decoder.py", line 337, in decode
    obj, end = self.raw_decode(s, idx=_w(s, 0).end())
  File "/usr/local/lib/python3.8/json/decoder.py", line 355, in raw_decode
    raise JSONDecodeError("Expecting value", s, err.value) from None
json.decoder.JSONDecodeError: Expecting value: line 1 column 1 (char 0)

During handling of the above exception, another exception occurred:

Traceback (most recent call last):
  File "/home/airflow/.local/lib/python3.8/site-packages/airflow/models/dagbag.py", line 344, in parse
    loader.exec_module(new_module)
  File "<frozen importlib._bootstrap_external>", line 843, in exec_module
  File "<frozen importlib._bootstrap>", line 219, in _call_with_frames_removed
  File "/opt/airflow/dags/flight_etl_dag.py", line 8, in <module>
    from extract import extract
  File "/opt/airflow/extract.py", line 21, in <module>
    extract()
  File "/opt/airflow/extract.py", line 7, in extract
    data=response.json()
  File "/home/airflow/.local/lib/python3.8/site-packages/requests/models.py", line 975, in json
    raise RequestsJSONDecodeError(e.msg, e.doc, e.pos)
requests.exceptions.JSONDecodeError: Expecting value: line 1 column 1 (char 0)
[2025-07-12T01:48:23.105+0000] {processor.py:842} WARNING - No viable dags retrieved from /opt/airflow/dags/flight_etl_dag.py
[2025-07-12T01:48:23.147+0000] {processor.py:183} INFO - Processing /opt/airflow/dags/flight_etl_dag.py took 0.813 seconds
[2025-07-12T01:48:53.944+0000] {processor.py:161} INFO - Started process (PID=1220) to work on /opt/airflow/dags/flight_etl_dag.py
[2025-07-12T01:48:53.946+0000] {processor.py:830} INFO - Processing file /opt/airflow/dags/flight_etl_dag.py for tasks to queue
[2025-07-12T01:48:53.948+0000] {logging_mixin.py:188} INFO - [2025-07-12T01:48:53.948+0000] {dagbag.py:538} INFO - Filling up the DagBag from /opt/airflow/dags/flight_etl_dag.py
[2025-07-12T01:48:54.635+0000] {logging_mixin.py:188} INFO - [2025-07-12T01:48:54.618+0000] {dagbag.py:348} ERROR - Failed to import: /opt/airflow/dags/flight_etl_dag.py
Traceback (most recent call last):
  File "/home/airflow/.local/lib/python3.8/site-packages/requests/models.py", line 971, in json
    return complexjson.loads(self.text, **kwargs)
  File "/usr/local/lib/python3.8/json/__init__.py", line 357, in loads
    return _default_decoder.decode(s)
  File "/usr/local/lib/python3.8/json/decoder.py", line 337, in decode
    obj, end = self.raw_decode(s, idx=_w(s, 0).end())
  File "/usr/local/lib/python3.8/json/decoder.py", line 355, in raw_decode
    raise JSONDecodeError("Expecting value", s, err.value) from None
json.decoder.JSONDecodeError: Expecting value: line 1 column 1 (char 0)

During handling of the above exception, another exception occurred:

Traceback (most recent call last):
  File "/home/airflow/.local/lib/python3.8/site-packages/airflow/models/dagbag.py", line 344, in parse
    loader.exec_module(new_module)
  File "<frozen importlib._bootstrap_external>", line 843, in exec_module
  File "<frozen importlib._bootstrap>", line 219, in _call_with_frames_removed
  File "/opt/airflow/dags/flight_etl_dag.py", line 8, in <module>
    from extract import extract
  File "/opt/airflow/extract.py", line 21, in <module>
    extract()
  File "/opt/airflow/extract.py", line 7, in extract
    data=response.json()
  File "/home/airflow/.local/lib/python3.8/site-packages/requests/models.py", line 975, in json
    raise RequestsJSONDecodeError(e.msg, e.doc, e.pos)
requests.exceptions.JSONDecodeError: Expecting value: line 1 column 1 (char 0)
[2025-07-12T01:48:54.638+0000] {processor.py:842} WARNING - No viable dags retrieved from /opt/airflow/dags/flight_etl_dag.py
[2025-07-12T01:48:54.672+0000] {processor.py:183} INFO - Processing /opt/airflow/dags/flight_etl_dag.py took 0.733 seconds
[2025-07-12T01:49:24.946+0000] {processor.py:161} INFO - Started process (PID=1280) to work on /opt/airflow/dags/flight_etl_dag.py
[2025-07-12T01:49:24.948+0000] {processor.py:830} INFO - Processing file /opt/airflow/dags/flight_etl_dag.py for tasks to queue
[2025-07-12T01:49:24.952+0000] {logging_mixin.py:188} INFO - [2025-07-12T01:49:24.952+0000] {dagbag.py:538} INFO - Filling up the DagBag from /opt/airflow/dags/flight_etl_dag.py
[2025-07-12T01:49:25.715+0000] {logging_mixin.py:188} INFO - [2025-07-12T01:49:25.651+0000] {dagbag.py:348} ERROR - Failed to import: /opt/airflow/dags/flight_etl_dag.py
Traceback (most recent call last):
  File "/home/airflow/.local/lib/python3.8/site-packages/requests/models.py", line 971, in json
    return complexjson.loads(self.text, **kwargs)
  File "/usr/local/lib/python3.8/json/__init__.py", line 357, in loads
    return _default_decoder.decode(s)
  File "/usr/local/lib/python3.8/json/decoder.py", line 337, in decode
    obj, end = self.raw_decode(s, idx=_w(s, 0).end())
  File "/usr/local/lib/python3.8/json/decoder.py", line 355, in raw_decode
    raise JSONDecodeError("Expecting value", s, err.value) from None
json.decoder.JSONDecodeError: Expecting value: line 1 column 1 (char 0)

During handling of the above exception, another exception occurred:

Traceback (most recent call last):
  File "/home/airflow/.local/lib/python3.8/site-packages/airflow/models/dagbag.py", line 344, in parse
    loader.exec_module(new_module)
  File "<frozen importlib._bootstrap_external>", line 843, in exec_module
  File "<frozen importlib._bootstrap>", line 219, in _call_with_frames_removed
  File "/opt/airflow/dags/flight_etl_dag.py", line 8, in <module>
    from extract import extract
  File "/opt/airflow/extract.py", line 21, in <module>
    extract()
  File "/opt/airflow/extract.py", line 7, in extract
    data=response.json()
  File "/home/airflow/.local/lib/python3.8/site-packages/requests/models.py", line 975, in json
    raise RequestsJSONDecodeError(e.msg, e.doc, e.pos)
requests.exceptions.JSONDecodeError: Expecting value: line 1 column 1 (char 0)
[2025-07-12T01:49:25.725+0000] {processor.py:842} WARNING - No viable dags retrieved from /opt/airflow/dags/flight_etl_dag.py
[2025-07-12T01:49:25.754+0000] {processor.py:183} INFO - Processing /opt/airflow/dags/flight_etl_dag.py took 0.813 seconds
[2025-07-12T01:49:56.140+0000] {processor.py:161} INFO - Started process (PID=1339) to work on /opt/airflow/dags/flight_etl_dag.py
[2025-07-12T01:49:56.144+0000] {processor.py:830} INFO - Processing file /opt/airflow/dags/flight_etl_dag.py for tasks to queue
[2025-07-12T01:49:56.157+0000] {logging_mixin.py:188} INFO - [2025-07-12T01:49:56.156+0000] {dagbag.py:538} INFO - Filling up the DagBag from /opt/airflow/dags/flight_etl_dag.py
[2025-07-12T01:49:56.900+0000] {logging_mixin.py:188} INFO - [2025-07-12T01:49:56.880+0000] {dagbag.py:348} ERROR - Failed to import: /opt/airflow/dags/flight_etl_dag.py
Traceback (most recent call last):
  File "/home/airflow/.local/lib/python3.8/site-packages/requests/models.py", line 971, in json
    return complexjson.loads(self.text, **kwargs)
  File "/usr/local/lib/python3.8/json/__init__.py", line 357, in loads
    return _default_decoder.decode(s)
  File "/usr/local/lib/python3.8/json/decoder.py", line 337, in decode
    obj, end = self.raw_decode(s, idx=_w(s, 0).end())
  File "/usr/local/lib/python3.8/json/decoder.py", line 355, in raw_decode
    raise JSONDecodeError("Expecting value", s, err.value) from None
json.decoder.JSONDecodeError: Expecting value: line 1 column 1 (char 0)

During handling of the above exception, another exception occurred:

Traceback (most recent call last):
  File "/home/airflow/.local/lib/python3.8/site-packages/airflow/models/dagbag.py", line 344, in parse
    loader.exec_module(new_module)
  File "<frozen importlib._bootstrap_external>", line 843, in exec_module
  File "<frozen importlib._bootstrap>", line 219, in _call_with_frames_removed
  File "/opt/airflow/dags/flight_etl_dag.py", line 8, in <module>
    from extract import extract
  File "/opt/airflow/extract.py", line 21, in <module>
    extract()
  File "/opt/airflow/extract.py", line 7, in extract
    data=response.json()
  File "/home/airflow/.local/lib/python3.8/site-packages/requests/models.py", line 975, in json
    raise RequestsJSONDecodeError(e.msg, e.doc, e.pos)
requests.exceptions.JSONDecodeError: Expecting value: line 1 column 1 (char 0)
[2025-07-12T01:49:56.904+0000] {processor.py:842} WARNING - No viable dags retrieved from /opt/airflow/dags/flight_etl_dag.py
[2025-07-12T01:49:56.959+0000] {processor.py:183} INFO - Processing /opt/airflow/dags/flight_etl_dag.py took 0.825 seconds
[2025-07-12T01:50:27.167+0000] {processor.py:161} INFO - Started process (PID=1399) to work on /opt/airflow/dags/flight_etl_dag.py
[2025-07-12T01:50:27.169+0000] {processor.py:830} INFO - Processing file /opt/airflow/dags/flight_etl_dag.py for tasks to queue
[2025-07-12T01:50:27.171+0000] {logging_mixin.py:188} INFO - [2025-07-12T01:50:27.171+0000] {dagbag.py:538} INFO - Filling up the DagBag from /opt/airflow/dags/flight_etl_dag.py
[2025-07-12T01:50:27.853+0000] {logging_mixin.py:188} INFO - [2025-07-12T01:50:27.824+0000] {dagbag.py:348} ERROR - Failed to import: /opt/airflow/dags/flight_etl_dag.py
Traceback (most recent call last):
  File "/home/airflow/.local/lib/python3.8/site-packages/requests/models.py", line 971, in json
    return complexjson.loads(self.text, **kwargs)
  File "/usr/local/lib/python3.8/json/__init__.py", line 357, in loads
    return _default_decoder.decode(s)
  File "/usr/local/lib/python3.8/json/decoder.py", line 337, in decode
    obj, end = self.raw_decode(s, idx=_w(s, 0).end())
  File "/usr/local/lib/python3.8/json/decoder.py", line 355, in raw_decode
    raise JSONDecodeError("Expecting value", s, err.value) from None
json.decoder.JSONDecodeError: Expecting value: line 1 column 1 (char 0)

During handling of the above exception, another exception occurred:

Traceback (most recent call last):
  File "/home/airflow/.local/lib/python3.8/site-packages/airflow/models/dagbag.py", line 344, in parse
    loader.exec_module(new_module)
  File "<frozen importlib._bootstrap_external>", line 843, in exec_module
  File "<frozen importlib._bootstrap>", line 219, in _call_with_frames_removed
  File "/opt/airflow/dags/flight_etl_dag.py", line 8, in <module>
    from extract import extract
  File "/opt/airflow/extract.py", line 21, in <module>
    extract()
  File "/opt/airflow/extract.py", line 7, in extract
    data=response.json()
  File "/home/airflow/.local/lib/python3.8/site-packages/requests/models.py", line 975, in json
    raise RequestsJSONDecodeError(e.msg, e.doc, e.pos)
requests.exceptions.JSONDecodeError: Expecting value: line 1 column 1 (char 0)
[2025-07-12T01:50:27.861+0000] {processor.py:842} WARNING - No viable dags retrieved from /opt/airflow/dags/flight_etl_dag.py
[2025-07-12T01:50:27.910+0000] {processor.py:183} INFO - Processing /opt/airflow/dags/flight_etl_dag.py took 0.747 seconds
[2025-07-12T01:50:58.112+0000] {processor.py:161} INFO - Started process (PID=1456) to work on /opt/airflow/dags/flight_etl_dag.py
[2025-07-12T01:50:58.115+0000] {processor.py:830} INFO - Processing file /opt/airflow/dags/flight_etl_dag.py for tasks to queue
[2025-07-12T01:50:58.118+0000] {logging_mixin.py:188} INFO - [2025-07-12T01:50:58.117+0000] {dagbag.py:538} INFO - Filling up the DagBag from /opt/airflow/dags/flight_etl_dag.py
[2025-07-12T01:50:58.862+0000] {logging_mixin.py:188} INFO - [2025-07-12T01:50:58.834+0000] {dagbag.py:348} ERROR - Failed to import: /opt/airflow/dags/flight_etl_dag.py
Traceback (most recent call last):
  File "/home/airflow/.local/lib/python3.8/site-packages/requests/models.py", line 971, in json
    return complexjson.loads(self.text, **kwargs)
  File "/usr/local/lib/python3.8/json/__init__.py", line 357, in loads
    return _default_decoder.decode(s)
  File "/usr/local/lib/python3.8/json/decoder.py", line 337, in decode
    obj, end = self.raw_decode(s, idx=_w(s, 0).end())
  File "/usr/local/lib/python3.8/json/decoder.py", line 355, in raw_decode
    raise JSONDecodeError("Expecting value", s, err.value) from None
json.decoder.JSONDecodeError: Expecting value: line 1 column 1 (char 0)

During handling of the above exception, another exception occurred:

Traceback (most recent call last):
  File "/home/airflow/.local/lib/python3.8/site-packages/airflow/models/dagbag.py", line 344, in parse
    loader.exec_module(new_module)
  File "<frozen importlib._bootstrap_external>", line 843, in exec_module
  File "<frozen importlib._bootstrap>", line 219, in _call_with_frames_removed
  File "/opt/airflow/dags/flight_etl_dag.py", line 8, in <module>
    from extract import extract
  File "/opt/airflow/extract.py", line 21, in <module>
    extract()
  File "/opt/airflow/extract.py", line 7, in extract
    data=response.json()
  File "/home/airflow/.local/lib/python3.8/site-packages/requests/models.py", line 975, in json
    raise RequestsJSONDecodeError(e.msg, e.doc, e.pos)
requests.exceptions.JSONDecodeError: Expecting value: line 1 column 1 (char 0)
[2025-07-12T01:50:58.867+0000] {processor.py:842} WARNING - No viable dags retrieved from /opt/airflow/dags/flight_etl_dag.py
[2025-07-12T01:50:58.901+0000] {processor.py:183} INFO - Processing /opt/airflow/dags/flight_etl_dag.py took 0.795 seconds
[2025-07-12T01:51:29.011+0000] {processor.py:161} INFO - Started process (PID=1514) to work on /opt/airflow/dags/flight_etl_dag.py
[2025-07-12T01:51:29.013+0000] {processor.py:830} INFO - Processing file /opt/airflow/dags/flight_etl_dag.py for tasks to queue
[2025-07-12T01:51:29.016+0000] {logging_mixin.py:188} INFO - [2025-07-12T01:51:29.016+0000] {dagbag.py:538} INFO - Filling up the DagBag from /opt/airflow/dags/flight_etl_dag.py
[2025-07-12T01:51:29.791+0000] {logging_mixin.py:188} INFO - [2025-07-12T01:51:29.760+0000] {dagbag.py:348} ERROR - Failed to import: /opt/airflow/dags/flight_etl_dag.py
Traceback (most recent call last):
  File "/home/airflow/.local/lib/python3.8/site-packages/requests/models.py", line 971, in json
    return complexjson.loads(self.text, **kwargs)
  File "/usr/local/lib/python3.8/json/__init__.py", line 357, in loads
    return _default_decoder.decode(s)
  File "/usr/local/lib/python3.8/json/decoder.py", line 337, in decode
    obj, end = self.raw_decode(s, idx=_w(s, 0).end())
  File "/usr/local/lib/python3.8/json/decoder.py", line 355, in raw_decode
    raise JSONDecodeError("Expecting value", s, err.value) from None
json.decoder.JSONDecodeError: Expecting value: line 1 column 1 (char 0)

During handling of the above exception, another exception occurred:

Traceback (most recent call last):
  File "/home/airflow/.local/lib/python3.8/site-packages/airflow/models/dagbag.py", line 344, in parse
    loader.exec_module(new_module)
  File "<frozen importlib._bootstrap_external>", line 843, in exec_module
  File "<frozen importlib._bootstrap>", line 219, in _call_with_frames_removed
  File "/opt/airflow/dags/flight_etl_dag.py", line 8, in <module>
    from extract import extract
  File "/opt/airflow/extract.py", line 21, in <module>
    extract()
  File "/opt/airflow/extract.py", line 7, in extract
    data=response.json()
  File "/home/airflow/.local/lib/python3.8/site-packages/requests/models.py", line 975, in json
    raise RequestsJSONDecodeError(e.msg, e.doc, e.pos)
requests.exceptions.JSONDecodeError: Expecting value: line 1 column 1 (char 0)
[2025-07-12T01:51:29.797+0000] {processor.py:842} WARNING - No viable dags retrieved from /opt/airflow/dags/flight_etl_dag.py
[2025-07-12T01:51:29.838+0000] {processor.py:183} INFO - Processing /opt/airflow/dags/flight_etl_dag.py took 0.833 seconds
[2025-07-12T01:52:00.379+0000] {processor.py:161} INFO - Started process (PID=1570) to work on /opt/airflow/dags/flight_etl_dag.py
[2025-07-12T01:52:00.381+0000] {processor.py:830} INFO - Processing file /opt/airflow/dags/flight_etl_dag.py for tasks to queue
[2025-07-12T01:52:00.385+0000] {logging_mixin.py:188} INFO - [2025-07-12T01:52:00.385+0000] {dagbag.py:538} INFO - Filling up the DagBag from /opt/airflow/dags/flight_etl_dag.py
[2025-07-12T01:52:01.227+0000] {logging_mixin.py:188} INFO - [2025-07-12T01:52:01.195+0000] {dagbag.py:348} ERROR - Failed to import: /opt/airflow/dags/flight_etl_dag.py
Traceback (most recent call last):
  File "/home/airflow/.local/lib/python3.8/site-packages/requests/models.py", line 971, in json
    return complexjson.loads(self.text, **kwargs)
  File "/usr/local/lib/python3.8/json/__init__.py", line 357, in loads
    return _default_decoder.decode(s)
  File "/usr/local/lib/python3.8/json/decoder.py", line 337, in decode
    obj, end = self.raw_decode(s, idx=_w(s, 0).end())
  File "/usr/local/lib/python3.8/json/decoder.py", line 355, in raw_decode
    raise JSONDecodeError("Expecting value", s, err.value) from None
json.decoder.JSONDecodeError: Expecting value: line 1 column 1 (char 0)

During handling of the above exception, another exception occurred:

Traceback (most recent call last):
  File "/home/airflow/.local/lib/python3.8/site-packages/airflow/models/dagbag.py", line 344, in parse
    loader.exec_module(new_module)
  File "<frozen importlib._bootstrap_external>", line 843, in exec_module
  File "<frozen importlib._bootstrap>", line 219, in _call_with_frames_removed
  File "/opt/airflow/dags/flight_etl_dag.py", line 8, in <module>
    from extract import extract
  File "/opt/airflow/extract.py", line 21, in <module>
    extract()
  File "/opt/airflow/extract.py", line 7, in extract
    data=response.json()
  File "/home/airflow/.local/lib/python3.8/site-packages/requests/models.py", line 975, in json
    raise RequestsJSONDecodeError(e.msg, e.doc, e.pos)
requests.exceptions.JSONDecodeError: Expecting value: line 1 column 1 (char 0)
[2025-07-12T01:52:01.231+0000] {processor.py:842} WARNING - No viable dags retrieved from /opt/airflow/dags/flight_etl_dag.py
[2025-07-12T01:52:01.261+0000] {processor.py:183} INFO - Processing /opt/airflow/dags/flight_etl_dag.py took 0.890 seconds
[2025-07-12T01:52:31.723+0000] {processor.py:161} INFO - Started process (PID=1626) to work on /opt/airflow/dags/flight_etl_dag.py
[2025-07-12T01:52:31.725+0000] {processor.py:830} INFO - Processing file /opt/airflow/dags/flight_etl_dag.py for tasks to queue
[2025-07-12T01:52:31.728+0000] {logging_mixin.py:188} INFO - [2025-07-12T01:52:31.728+0000] {dagbag.py:538} INFO - Filling up the DagBag from /opt/airflow/dags/flight_etl_dag.py
[2025-07-12T01:52:32.579+0000] {logging_mixin.py:188} INFO - [2025-07-12T01:52:32.548+0000] {dagbag.py:348} ERROR - Failed to import: /opt/airflow/dags/flight_etl_dag.py
Traceback (most recent call last):
  File "/home/airflow/.local/lib/python3.8/site-packages/requests/models.py", line 971, in json
    return complexjson.loads(self.text, **kwargs)
  File "/usr/local/lib/python3.8/json/__init__.py", line 357, in loads
    return _default_decoder.decode(s)
  File "/usr/local/lib/python3.8/json/decoder.py", line 337, in decode
    obj, end = self.raw_decode(s, idx=_w(s, 0).end())
  File "/usr/local/lib/python3.8/json/decoder.py", line 355, in raw_decode
    raise JSONDecodeError("Expecting value", s, err.value) from None
json.decoder.JSONDecodeError: Expecting value: line 1 column 1 (char 0)

During handling of the above exception, another exception occurred:

Traceback (most recent call last):
  File "/home/airflow/.local/lib/python3.8/site-packages/airflow/models/dagbag.py", line 344, in parse
    loader.exec_module(new_module)
  File "<frozen importlib._bootstrap_external>", line 843, in exec_module
  File "<frozen importlib._bootstrap>", line 219, in _call_with_frames_removed
  File "/opt/airflow/dags/flight_etl_dag.py", line 8, in <module>
    from extract import extract
  File "/opt/airflow/extract.py", line 21, in <module>
    extract()
  File "/opt/airflow/extract.py", line 7, in extract
    data=response.json()
  File "/home/airflow/.local/lib/python3.8/site-packages/requests/models.py", line 975, in json
    raise RequestsJSONDecodeError(e.msg, e.doc, e.pos)
requests.exceptions.JSONDecodeError: Expecting value: line 1 column 1 (char 0)
[2025-07-12T01:52:32.584+0000] {processor.py:842} WARNING - No viable dags retrieved from /opt/airflow/dags/flight_etl_dag.py
[2025-07-12T01:52:32.627+0000] {processor.py:183} INFO - Processing /opt/airflow/dags/flight_etl_dag.py took 0.909 seconds
[2025-07-12T01:53:03.534+0000] {processor.py:161} INFO - Started process (PID=1682) to work on /opt/airflow/dags/flight_etl_dag.py
[2025-07-12T01:53:03.536+0000] {processor.py:830} INFO - Processing file /opt/airflow/dags/flight_etl_dag.py for tasks to queue
[2025-07-12T01:53:03.540+0000] {logging_mixin.py:188} INFO - [2025-07-12T01:53:03.539+0000] {dagbag.py:538} INFO - Filling up the DagBag from /opt/airflow/dags/flight_etl_dag.py
[2025-07-12T01:53:04.536+0000] {processor.py:840} INFO - DAG(s) 'flight_etl_dag' retrieved from /opt/airflow/dags/flight_etl_dag.py
[2025-07-12T01:53:04.677+0000] {logging_mixin.py:188} INFO - [2025-07-12T01:53:04.675+0000] {override.py:1769} INFO - Created Permission View: can edit on DAG:flight_etl_dag
[2025-07-12T01:53:04.697+0000] {logging_mixin.py:188} INFO - [2025-07-12T01:53:04.696+0000] {override.py:1769} INFO - Created Permission View: can delete on DAG:flight_etl_dag
[2025-07-12T01:53:04.711+0000] {logging_mixin.py:188} INFO - [2025-07-12T01:53:04.710+0000] {override.py:1769} INFO - Created Permission View: can read on DAG:flight_etl_dag
[2025-07-12T01:53:04.712+0000] {logging_mixin.py:188} INFO - [2025-07-12T01:53:04.712+0000] {dag.py:3036} INFO - Sync 1 DAGs
[2025-07-12T01:53:04.730+0000] {logging_mixin.py:188} INFO - [2025-07-12T01:53:04.729+0000] {dag.py:3058} INFO - Creating ORM DAG for flight_etl_dag
[2025-07-12T01:53:04.744+0000] {logging_mixin.py:188} INFO - [2025-07-12T01:53:04.744+0000] {dag.py:3823} INFO - Setting next_dagrun for flight_etl_dag to 2025-07-11 00:00:00+00:00, run_after=2025-07-12 00:00:00+00:00
[2025-07-12T01:53:04.784+0000] {processor.py:183} INFO - Processing /opt/airflow/dags/flight_etl_dag.py took 1.255 seconds
[2025-07-12T01:54:12.021+0000] {processor.py:161} INFO - Started process (PID=60) to work on /opt/airflow/dags/flight_etl_dag.py
[2025-07-12T01:54:12.023+0000] {processor.py:830} INFO - Processing file /opt/airflow/dags/flight_etl_dag.py for tasks to queue
[2025-07-12T01:54:12.027+0000] {logging_mixin.py:188} INFO - [2025-07-12T01:54:12.026+0000] {dagbag.py:538} INFO - Filling up the DagBag from /opt/airflow/dags/flight_etl_dag.py
[2025-07-12T01:54:13.898+0000] {processor.py:840} INFO - DAG(s) 'flight_etl_dag' retrieved from /opt/airflow/dags/flight_etl_dag.py
[2025-07-12T01:54:14.317+0000] {logging_mixin.py:188} INFO - [2025-07-12T01:54:14.316+0000] {override.py:1769} INFO - Created Permission View: can read on DAG:flight_etl_dag
[2025-07-12T01:54:14.342+0000] {logging_mixin.py:188} INFO - [2025-07-12T01:54:14.341+0000] {override.py:1769} INFO - Created Permission View: can delete on DAG:flight_etl_dag
[2025-07-12T01:54:14.358+0000] {logging_mixin.py:188} INFO - [2025-07-12T01:54:14.357+0000] {override.py:1769} INFO - Created Permission View: can edit on DAG:flight_etl_dag
[2025-07-12T01:54:14.360+0000] {logging_mixin.py:188} INFO - [2025-07-12T01:54:14.359+0000] {dag.py:3036} INFO - Sync 1 DAGs
[2025-07-12T01:54:14.377+0000] {logging_mixin.py:188} INFO - [2025-07-12T01:54:14.377+0000] {dag.py:3058} INFO - Creating ORM DAG for flight_etl_dag
[2025-07-12T01:54:14.393+0000] {logging_mixin.py:188} INFO - [2025-07-12T01:54:14.392+0000] {dag.py:3823} INFO - Setting next_dagrun for flight_etl_dag to 2025-07-11 00:00:00+00:00, run_after=2025-07-12 00:00:00+00:00
[2025-07-12T01:54:14.435+0000] {processor.py:183} INFO - Processing /opt/airflow/dags/flight_etl_dag.py took 2.419 seconds
[2025-07-12T01:54:45.135+0000] {processor.py:161} INFO - Started process (PID=126) to work on /opt/airflow/dags/flight_etl_dag.py
[2025-07-12T01:54:45.137+0000] {processor.py:830} INFO - Processing file /opt/airflow/dags/flight_etl_dag.py for tasks to queue
[2025-07-12T01:54:45.141+0000] {logging_mixin.py:188} INFO - [2025-07-12T01:54:45.141+0000] {dagbag.py:538} INFO - Filling up the DagBag from /opt/airflow/dags/flight_etl_dag.py
[2025-07-12T01:54:46.031+0000] {processor.py:840} INFO - DAG(s) 'flight_etl_dag' retrieved from /opt/airflow/dags/flight_etl_dag.py
[2025-07-12T01:54:46.052+0000] {logging_mixin.py:188} INFO - [2025-07-12T01:54:46.052+0000] {dag.py:3036} INFO - Sync 1 DAGs
[2025-07-12T01:54:46.078+0000] {logging_mixin.py:188} INFO - [2025-07-12T01:54:46.077+0000] {dag.py:3823} INFO - Setting next_dagrun for flight_etl_dag to 2025-07-11 00:00:00+00:00, run_after=2025-07-12 00:00:00+00:00
[2025-07-12T01:54:46.110+0000] {processor.py:183} INFO - Processing /opt/airflow/dags/flight_etl_dag.py took 0.981 seconds
[2025-07-12T01:55:16.253+0000] {processor.py:161} INFO - Started process (PID=187) to work on /opt/airflow/dags/flight_etl_dag.py
[2025-07-12T01:55:16.255+0000] {processor.py:830} INFO - Processing file /opt/airflow/dags/flight_etl_dag.py for tasks to queue
[2025-07-12T01:55:16.259+0000] {logging_mixin.py:188} INFO - [2025-07-12T01:55:16.258+0000] {dagbag.py:538} INFO - Filling up the DagBag from /opt/airflow/dags/flight_etl_dag.py
[2025-07-12T01:55:17.052+0000] {processor.py:840} INFO - DAG(s) 'flight_etl_dag' retrieved from /opt/airflow/dags/flight_etl_dag.py
[2025-07-12T01:55:17.076+0000] {logging_mixin.py:188} INFO - [2025-07-12T01:55:17.075+0000] {dag.py:3036} INFO - Sync 1 DAGs
[2025-07-12T01:55:17.103+0000] {logging_mixin.py:188} INFO - [2025-07-12T01:55:17.103+0000] {dag.py:3823} INFO - Setting next_dagrun for flight_etl_dag to 2025-07-11 00:00:00+00:00, run_after=2025-07-12 00:00:00+00:00
[2025-07-12T01:55:17.134+0000] {processor.py:183} INFO - Processing /opt/airflow/dags/flight_etl_dag.py took 0.887 seconds
[2025-07-12T01:55:47.424+0000] {processor.py:161} INFO - Started process (PID=249) to work on /opt/airflow/dags/flight_etl_dag.py
[2025-07-12T01:55:47.426+0000] {processor.py:830} INFO - Processing file /opt/airflow/dags/flight_etl_dag.py for tasks to queue
[2025-07-12T01:55:47.429+0000] {logging_mixin.py:188} INFO - [2025-07-12T01:55:47.428+0000] {dagbag.py:538} INFO - Filling up the DagBag from /opt/airflow/dags/flight_etl_dag.py
[2025-07-12T01:55:48.194+0000] {processor.py:840} INFO - DAG(s) 'flight_etl_dag' retrieved from /opt/airflow/dags/flight_etl_dag.py
[2025-07-12T01:55:48.221+0000] {logging_mixin.py:188} INFO - [2025-07-12T01:55:48.220+0000] {dag.py:3036} INFO - Sync 1 DAGs
[2025-07-12T01:55:48.250+0000] {logging_mixin.py:188} INFO - [2025-07-12T01:55:48.250+0000] {dag.py:3823} INFO - Setting next_dagrun for flight_etl_dag to 2025-07-12 00:00:00+00:00, run_after=2025-07-13 00:00:00+00:00
[2025-07-12T01:55:48.283+0000] {processor.py:183} INFO - Processing /opt/airflow/dags/flight_etl_dag.py took 0.864 seconds
[2025-07-12T01:56:18.367+0000] {processor.py:161} INFO - Started process (PID=309) to work on /opt/airflow/dags/flight_etl_dag.py
[2025-07-12T01:56:18.369+0000] {processor.py:830} INFO - Processing file /opt/airflow/dags/flight_etl_dag.py for tasks to queue
[2025-07-12T01:56:18.372+0000] {logging_mixin.py:188} INFO - [2025-07-12T01:56:18.372+0000] {dagbag.py:538} INFO - Filling up the DagBag from /opt/airflow/dags/flight_etl_dag.py
[2025-07-12T01:56:19.146+0000] {processor.py:840} INFO - DAG(s) 'flight_etl_dag' retrieved from /opt/airflow/dags/flight_etl_dag.py
[2025-07-12T01:56:19.179+0000] {logging_mixin.py:188} INFO - [2025-07-12T01:56:19.178+0000] {dag.py:3036} INFO - Sync 1 DAGs
[2025-07-12T01:56:19.213+0000] {logging_mixin.py:188} INFO - [2025-07-12T01:56:19.212+0000] {dag.py:3823} INFO - Setting next_dagrun for flight_etl_dag to 2025-07-12 00:00:00+00:00, run_after=2025-07-13 00:00:00+00:00
[2025-07-12T01:56:19.265+0000] {processor.py:183} INFO - Processing /opt/airflow/dags/flight_etl_dag.py took 0.903 seconds
[2025-07-12T01:56:49.977+0000] {processor.py:161} INFO - Started process (PID=370) to work on /opt/airflow/dags/flight_etl_dag.py
[2025-07-12T01:56:49.979+0000] {processor.py:830} INFO - Processing file /opt/airflow/dags/flight_etl_dag.py for tasks to queue
[2025-07-12T01:56:49.983+0000] {logging_mixin.py:188} INFO - [2025-07-12T01:56:49.982+0000] {dagbag.py:538} INFO - Filling up the DagBag from /opt/airflow/dags/flight_etl_dag.py
[2025-07-12T01:56:50.619+0000] {processor.py:840} INFO - DAG(s) 'flight_etl_dag' retrieved from /opt/airflow/dags/flight_etl_dag.py
[2025-07-12T01:56:50.643+0000] {logging_mixin.py:188} INFO - [2025-07-12T01:56:50.643+0000] {dag.py:3036} INFO - Sync 1 DAGs
[2025-07-12T01:56:50.671+0000] {logging_mixin.py:188} INFO - [2025-07-12T01:56:50.671+0000] {dag.py:3823} INFO - Setting next_dagrun for flight_etl_dag to 2025-07-12 00:00:00+00:00, run_after=2025-07-13 00:00:00+00:00
[2025-07-12T01:56:50.703+0000] {processor.py:183} INFO - Processing /opt/airflow/dags/flight_etl_dag.py took 0.731 seconds
