[2025-07-10T00:01:34.095+0000] {processor.py:161} INFO - Started process (PID=67) to work on /opt/airflow/dags/flight_etl_dag.py
[2025-07-10T00:01:34.098+0000] {processor.py:830} INFO - Processing file /opt/airflow/dags/flight_etl_dag.py for tasks to queue
[2025-07-10T00:01:34.102+0000] {logging_mixin.py:188} INFO - [2025-07-10T00:01:34.102+0000] {dagbag.py:538} INFO - Filling up the DagBag from /opt/airflow/dags/flight_etl_dag.py
[2025-07-10T00:01:34.912+0000] {logging_mixin.py:188} INFO - [2025-07-10T00:01:34.889+0000] {dagbag.py:348} ERROR - Failed to import: /opt/airflow/dags/flight_etl_dag.py
Traceback (most recent call last):
  File "/home/airflow/.local/lib/python3.8/site-packages/requests/models.py", line 971, in json
    return complexjson.loads(self.text, **kwargs)
  File "/usr/local/lib/python3.8/json/__init__.py", line 357, in loads
    return _default_decoder.decode(s)
  File "/usr/local/lib/python3.8/json/decoder.py", line 337, in decode
    obj, end = self.raw_decode(s, idx=_w(s, 0).end())
  File "/usr/local/lib/python3.8/json/decoder.py", line 355, in raw_decode
    raise JSONDecodeError("Expecting value", s, err.value) from None
json.decoder.JSONDecodeError: Expecting value: line 1 column 1 (char 0)

During handling of the above exception, another exception occurred:

Traceback (most recent call last):
  File "/home/airflow/.local/lib/python3.8/site-packages/airflow/models/dagbag.py", line 344, in parse
    loader.exec_module(new_module)
  File "<frozen importlib._bootstrap_external>", line 843, in exec_module
  File "<frozen importlib._bootstrap>", line 219, in _call_with_frames_removed
  File "/opt/airflow/dags/flight_etl_dag.py", line 8, in <module>
    from extract import extract
  File "/opt/airflow/extract.py", line 21, in <module>
    extract()
  File "/opt/airflow/extract.py", line 7, in extract
    data=response.json()
  File "/home/airflow/.local/lib/python3.8/site-packages/requests/models.py", line 975, in json
    raise RequestsJSONDecodeError(e.msg, e.doc, e.pos)
requests.exceptions.JSONDecodeError: Expecting value: line 1 column 1 (char 0)
[2025-07-10T00:01:34.918+0000] {processor.py:842} WARNING - No viable dags retrieved from /opt/airflow/dags/flight_etl_dag.py
[2025-07-10T00:01:34.953+0000] {processor.py:183} INFO - Processing /opt/airflow/dags/flight_etl_dag.py took 0.864 seconds
[2025-07-10T00:02:05.018+0000] {processor.py:161} INFO - Started process (PID=124) to work on /opt/airflow/dags/flight_etl_dag.py
[2025-07-10T00:02:05.020+0000] {processor.py:830} INFO - Processing file /opt/airflow/dags/flight_etl_dag.py for tasks to queue
[2025-07-10T00:02:05.023+0000] {logging_mixin.py:188} INFO - [2025-07-10T00:02:05.022+0000] {dagbag.py:538} INFO - Filling up the DagBag from /opt/airflow/dags/flight_etl_dag.py
[2025-07-10T00:02:05.732+0000] {logging_mixin.py:188} INFO - [2025-07-10T00:02:05.713+0000] {dagbag.py:348} ERROR - Failed to import: /opt/airflow/dags/flight_etl_dag.py
Traceback (most recent call last):
  File "/home/airflow/.local/lib/python3.8/site-packages/requests/models.py", line 971, in json
    return complexjson.loads(self.text, **kwargs)
  File "/usr/local/lib/python3.8/json/__init__.py", line 357, in loads
    return _default_decoder.decode(s)
  File "/usr/local/lib/python3.8/json/decoder.py", line 337, in decode
    obj, end = self.raw_decode(s, idx=_w(s, 0).end())
  File "/usr/local/lib/python3.8/json/decoder.py", line 355, in raw_decode
    raise JSONDecodeError("Expecting value", s, err.value) from None
json.decoder.JSONDecodeError: Expecting value: line 1 column 1 (char 0)

During handling of the above exception, another exception occurred:

Traceback (most recent call last):
  File "/home/airflow/.local/lib/python3.8/site-packages/airflow/models/dagbag.py", line 344, in parse
    loader.exec_module(new_module)
  File "<frozen importlib._bootstrap_external>", line 843, in exec_module
  File "<frozen importlib._bootstrap>", line 219, in _call_with_frames_removed
  File "/opt/airflow/dags/flight_etl_dag.py", line 8, in <module>
    from extract import extract
  File "/opt/airflow/extract.py", line 21, in <module>
    extract()
  File "/opt/airflow/extract.py", line 7, in extract
    data=response.json()
  File "/home/airflow/.local/lib/python3.8/site-packages/requests/models.py", line 975, in json
    raise RequestsJSONDecodeError(e.msg, e.doc, e.pos)
requests.exceptions.JSONDecodeError: Expecting value: line 1 column 1 (char 0)
[2025-07-10T00:02:05.737+0000] {processor.py:842} WARNING - No viable dags retrieved from /opt/airflow/dags/flight_etl_dag.py
[2025-07-10T00:02:05.771+0000] {processor.py:183} INFO - Processing /opt/airflow/dags/flight_etl_dag.py took 0.758 seconds
[2025-07-10T00:02:36.003+0000] {processor.py:161} INFO - Started process (PID=181) to work on /opt/airflow/dags/flight_etl_dag.py
[2025-07-10T00:02:36.004+0000] {processor.py:830} INFO - Processing file /opt/airflow/dags/flight_etl_dag.py for tasks to queue
[2025-07-10T00:02:36.007+0000] {logging_mixin.py:188} INFO - [2025-07-10T00:02:36.007+0000] {dagbag.py:538} INFO - Filling up the DagBag from /opt/airflow/dags/flight_etl_dag.py
[2025-07-10T00:02:36.756+0000] {logging_mixin.py:188} INFO - [2025-07-10T00:02:36.740+0000] {dagbag.py:348} ERROR - Failed to import: /opt/airflow/dags/flight_etl_dag.py
Traceback (most recent call last):
  File "/home/airflow/.local/lib/python3.8/site-packages/requests/models.py", line 971, in json
    return complexjson.loads(self.text, **kwargs)
  File "/usr/local/lib/python3.8/json/__init__.py", line 357, in loads
    return _default_decoder.decode(s)
  File "/usr/local/lib/python3.8/json/decoder.py", line 337, in decode
    obj, end = self.raw_decode(s, idx=_w(s, 0).end())
  File "/usr/local/lib/python3.8/json/decoder.py", line 355, in raw_decode
    raise JSONDecodeError("Expecting value", s, err.value) from None
json.decoder.JSONDecodeError: Expecting value: line 1 column 1 (char 0)

During handling of the above exception, another exception occurred:

Traceback (most recent call last):
  File "/home/airflow/.local/lib/python3.8/site-packages/airflow/models/dagbag.py", line 344, in parse
    loader.exec_module(new_module)
  File "<frozen importlib._bootstrap_external>", line 843, in exec_module
  File "<frozen importlib._bootstrap>", line 219, in _call_with_frames_removed
  File "/opt/airflow/dags/flight_etl_dag.py", line 8, in <module>
    from extract import extract
  File "/opt/airflow/extract.py", line 21, in <module>
    extract()
  File "/opt/airflow/extract.py", line 7, in extract
    data=response.json()
  File "/home/airflow/.local/lib/python3.8/site-packages/requests/models.py", line 975, in json
    raise RequestsJSONDecodeError(e.msg, e.doc, e.pos)
requests.exceptions.JSONDecodeError: Expecting value: line 1 column 1 (char 0)
[2025-07-10T00:02:36.760+0000] {processor.py:842} WARNING - No viable dags retrieved from /opt/airflow/dags/flight_etl_dag.py
[2025-07-10T00:02:36.793+0000] {processor.py:183} INFO - Processing /opt/airflow/dags/flight_etl_dag.py took 0.795 seconds
[2025-07-10T00:03:07.659+0000] {processor.py:161} INFO - Started process (PID=245) to work on /opt/airflow/dags/flight_etl_dag.py
[2025-07-10T00:03:07.672+0000] {processor.py:830} INFO - Processing file /opt/airflow/dags/flight_etl_dag.py for tasks to queue
[2025-07-10T00:03:07.678+0000] {logging_mixin.py:188} INFO - [2025-07-10T00:03:07.677+0000] {dagbag.py:538} INFO - Filling up the DagBag from /opt/airflow/dags/flight_etl_dag.py
[2025-07-10T00:03:08.397+0000] {logging_mixin.py:188} INFO - [2025-07-10T00:03:08.384+0000] {dagbag.py:348} ERROR - Failed to import: /opt/airflow/dags/flight_etl_dag.py
Traceback (most recent call last):
  File "/home/airflow/.local/lib/python3.8/site-packages/requests/models.py", line 971, in json
    return complexjson.loads(self.text, **kwargs)
  File "/usr/local/lib/python3.8/json/__init__.py", line 357, in loads
    return _default_decoder.decode(s)
  File "/usr/local/lib/python3.8/json/decoder.py", line 337, in decode
    obj, end = self.raw_decode(s, idx=_w(s, 0).end())
  File "/usr/local/lib/python3.8/json/decoder.py", line 355, in raw_decode
    raise JSONDecodeError("Expecting value", s, err.value) from None
json.decoder.JSONDecodeError: Expecting value: line 1 column 1 (char 0)

During handling of the above exception, another exception occurred:

Traceback (most recent call last):
  File "/home/airflow/.local/lib/python3.8/site-packages/airflow/models/dagbag.py", line 344, in parse
    loader.exec_module(new_module)
  File "<frozen importlib._bootstrap_external>", line 843, in exec_module
  File "<frozen importlib._bootstrap>", line 219, in _call_with_frames_removed
  File "/opt/airflow/dags/flight_etl_dag.py", line 8, in <module>
    from extract import extract
  File "/opt/airflow/extract.py", line 21, in <module>
    extract()
  File "/opt/airflow/extract.py", line 7, in extract
    data=response.json()
  File "/home/airflow/.local/lib/python3.8/site-packages/requests/models.py", line 975, in json
    raise RequestsJSONDecodeError(e.msg, e.doc, e.pos)
requests.exceptions.JSONDecodeError: Expecting value: line 1 column 1 (char 0)
[2025-07-10T00:03:08.402+0000] {processor.py:842} WARNING - No viable dags retrieved from /opt/airflow/dags/flight_etl_dag.py
[2025-07-10T00:03:08.435+0000] {processor.py:183} INFO - Processing /opt/airflow/dags/flight_etl_dag.py took 0.792 seconds
[2025-07-10T00:03:38.525+0000] {processor.py:161} INFO - Started process (PID=304) to work on /opt/airflow/dags/flight_etl_dag.py
[2025-07-10T00:03:38.527+0000] {processor.py:830} INFO - Processing file /opt/airflow/dags/flight_etl_dag.py for tasks to queue
[2025-07-10T00:03:38.530+0000] {logging_mixin.py:188} INFO - [2025-07-10T00:03:38.529+0000] {dagbag.py:538} INFO - Filling up the DagBag from /opt/airflow/dags/flight_etl_dag.py
[2025-07-10T00:03:39.436+0000] {logging_mixin.py:188} INFO - [2025-07-10T00:03:39.408+0000] {dagbag.py:348} ERROR - Failed to import: /opt/airflow/dags/flight_etl_dag.py
Traceback (most recent call last):
  File "/home/airflow/.local/lib/python3.8/site-packages/requests/models.py", line 971, in json
    return complexjson.loads(self.text, **kwargs)
  File "/usr/local/lib/python3.8/json/__init__.py", line 357, in loads
    return _default_decoder.decode(s)
  File "/usr/local/lib/python3.8/json/decoder.py", line 337, in decode
    obj, end = self.raw_decode(s, idx=_w(s, 0).end())
  File "/usr/local/lib/python3.8/json/decoder.py", line 355, in raw_decode
    raise JSONDecodeError("Expecting value", s, err.value) from None
json.decoder.JSONDecodeError: Expecting value: line 1 column 1 (char 0)

During handling of the above exception, another exception occurred:

Traceback (most recent call last):
  File "/home/airflow/.local/lib/python3.8/site-packages/airflow/models/dagbag.py", line 344, in parse
    loader.exec_module(new_module)
  File "<frozen importlib._bootstrap_external>", line 843, in exec_module
  File "<frozen importlib._bootstrap>", line 219, in _call_with_frames_removed
  File "/opt/airflow/dags/flight_etl_dag.py", line 8, in <module>
    from extract import extract
  File "/opt/airflow/extract.py", line 21, in <module>
    extract()
  File "/opt/airflow/extract.py", line 7, in extract
    data=response.json()
  File "/home/airflow/.local/lib/python3.8/site-packages/requests/models.py", line 975, in json
    raise RequestsJSONDecodeError(e.msg, e.doc, e.pos)
requests.exceptions.JSONDecodeError: Expecting value: line 1 column 1 (char 0)
[2025-07-10T00:03:39.442+0000] {processor.py:842} WARNING - No viable dags retrieved from /opt/airflow/dags/flight_etl_dag.py
[2025-07-10T00:03:39.482+0000] {processor.py:183} INFO - Processing /opt/airflow/dags/flight_etl_dag.py took 0.964 seconds
[2025-07-10T00:04:10.025+0000] {processor.py:161} INFO - Started process (PID=361) to work on /opt/airflow/dags/flight_etl_dag.py
[2025-07-10T00:04:10.028+0000] {processor.py:830} INFO - Processing file /opt/airflow/dags/flight_etl_dag.py for tasks to queue
[2025-07-10T00:04:10.031+0000] {logging_mixin.py:188} INFO - [2025-07-10T00:04:10.031+0000] {dagbag.py:538} INFO - Filling up the DagBag from /opt/airflow/dags/flight_etl_dag.py
[2025-07-10T00:04:10.774+0000] {logging_mixin.py:188} INFO - [2025-07-10T00:04:10.743+0000] {dagbag.py:348} ERROR - Failed to import: /opt/airflow/dags/flight_etl_dag.py
Traceback (most recent call last):
  File "/home/airflow/.local/lib/python3.8/site-packages/requests/models.py", line 971, in json
    return complexjson.loads(self.text, **kwargs)
  File "/usr/local/lib/python3.8/json/__init__.py", line 357, in loads
    return _default_decoder.decode(s)
  File "/usr/local/lib/python3.8/json/decoder.py", line 337, in decode
    obj, end = self.raw_decode(s, idx=_w(s, 0).end())
  File "/usr/local/lib/python3.8/json/decoder.py", line 355, in raw_decode
    raise JSONDecodeError("Expecting value", s, err.value) from None
json.decoder.JSONDecodeError: Expecting value: line 1 column 1 (char 0)

During handling of the above exception, another exception occurred:

Traceback (most recent call last):
  File "/home/airflow/.local/lib/python3.8/site-packages/airflow/models/dagbag.py", line 344, in parse
    loader.exec_module(new_module)
  File "<frozen importlib._bootstrap_external>", line 843, in exec_module
  File "<frozen importlib._bootstrap>", line 219, in _call_with_frames_removed
  File "/opt/airflow/dags/flight_etl_dag.py", line 8, in <module>
    from extract import extract
  File "/opt/airflow/extract.py", line 21, in <module>
    extract()
  File "/opt/airflow/extract.py", line 7, in extract
    data=response.json()
  File "/home/airflow/.local/lib/python3.8/site-packages/requests/models.py", line 975, in json
    raise RequestsJSONDecodeError(e.msg, e.doc, e.pos)
requests.exceptions.JSONDecodeError: Expecting value: line 1 column 1 (char 0)
[2025-07-10T00:04:10.781+0000] {processor.py:842} WARNING - No viable dags retrieved from /opt/airflow/dags/flight_etl_dag.py
[2025-07-10T00:04:10.822+0000] {processor.py:183} INFO - Processing /opt/airflow/dags/flight_etl_dag.py took 0.802 seconds
[2025-07-10T00:04:41.869+0000] {processor.py:161} INFO - Started process (PID=419) to work on /opt/airflow/dags/flight_etl_dag.py
[2025-07-10T00:04:41.871+0000] {processor.py:830} INFO - Processing file /opt/airflow/dags/flight_etl_dag.py for tasks to queue
[2025-07-10T00:04:41.874+0000] {logging_mixin.py:188} INFO - [2025-07-10T00:04:41.874+0000] {dagbag.py:538} INFO - Filling up the DagBag from /opt/airflow/dags/flight_etl_dag.py
[2025-07-10T00:04:42.654+0000] {logging_mixin.py:188} INFO - [2025-07-10T00:04:42.640+0000] {dagbag.py:348} ERROR - Failed to import: /opt/airflow/dags/flight_etl_dag.py
Traceback (most recent call last):
  File "/home/airflow/.local/lib/python3.8/site-packages/requests/models.py", line 971, in json
    return complexjson.loads(self.text, **kwargs)
  File "/usr/local/lib/python3.8/json/__init__.py", line 357, in loads
    return _default_decoder.decode(s)
  File "/usr/local/lib/python3.8/json/decoder.py", line 337, in decode
    obj, end = self.raw_decode(s, idx=_w(s, 0).end())
  File "/usr/local/lib/python3.8/json/decoder.py", line 355, in raw_decode
    raise JSONDecodeError("Expecting value", s, err.value) from None
json.decoder.JSONDecodeError: Expecting value: line 1 column 1 (char 0)

During handling of the above exception, another exception occurred:

Traceback (most recent call last):
  File "/home/airflow/.local/lib/python3.8/site-packages/airflow/models/dagbag.py", line 344, in parse
    loader.exec_module(new_module)
  File "<frozen importlib._bootstrap_external>", line 843, in exec_module
  File "<frozen importlib._bootstrap>", line 219, in _call_with_frames_removed
  File "/opt/airflow/dags/flight_etl_dag.py", line 8, in <module>
    from extract import extract
  File "/opt/airflow/extract.py", line 21, in <module>
    extract()
  File "/opt/airflow/extract.py", line 7, in extract
    data=response.json()
  File "/home/airflow/.local/lib/python3.8/site-packages/requests/models.py", line 975, in json
    raise RequestsJSONDecodeError(e.msg, e.doc, e.pos)
requests.exceptions.JSONDecodeError: Expecting value: line 1 column 1 (char 0)
[2025-07-10T00:04:42.666+0000] {processor.py:842} WARNING - No viable dags retrieved from /opt/airflow/dags/flight_etl_dag.py
[2025-07-10T02:03:28.866+0000] {processor.py:161} INFO - Started process (PID=61) to work on /opt/airflow/dags/flight_etl_dag.py
[2025-07-10T02:03:28.870+0000] {processor.py:830} INFO - Processing file /opt/airflow/dags/flight_etl_dag.py for tasks to queue
[2025-07-10T02:03:28.876+0000] {logging_mixin.py:188} INFO - [2025-07-10T02:03:28.875+0000] {dagbag.py:538} INFO - Filling up the DagBag from /opt/airflow/dags/flight_etl_dag.py
[2025-07-10T02:03:31.129+0000] {logging_mixin.py:188} INFO - [2025-07-10T02:03:31.113+0000] {dagbag.py:348} ERROR - Failed to import: /opt/airflow/dags/flight_etl_dag.py
Traceback (most recent call last):
  File "/home/airflow/.local/lib/python3.8/site-packages/requests/models.py", line 971, in json
    return complexjson.loads(self.text, **kwargs)
  File "/usr/local/lib/python3.8/json/__init__.py", line 357, in loads
    return _default_decoder.decode(s)
  File "/usr/local/lib/python3.8/json/decoder.py", line 337, in decode
    obj, end = self.raw_decode(s, idx=_w(s, 0).end())
  File "/usr/local/lib/python3.8/json/decoder.py", line 355, in raw_decode
    raise JSONDecodeError("Expecting value", s, err.value) from None
json.decoder.JSONDecodeError: Expecting value: line 1 column 1 (char 0)

During handling of the above exception, another exception occurred:

Traceback (most recent call last):
  File "/home/airflow/.local/lib/python3.8/site-packages/airflow/models/dagbag.py", line 344, in parse
    loader.exec_module(new_module)
  File "<frozen importlib._bootstrap_external>", line 843, in exec_module
  File "<frozen importlib._bootstrap>", line 219, in _call_with_frames_removed
  File "/opt/airflow/dags/flight_etl_dag.py", line 8, in <module>
    from extract import extract
  File "/opt/airflow/extract.py", line 21, in <module>
    extract()
  File "/opt/airflow/extract.py", line 7, in extract
    data=response.json()
  File "/home/airflow/.local/lib/python3.8/site-packages/requests/models.py", line 975, in json
    raise RequestsJSONDecodeError(e.msg, e.doc, e.pos)
requests.exceptions.JSONDecodeError: Expecting value: line 1 column 1 (char 0)
[2025-07-10T02:03:31.132+0000] {processor.py:842} WARNING - No viable dags retrieved from /opt/airflow/dags/flight_etl_dag.py
[2025-07-10T02:03:31.157+0000] {processor.py:183} INFO - Processing /opt/airflow/dags/flight_etl_dag.py took 2.304 seconds
[2025-07-10T02:04:01.555+0000] {processor.py:161} INFO - Started process (PID=129) to work on /opt/airflow/dags/flight_etl_dag.py
[2025-07-10T02:04:01.557+0000] {processor.py:830} INFO - Processing file /opt/airflow/dags/flight_etl_dag.py for tasks to queue
[2025-07-10T02:04:01.560+0000] {logging_mixin.py:188} INFO - [2025-07-10T02:04:01.559+0000] {dagbag.py:538} INFO - Filling up the DagBag from /opt/airflow/dags/flight_etl_dag.py
[2025-07-10T02:04:02.750+0000] {logging_mixin.py:188} INFO - [2025-07-10T02:04:02.733+0000] {dagbag.py:348} ERROR - Failed to import: /opt/airflow/dags/flight_etl_dag.py
Traceback (most recent call last):
  File "/home/airflow/.local/lib/python3.8/site-packages/requests/models.py", line 971, in json
    return complexjson.loads(self.text, **kwargs)
  File "/usr/local/lib/python3.8/json/__init__.py", line 357, in loads
    return _default_decoder.decode(s)
  File "/usr/local/lib/python3.8/json/decoder.py", line 337, in decode
    obj, end = self.raw_decode(s, idx=_w(s, 0).end())
  File "/usr/local/lib/python3.8/json/decoder.py", line 355, in raw_decode
    raise JSONDecodeError("Expecting value", s, err.value) from None
json.decoder.JSONDecodeError: Expecting value: line 1 column 1 (char 0)

During handling of the above exception, another exception occurred:

Traceback (most recent call last):
  File "/home/airflow/.local/lib/python3.8/site-packages/airflow/models/dagbag.py", line 344, in parse
    loader.exec_module(new_module)
  File "<frozen importlib._bootstrap_external>", line 843, in exec_module
  File "<frozen importlib._bootstrap>", line 219, in _call_with_frames_removed
  File "/opt/airflow/dags/flight_etl_dag.py", line 8, in <module>
    from extract import extract
  File "/opt/airflow/extract.py", line 21, in <module>
    extract()
  File "/opt/airflow/extract.py", line 7, in extract
    data=response.json()
  File "/home/airflow/.local/lib/python3.8/site-packages/requests/models.py", line 975, in json
    raise RequestsJSONDecodeError(e.msg, e.doc, e.pos)
requests.exceptions.JSONDecodeError: Expecting value: line 1 column 1 (char 0)
[2025-07-10T02:04:02.753+0000] {processor.py:842} WARNING - No viable dags retrieved from /opt/airflow/dags/flight_etl_dag.py
[2025-07-10T02:04:02.776+0000] {processor.py:183} INFO - Processing /opt/airflow/dags/flight_etl_dag.py took 1.225 seconds
[2025-07-10T02:04:33.126+0000] {processor.py:161} INFO - Started process (PID=191) to work on /opt/airflow/dags/flight_etl_dag.py
[2025-07-10T02:04:33.129+0000] {processor.py:830} INFO - Processing file /opt/airflow/dags/flight_etl_dag.py for tasks to queue
[2025-07-10T02:04:33.133+0000] {logging_mixin.py:188} INFO - [2025-07-10T02:04:33.133+0000] {dagbag.py:538} INFO - Filling up the DagBag from /opt/airflow/dags/flight_etl_dag.py
[2025-07-10T02:04:34.111+0000] {logging_mixin.py:188} INFO - [2025-07-10T02:04:34.083+0000] {dagbag.py:348} ERROR - Failed to import: /opt/airflow/dags/flight_etl_dag.py
Traceback (most recent call last):
  File "/home/airflow/.local/lib/python3.8/site-packages/requests/models.py", line 971, in json
    return complexjson.loads(self.text, **kwargs)
  File "/usr/local/lib/python3.8/json/__init__.py", line 357, in loads
    return _default_decoder.decode(s)
  File "/usr/local/lib/python3.8/json/decoder.py", line 337, in decode
    obj, end = self.raw_decode(s, idx=_w(s, 0).end())
  File "/usr/local/lib/python3.8/json/decoder.py", line 355, in raw_decode
    raise JSONDecodeError("Expecting value", s, err.value) from None
json.decoder.JSONDecodeError: Expecting value: line 1 column 1 (char 0)

During handling of the above exception, another exception occurred:

Traceback (most recent call last):
  File "/home/airflow/.local/lib/python3.8/site-packages/airflow/models/dagbag.py", line 344, in parse
    loader.exec_module(new_module)
  File "<frozen importlib._bootstrap_external>", line 843, in exec_module
  File "<frozen importlib._bootstrap>", line 219, in _call_with_frames_removed
  File "/opt/airflow/dags/flight_etl_dag.py", line 8, in <module>
    from extract import extract
  File "/opt/airflow/extract.py", line 21, in <module>
    extract()
  File "/opt/airflow/extract.py", line 7, in extract
    data=response.json()
  File "/home/airflow/.local/lib/python3.8/site-packages/requests/models.py", line 975, in json
    raise RequestsJSONDecodeError(e.msg, e.doc, e.pos)
requests.exceptions.JSONDecodeError: Expecting value: line 1 column 1 (char 0)
[2025-07-10T02:04:34.115+0000] {processor.py:842} WARNING - No viable dags retrieved from /opt/airflow/dags/flight_etl_dag.py
[2025-07-10T02:04:34.140+0000] {processor.py:183} INFO - Processing /opt/airflow/dags/flight_etl_dag.py took 1.021 seconds
[2025-07-10T02:05:04.707+0000] {processor.py:161} INFO - Started process (PID=251) to work on /opt/airflow/dags/flight_etl_dag.py
[2025-07-10T02:05:04.711+0000] {processor.py:830} INFO - Processing file /opt/airflow/dags/flight_etl_dag.py for tasks to queue
[2025-07-10T02:05:04.717+0000] {logging_mixin.py:188} INFO - [2025-07-10T02:05:04.716+0000] {dagbag.py:538} INFO - Filling up the DagBag from /opt/airflow/dags/flight_etl_dag.py
[2025-07-10T02:05:05.627+0000] {logging_mixin.py:188} INFO - [2025-07-10T02:05:05.608+0000] {dagbag.py:348} ERROR - Failed to import: /opt/airflow/dags/flight_etl_dag.py
Traceback (most recent call last):
  File "/home/airflow/.local/lib/python3.8/site-packages/requests/models.py", line 971, in json
    return complexjson.loads(self.text, **kwargs)
  File "/usr/local/lib/python3.8/json/__init__.py", line 357, in loads
    return _default_decoder.decode(s)
  File "/usr/local/lib/python3.8/json/decoder.py", line 337, in decode
    obj, end = self.raw_decode(s, idx=_w(s, 0).end())
  File "/usr/local/lib/python3.8/json/decoder.py", line 355, in raw_decode
    raise JSONDecodeError("Expecting value", s, err.value) from None
json.decoder.JSONDecodeError: Expecting value: line 1 column 1 (char 0)

During handling of the above exception, another exception occurred:

Traceback (most recent call last):
  File "/home/airflow/.local/lib/python3.8/site-packages/airflow/models/dagbag.py", line 344, in parse
    loader.exec_module(new_module)
  File "<frozen importlib._bootstrap_external>", line 843, in exec_module
  File "<frozen importlib._bootstrap>", line 219, in _call_with_frames_removed
  File "/opt/airflow/dags/flight_etl_dag.py", line 8, in <module>
    from extract import extract
  File "/opt/airflow/extract.py", line 21, in <module>
    extract()
  File "/opt/airflow/extract.py", line 7, in extract
    data=response.json()
  File "/home/airflow/.local/lib/python3.8/site-packages/requests/models.py", line 975, in json
    raise RequestsJSONDecodeError(e.msg, e.doc, e.pos)
requests.exceptions.JSONDecodeError: Expecting value: line 1 column 1 (char 0)
[2025-07-10T02:05:05.632+0000] {processor.py:842} WARNING - No viable dags retrieved from /opt/airflow/dags/flight_etl_dag.py
[2025-07-10T02:05:05.662+0000] {processor.py:183} INFO - Processing /opt/airflow/dags/flight_etl_dag.py took 0.967 seconds
[2025-07-10T02:05:35.957+0000] {processor.py:161} INFO - Started process (PID=308) to work on /opt/airflow/dags/flight_etl_dag.py
[2025-07-10T02:05:35.959+0000] {processor.py:830} INFO - Processing file /opt/airflow/dags/flight_etl_dag.py for tasks to queue
[2025-07-10T02:05:35.961+0000] {logging_mixin.py:188} INFO - [2025-07-10T02:05:35.961+0000] {dagbag.py:538} INFO - Filling up the DagBag from /opt/airflow/dags/flight_etl_dag.py
[2025-07-10T02:05:36.659+0000] {logging_mixin.py:188} INFO - [2025-07-10T02:05:36.643+0000] {dagbag.py:348} ERROR - Failed to import: /opt/airflow/dags/flight_etl_dag.py
Traceback (most recent call last):
  File "/home/airflow/.local/lib/python3.8/site-packages/requests/models.py", line 971, in json
    return complexjson.loads(self.text, **kwargs)
  File "/usr/local/lib/python3.8/json/__init__.py", line 357, in loads
    return _default_decoder.decode(s)
  File "/usr/local/lib/python3.8/json/decoder.py", line 337, in decode
    obj, end = self.raw_decode(s, idx=_w(s, 0).end())
  File "/usr/local/lib/python3.8/json/decoder.py", line 355, in raw_decode
    raise JSONDecodeError("Expecting value", s, err.value) from None
json.decoder.JSONDecodeError: Expecting value: line 1 column 1 (char 0)

During handling of the above exception, another exception occurred:

Traceback (most recent call last):
  File "/home/airflow/.local/lib/python3.8/site-packages/airflow/models/dagbag.py", line 344, in parse
    loader.exec_module(new_module)
  File "<frozen importlib._bootstrap_external>", line 843, in exec_module
  File "<frozen importlib._bootstrap>", line 219, in _call_with_frames_removed
  File "/opt/airflow/dags/flight_etl_dag.py", line 8, in <module>
    from extract import extract
  File "/opt/airflow/extract.py", line 21, in <module>
    extract()
  File "/opt/airflow/extract.py", line 7, in extract
    data=response.json()
  File "/home/airflow/.local/lib/python3.8/site-packages/requests/models.py", line 975, in json
    raise RequestsJSONDecodeError(e.msg, e.doc, e.pos)
requests.exceptions.JSONDecodeError: Expecting value: line 1 column 1 (char 0)
[2025-07-10T02:05:36.662+0000] {processor.py:842} WARNING - No viable dags retrieved from /opt/airflow/dags/flight_etl_dag.py
[2025-07-10T02:05:36.686+0000] {processor.py:183} INFO - Processing /opt/airflow/dags/flight_etl_dag.py took 0.733 seconds
[2025-07-10T02:06:07.623+0000] {processor.py:161} INFO - Started process (PID=370) to work on /opt/airflow/dags/flight_etl_dag.py
[2025-07-10T02:06:07.624+0000] {processor.py:830} INFO - Processing file /opt/airflow/dags/flight_etl_dag.py for tasks to queue
[2025-07-10T02:06:07.627+0000] {logging_mixin.py:188} INFO - [2025-07-10T02:06:07.627+0000] {dagbag.py:538} INFO - Filling up the DagBag from /opt/airflow/dags/flight_etl_dag.py
[2025-07-10T02:06:08.292+0000] {logging_mixin.py:188} INFO - [2025-07-10T02:06:08.274+0000] {dagbag.py:348} ERROR - Failed to import: /opt/airflow/dags/flight_etl_dag.py
Traceback (most recent call last):
  File "/home/airflow/.local/lib/python3.8/site-packages/requests/models.py", line 971, in json
    return complexjson.loads(self.text, **kwargs)
  File "/usr/local/lib/python3.8/json/__init__.py", line 357, in loads
    return _default_decoder.decode(s)
  File "/usr/local/lib/python3.8/json/decoder.py", line 337, in decode
    obj, end = self.raw_decode(s, idx=_w(s, 0).end())
  File "/usr/local/lib/python3.8/json/decoder.py", line 355, in raw_decode
    raise JSONDecodeError("Expecting value", s, err.value) from None
json.decoder.JSONDecodeError: Expecting value: line 1 column 1 (char 0)

During handling of the above exception, another exception occurred:

Traceback (most recent call last):
  File "/home/airflow/.local/lib/python3.8/site-packages/airflow/models/dagbag.py", line 344, in parse
    loader.exec_module(new_module)
  File "<frozen importlib._bootstrap_external>", line 843, in exec_module
  File "<frozen importlib._bootstrap>", line 219, in _call_with_frames_removed
  File "/opt/airflow/dags/flight_etl_dag.py", line 8, in <module>
    from extract import extract
  File "/opt/airflow/extract.py", line 21, in <module>
    extract()
  File "/opt/airflow/extract.py", line 7, in extract
    data=response.json()
  File "/home/airflow/.local/lib/python3.8/site-packages/requests/models.py", line 975, in json
    raise RequestsJSONDecodeError(e.msg, e.doc, e.pos)
requests.exceptions.JSONDecodeError: Expecting value: line 1 column 1 (char 0)
[2025-07-10T02:06:08.295+0000] {processor.py:842} WARNING - No viable dags retrieved from /opt/airflow/dags/flight_etl_dag.py
[2025-07-10T02:06:08.321+0000] {processor.py:183} INFO - Processing /opt/airflow/dags/flight_etl_dag.py took 0.703 seconds
[2025-07-10T02:06:38.655+0000] {processor.py:161} INFO - Started process (PID=426) to work on /opt/airflow/dags/flight_etl_dag.py
[2025-07-10T02:06:38.657+0000] {processor.py:830} INFO - Processing file /opt/airflow/dags/flight_etl_dag.py for tasks to queue
[2025-07-10T02:06:38.661+0000] {logging_mixin.py:188} INFO - [2025-07-10T02:06:38.660+0000] {dagbag.py:538} INFO - Filling up the DagBag from /opt/airflow/dags/flight_etl_dag.py
[2025-07-10T02:06:39.501+0000] {logging_mixin.py:188} INFO - [2025-07-10T02:06:39.478+0000] {dagbag.py:348} ERROR - Failed to import: /opt/airflow/dags/flight_etl_dag.py
Traceback (most recent call last):
  File "/home/airflow/.local/lib/python3.8/site-packages/requests/models.py", line 971, in json
    return complexjson.loads(self.text, **kwargs)
  File "/usr/local/lib/python3.8/json/__init__.py", line 357, in loads
    return _default_decoder.decode(s)
  File "/usr/local/lib/python3.8/json/decoder.py", line 337, in decode
    obj, end = self.raw_decode(s, idx=_w(s, 0).end())
  File "/usr/local/lib/python3.8/json/decoder.py", line 355, in raw_decode
    raise JSONDecodeError("Expecting value", s, err.value) from None
json.decoder.JSONDecodeError: Expecting value: line 1 column 1 (char 0)

During handling of the above exception, another exception occurred:

Traceback (most recent call last):
  File "/home/airflow/.local/lib/python3.8/site-packages/airflow/models/dagbag.py", line 344, in parse
    loader.exec_module(new_module)
  File "<frozen importlib._bootstrap_external>", line 843, in exec_module
  File "<frozen importlib._bootstrap>", line 219, in _call_with_frames_removed
  File "/opt/airflow/dags/flight_etl_dag.py", line 8, in <module>
    from extract import extract
  File "/opt/airflow/extract.py", line 21, in <module>
    extract()
  File "/opt/airflow/extract.py", line 7, in extract
    data=response.json()
  File "/home/airflow/.local/lib/python3.8/site-packages/requests/models.py", line 975, in json
    raise RequestsJSONDecodeError(e.msg, e.doc, e.pos)
requests.exceptions.JSONDecodeError: Expecting value: line 1 column 1 (char 0)
[2025-07-10T02:06:39.505+0000] {processor.py:842} WARNING - No viable dags retrieved from /opt/airflow/dags/flight_etl_dag.py
[2025-07-10T02:06:39.534+0000] {processor.py:183} INFO - Processing /opt/airflow/dags/flight_etl_dag.py took 0.884 seconds
[2025-07-10T02:07:09.709+0000] {processor.py:161} INFO - Started process (PID=487) to work on /opt/airflow/dags/flight_etl_dag.py
[2025-07-10T02:07:09.711+0000] {processor.py:830} INFO - Processing file /opt/airflow/dags/flight_etl_dag.py for tasks to queue
[2025-07-10T02:07:09.714+0000] {logging_mixin.py:188} INFO - [2025-07-10T02:07:09.714+0000] {dagbag.py:538} INFO - Filling up the DagBag from /opt/airflow/dags/flight_etl_dag.py
[2025-07-10T02:07:10.316+0000] {logging_mixin.py:188} INFO - [2025-07-10T02:07:10.302+0000] {dagbag.py:348} ERROR - Failed to import: /opt/airflow/dags/flight_etl_dag.py
Traceback (most recent call last):
  File "/home/airflow/.local/lib/python3.8/site-packages/requests/models.py", line 971, in json
    return complexjson.loads(self.text, **kwargs)
  File "/usr/local/lib/python3.8/json/__init__.py", line 357, in loads
    return _default_decoder.decode(s)
  File "/usr/local/lib/python3.8/json/decoder.py", line 337, in decode
    obj, end = self.raw_decode(s, idx=_w(s, 0).end())
  File "/usr/local/lib/python3.8/json/decoder.py", line 355, in raw_decode
    raise JSONDecodeError("Expecting value", s, err.value) from None
json.decoder.JSONDecodeError: Expecting value: line 1 column 1 (char 0)

During handling of the above exception, another exception occurred:

Traceback (most recent call last):
  File "/home/airflow/.local/lib/python3.8/site-packages/airflow/models/dagbag.py", line 344, in parse
    loader.exec_module(new_module)
  File "<frozen importlib._bootstrap_external>", line 843, in exec_module
  File "<frozen importlib._bootstrap>", line 219, in _call_with_frames_removed
  File "/opt/airflow/dags/flight_etl_dag.py", line 8, in <module>
    from extract import extract
  File "/opt/airflow/extract.py", line 21, in <module>
    extract()
  File "/opt/airflow/extract.py", line 7, in extract
    data=response.json()
  File "/home/airflow/.local/lib/python3.8/site-packages/requests/models.py", line 975, in json
    raise RequestsJSONDecodeError(e.msg, e.doc, e.pos)
requests.exceptions.JSONDecodeError: Expecting value: line 1 column 1 (char 0)
[2025-07-10T02:07:10.319+0000] {processor.py:842} WARNING - No viable dags retrieved from /opt/airflow/dags/flight_etl_dag.py
[2025-07-10T02:07:10.347+0000] {processor.py:183} INFO - Processing /opt/airflow/dags/flight_etl_dag.py took 0.642 seconds
[2025-07-10T02:07:40.811+0000] {processor.py:161} INFO - Started process (PID=543) to work on /opt/airflow/dags/flight_etl_dag.py
[2025-07-10T02:07:40.813+0000] {processor.py:830} INFO - Processing file /opt/airflow/dags/flight_etl_dag.py for tasks to queue
[2025-07-10T02:07:40.816+0000] {logging_mixin.py:188} INFO - [2025-07-10T02:07:40.816+0000] {dagbag.py:538} INFO - Filling up the DagBag from /opt/airflow/dags/flight_etl_dag.py
[2025-07-10T02:07:41.471+0000] {logging_mixin.py:188} INFO - [2025-07-10T02:07:41.458+0000] {dagbag.py:348} ERROR - Failed to import: /opt/airflow/dags/flight_etl_dag.py
Traceback (most recent call last):
  File "/home/airflow/.local/lib/python3.8/site-packages/requests/models.py", line 971, in json
    return complexjson.loads(self.text, **kwargs)
  File "/usr/local/lib/python3.8/json/__init__.py", line 357, in loads
    return _default_decoder.decode(s)
  File "/usr/local/lib/python3.8/json/decoder.py", line 337, in decode
    obj, end = self.raw_decode(s, idx=_w(s, 0).end())
  File "/usr/local/lib/python3.8/json/decoder.py", line 355, in raw_decode
    raise JSONDecodeError("Expecting value", s, err.value) from None
json.decoder.JSONDecodeError: Expecting value: line 1 column 1 (char 0)

During handling of the above exception, another exception occurred:

Traceback (most recent call last):
  File "/home/airflow/.local/lib/python3.8/site-packages/airflow/models/dagbag.py", line 344, in parse
    loader.exec_module(new_module)
  File "<frozen importlib._bootstrap_external>", line 843, in exec_module
  File "<frozen importlib._bootstrap>", line 219, in _call_with_frames_removed
  File "/opt/airflow/dags/flight_etl_dag.py", line 8, in <module>
    from extract import extract
  File "/opt/airflow/extract.py", line 21, in <module>
    extract()
  File "/opt/airflow/extract.py", line 7, in extract
    data=response.json()
  File "/home/airflow/.local/lib/python3.8/site-packages/requests/models.py", line 975, in json
    raise RequestsJSONDecodeError(e.msg, e.doc, e.pos)
requests.exceptions.JSONDecodeError: Expecting value: line 1 column 1 (char 0)
[2025-07-10T02:07:41.474+0000] {processor.py:842} WARNING - No viable dags retrieved from /opt/airflow/dags/flight_etl_dag.py
[2025-07-10T02:07:41.494+0000] {processor.py:183} INFO - Processing /opt/airflow/dags/flight_etl_dag.py took 0.689 seconds
[2025-07-10T02:08:11.690+0000] {processor.py:161} INFO - Started process (PID=604) to work on /opt/airflow/dags/flight_etl_dag.py
[2025-07-10T02:08:11.693+0000] {processor.py:830} INFO - Processing file /opt/airflow/dags/flight_etl_dag.py for tasks to queue
[2025-07-10T02:08:11.699+0000] {logging_mixin.py:188} INFO - [2025-07-10T02:08:11.698+0000] {dagbag.py:538} INFO - Filling up the DagBag from /opt/airflow/dags/flight_etl_dag.py
[2025-07-10T02:08:12.716+0000] {logging_mixin.py:188} INFO - [2025-07-10T02:08:12.694+0000] {dagbag.py:348} ERROR - Failed to import: /opt/airflow/dags/flight_etl_dag.py
Traceback (most recent call last):
  File "/home/airflow/.local/lib/python3.8/site-packages/requests/models.py", line 971, in json
    return complexjson.loads(self.text, **kwargs)
  File "/usr/local/lib/python3.8/json/__init__.py", line 357, in loads
    return _default_decoder.decode(s)
  File "/usr/local/lib/python3.8/json/decoder.py", line 337, in decode
    obj, end = self.raw_decode(s, idx=_w(s, 0).end())
  File "/usr/local/lib/python3.8/json/decoder.py", line 355, in raw_decode
    raise JSONDecodeError("Expecting value", s, err.value) from None
json.decoder.JSONDecodeError: Expecting value: line 1 column 1 (char 0)

During handling of the above exception, another exception occurred:

Traceback (most recent call last):
  File "/home/airflow/.local/lib/python3.8/site-packages/airflow/models/dagbag.py", line 344, in parse
    loader.exec_module(new_module)
  File "<frozen importlib._bootstrap_external>", line 843, in exec_module
  File "<frozen importlib._bootstrap>", line 219, in _call_with_frames_removed
  File "/opt/airflow/dags/flight_etl_dag.py", line 8, in <module>
    from extract import extract
  File "/opt/airflow/extract.py", line 21, in <module>
    extract()
  File "/opt/airflow/extract.py", line 7, in extract
    data=response.json()
  File "/home/airflow/.local/lib/python3.8/site-packages/requests/models.py", line 975, in json
    raise RequestsJSONDecodeError(e.msg, e.doc, e.pos)
requests.exceptions.JSONDecodeError: Expecting value: line 1 column 1 (char 0)
[2025-07-10T02:08:12.719+0000] {processor.py:842} WARNING - No viable dags retrieved from /opt/airflow/dags/flight_etl_dag.py
[2025-07-10T02:08:12.741+0000] {processor.py:183} INFO - Processing /opt/airflow/dags/flight_etl_dag.py took 1.059 seconds
[2025-07-10T02:08:43.360+0000] {processor.py:161} INFO - Started process (PID=660) to work on /opt/airflow/dags/flight_etl_dag.py
[2025-07-10T02:08:43.362+0000] {processor.py:830} INFO - Processing file /opt/airflow/dags/flight_etl_dag.py for tasks to queue
[2025-07-10T02:08:43.365+0000] {logging_mixin.py:188} INFO - [2025-07-10T02:08:43.365+0000] {dagbag.py:538} INFO - Filling up the DagBag from /opt/airflow/dags/flight_etl_dag.py
[2025-07-10T02:08:44.026+0000] {logging_mixin.py:188} INFO - [2025-07-10T02:08:44.010+0000] {dagbag.py:348} ERROR - Failed to import: /opt/airflow/dags/flight_etl_dag.py
Traceback (most recent call last):
  File "/home/airflow/.local/lib/python3.8/site-packages/requests/models.py", line 971, in json
    return complexjson.loads(self.text, **kwargs)
  File "/usr/local/lib/python3.8/json/__init__.py", line 357, in loads
    return _default_decoder.decode(s)
  File "/usr/local/lib/python3.8/json/decoder.py", line 337, in decode
    obj, end = self.raw_decode(s, idx=_w(s, 0).end())
  File "/usr/local/lib/python3.8/json/decoder.py", line 355, in raw_decode
    raise JSONDecodeError("Expecting value", s, err.value) from None
json.decoder.JSONDecodeError: Expecting value: line 1 column 1 (char 0)

During handling of the above exception, another exception occurred:

Traceback (most recent call last):
  File "/home/airflow/.local/lib/python3.8/site-packages/airflow/models/dagbag.py", line 344, in parse
    loader.exec_module(new_module)
  File "<frozen importlib._bootstrap_external>", line 843, in exec_module
  File "<frozen importlib._bootstrap>", line 219, in _call_with_frames_removed
  File "/opt/airflow/dags/flight_etl_dag.py", line 8, in <module>
    from extract import extract
  File "/opt/airflow/extract.py", line 21, in <module>
    extract()
  File "/opt/airflow/extract.py", line 7, in extract
    data=response.json()
  File "/home/airflow/.local/lib/python3.8/site-packages/requests/models.py", line 975, in json
    raise RequestsJSONDecodeError(e.msg, e.doc, e.pos)
requests.exceptions.JSONDecodeError: Expecting value: line 1 column 1 (char 0)
[2025-07-10T02:08:44.030+0000] {processor.py:842} WARNING - No viable dags retrieved from /opt/airflow/dags/flight_etl_dag.py
[2025-07-10T02:08:44.053+0000] {processor.py:183} INFO - Processing /opt/airflow/dags/flight_etl_dag.py took 0.696 seconds
[2025-07-10T02:09:45.110+0000] {processor.py:161} INFO - Started process (PID=55) to work on /opt/airflow/dags/flight_etl_dag.py
[2025-07-10T02:09:45.112+0000] {processor.py:830} INFO - Processing file /opt/airflow/dags/flight_etl_dag.py for tasks to queue
[2025-07-10T02:09:45.115+0000] {logging_mixin.py:188} INFO - [2025-07-10T02:09:45.114+0000] {dagbag.py:538} INFO - Filling up the DagBag from /opt/airflow/dags/flight_etl_dag.py
[2025-07-10T02:09:45.793+0000] {logging_mixin.py:188} INFO - [2025-07-10T02:09:45.779+0000] {dagbag.py:348} ERROR - Failed to import: /opt/airflow/dags/flight_etl_dag.py
Traceback (most recent call last):
  File "/home/airflow/.local/lib/python3.8/site-packages/requests/models.py", line 971, in json
    return complexjson.loads(self.text, **kwargs)
  File "/usr/local/lib/python3.8/json/__init__.py", line 357, in loads
    return _default_decoder.decode(s)
  File "/usr/local/lib/python3.8/json/decoder.py", line 337, in decode
    obj, end = self.raw_decode(s, idx=_w(s, 0).end())
  File "/usr/local/lib/python3.8/json/decoder.py", line 355, in raw_decode
    raise JSONDecodeError("Expecting value", s, err.value) from None
json.decoder.JSONDecodeError: Expecting value: line 1 column 1 (char 0)

During handling of the above exception, another exception occurred:

Traceback (most recent call last):
  File "/home/airflow/.local/lib/python3.8/site-packages/airflow/models/dagbag.py", line 344, in parse
    loader.exec_module(new_module)
  File "<frozen importlib._bootstrap_external>", line 843, in exec_module
  File "<frozen importlib._bootstrap>", line 219, in _call_with_frames_removed
  File "/opt/airflow/dags/flight_etl_dag.py", line 8, in <module>
    from extract import extract
  File "/opt/airflow/extract.py", line 21, in <module>
    extract()
  File "/opt/airflow/extract.py", line 7, in extract
    data=response.json()
  File "/home/airflow/.local/lib/python3.8/site-packages/requests/models.py", line 975, in json
    raise RequestsJSONDecodeError(e.msg, e.doc, e.pos)
requests.exceptions.JSONDecodeError: Expecting value: line 1 column 1 (char 0)
[2025-07-10T02:09:45.796+0000] {processor.py:842} WARNING - No viable dags retrieved from /opt/airflow/dags/flight_etl_dag.py
[2025-07-10T02:09:45.820+0000] {processor.py:183} INFO - Processing /opt/airflow/dags/flight_etl_dag.py took 0.714 seconds
[2025-07-10T02:10:15.944+0000] {processor.py:161} INFO - Started process (PID=115) to work on /opt/airflow/dags/flight_etl_dag.py
[2025-07-10T02:10:15.945+0000] {processor.py:830} INFO - Processing file /opt/airflow/dags/flight_etl_dag.py for tasks to queue
[2025-07-10T02:10:15.947+0000] {logging_mixin.py:188} INFO - [2025-07-10T02:10:15.947+0000] {dagbag.py:538} INFO - Filling up the DagBag from /opt/airflow/dags/flight_etl_dag.py
[2025-07-10T02:10:16.717+0000] {logging_mixin.py:188} INFO - [2025-07-10T02:10:16.699+0000] {dagbag.py:348} ERROR - Failed to import: /opt/airflow/dags/flight_etl_dag.py
Traceback (most recent call last):
  File "/home/airflow/.local/lib/python3.8/site-packages/requests/models.py", line 971, in json
    return complexjson.loads(self.text, **kwargs)
  File "/usr/local/lib/python3.8/json/__init__.py", line 357, in loads
    return _default_decoder.decode(s)
  File "/usr/local/lib/python3.8/json/decoder.py", line 337, in decode
    obj, end = self.raw_decode(s, idx=_w(s, 0).end())
  File "/usr/local/lib/python3.8/json/decoder.py", line 355, in raw_decode
    raise JSONDecodeError("Expecting value", s, err.value) from None
json.decoder.JSONDecodeError: Expecting value: line 1 column 1 (char 0)

During handling of the above exception, another exception occurred:

Traceback (most recent call last):
  File "/home/airflow/.local/lib/python3.8/site-packages/airflow/models/dagbag.py", line 344, in parse
    loader.exec_module(new_module)
  File "<frozen importlib._bootstrap_external>", line 843, in exec_module
  File "<frozen importlib._bootstrap>", line 219, in _call_with_frames_removed
  File "/opt/airflow/dags/flight_etl_dag.py", line 8, in <module>
    from extract import extract
  File "/opt/airflow/extract.py", line 21, in <module>
    extract()
  File "/opt/airflow/extract.py", line 7, in extract
    data=response.json()
  File "/home/airflow/.local/lib/python3.8/site-packages/requests/models.py", line 975, in json
    raise RequestsJSONDecodeError(e.msg, e.doc, e.pos)
requests.exceptions.JSONDecodeError: Expecting value: line 1 column 1 (char 0)
[2025-07-10T02:10:16.720+0000] {processor.py:842} WARNING - No viable dags retrieved from /opt/airflow/dags/flight_etl_dag.py
[2025-07-10T02:10:16.743+0000] {processor.py:183} INFO - Processing /opt/airflow/dags/flight_etl_dag.py took 0.802 seconds
[2025-07-10T02:10:47.707+0000] {processor.py:161} INFO - Started process (PID=180) to work on /opt/airflow/dags/flight_etl_dag.py
[2025-07-10T02:10:47.710+0000] {processor.py:830} INFO - Processing file /opt/airflow/dags/flight_etl_dag.py for tasks to queue
[2025-07-10T02:10:47.714+0000] {logging_mixin.py:188} INFO - [2025-07-10T02:10:47.714+0000] {dagbag.py:538} INFO - Filling up the DagBag from /opt/airflow/dags/flight_etl_dag.py
[2025-07-10T02:10:48.512+0000] {logging_mixin.py:188} INFO - [2025-07-10T02:10:48.486+0000] {dagbag.py:348} ERROR - Failed to import: /opt/airflow/dags/flight_etl_dag.py
Traceback (most recent call last):
  File "/home/airflow/.local/lib/python3.8/site-packages/requests/models.py", line 971, in json
    return complexjson.loads(self.text, **kwargs)
  File "/usr/local/lib/python3.8/json/__init__.py", line 357, in loads
    return _default_decoder.decode(s)
  File "/usr/local/lib/python3.8/json/decoder.py", line 337, in decode
    obj, end = self.raw_decode(s, idx=_w(s, 0).end())
  File "/usr/local/lib/python3.8/json/decoder.py", line 355, in raw_decode
    raise JSONDecodeError("Expecting value", s, err.value) from None
json.decoder.JSONDecodeError: Expecting value: line 1 column 1 (char 0)

During handling of the above exception, another exception occurred:

Traceback (most recent call last):
  File "/home/airflow/.local/lib/python3.8/site-packages/airflow/models/dagbag.py", line 344, in parse
    loader.exec_module(new_module)
  File "<frozen importlib._bootstrap_external>", line 843, in exec_module
  File "<frozen importlib._bootstrap>", line 219, in _call_with_frames_removed
  File "/opt/airflow/dags/flight_etl_dag.py", line 8, in <module>
    from extract import extract
  File "/opt/airflow/extract.py", line 21, in <module>
    extract()
  File "/opt/airflow/extract.py", line 7, in extract
    data=response.json()
  File "/home/airflow/.local/lib/python3.8/site-packages/requests/models.py", line 975, in json
    raise RequestsJSONDecodeError(e.msg, e.doc, e.pos)
requests.exceptions.JSONDecodeError: Expecting value: line 1 column 1 (char 0)
[2025-07-10T02:10:48.519+0000] {processor.py:842} WARNING - No viable dags retrieved from /opt/airflow/dags/flight_etl_dag.py
[2025-07-10T02:10:48.565+0000] {processor.py:183} INFO - Processing /opt/airflow/dags/flight_etl_dag.py took 0.863 seconds
[2025-07-10T02:11:18.690+0000] {processor.py:161} INFO - Started process (PID=239) to work on /opt/airflow/dags/flight_etl_dag.py
[2025-07-10T02:11:18.693+0000] {processor.py:830} INFO - Processing file /opt/airflow/dags/flight_etl_dag.py for tasks to queue
[2025-07-10T02:11:18.698+0000] {logging_mixin.py:188} INFO - [2025-07-10T02:11:18.697+0000] {dagbag.py:538} INFO - Filling up the DagBag from /opt/airflow/dags/flight_etl_dag.py
[2025-07-10T02:11:19.469+0000] {logging_mixin.py:188} INFO - [2025-07-10T02:11:19.445+0000] {dagbag.py:348} ERROR - Failed to import: /opt/airflow/dags/flight_etl_dag.py
Traceback (most recent call last):
  File "/home/airflow/.local/lib/python3.8/site-packages/requests/models.py", line 971, in json
    return complexjson.loads(self.text, **kwargs)
  File "/usr/local/lib/python3.8/json/__init__.py", line 357, in loads
    return _default_decoder.decode(s)
  File "/usr/local/lib/python3.8/json/decoder.py", line 337, in decode
    obj, end = self.raw_decode(s, idx=_w(s, 0).end())
  File "/usr/local/lib/python3.8/json/decoder.py", line 355, in raw_decode
    raise JSONDecodeError("Expecting value", s, err.value) from None
json.decoder.JSONDecodeError: Expecting value: line 1 column 1 (char 0)

During handling of the above exception, another exception occurred:

Traceback (most recent call last):
  File "/home/airflow/.local/lib/python3.8/site-packages/airflow/models/dagbag.py", line 344, in parse
    loader.exec_module(new_module)
  File "<frozen importlib._bootstrap_external>", line 843, in exec_module
  File "<frozen importlib._bootstrap>", line 219, in _call_with_frames_removed
  File "/opt/airflow/dags/flight_etl_dag.py", line 8, in <module>
    from extract import extract
  File "/opt/airflow/extract.py", line 21, in <module>
    extract()
  File "/opt/airflow/extract.py", line 7, in extract
    data=response.json()
  File "/home/airflow/.local/lib/python3.8/site-packages/requests/models.py", line 975, in json
    raise RequestsJSONDecodeError(e.msg, e.doc, e.pos)
requests.exceptions.JSONDecodeError: Expecting value: line 1 column 1 (char 0)
[2025-07-10T02:11:19.475+0000] {processor.py:842} WARNING - No viable dags retrieved from /opt/airflow/dags/flight_etl_dag.py
[2025-07-10T02:11:19.502+0000] {processor.py:183} INFO - Processing /opt/airflow/dags/flight_etl_dag.py took 0.819 seconds
[2025-07-10T02:11:50.013+0000] {processor.py:161} INFO - Started process (PID=295) to work on /opt/airflow/dags/flight_etl_dag.py
[2025-07-10T02:11:50.016+0000] {processor.py:830} INFO - Processing file /opt/airflow/dags/flight_etl_dag.py for tasks to queue
[2025-07-10T02:11:50.021+0000] {logging_mixin.py:188} INFO - [2025-07-10T02:11:50.020+0000] {dagbag.py:538} INFO - Filling up the DagBag from /opt/airflow/dags/flight_etl_dag.py
[2025-07-10T02:11:50.722+0000] {logging_mixin.py:188} INFO - [2025-07-10T02:11:50.708+0000] {dagbag.py:348} ERROR - Failed to import: /opt/airflow/dags/flight_etl_dag.py
Traceback (most recent call last):
  File "/home/airflow/.local/lib/python3.8/site-packages/requests/models.py", line 971, in json
    return complexjson.loads(self.text, **kwargs)
  File "/usr/local/lib/python3.8/json/__init__.py", line 357, in loads
    return _default_decoder.decode(s)
  File "/usr/local/lib/python3.8/json/decoder.py", line 337, in decode
    obj, end = self.raw_decode(s, idx=_w(s, 0).end())
  File "/usr/local/lib/python3.8/json/decoder.py", line 355, in raw_decode
    raise JSONDecodeError("Expecting value", s, err.value) from None
json.decoder.JSONDecodeError: Expecting value: line 1 column 1 (char 0)

During handling of the above exception, another exception occurred:

Traceback (most recent call last):
  File "/home/airflow/.local/lib/python3.8/site-packages/airflow/models/dagbag.py", line 344, in parse
    loader.exec_module(new_module)
  File "<frozen importlib._bootstrap_external>", line 843, in exec_module
  File "<frozen importlib._bootstrap>", line 219, in _call_with_frames_removed
  File "/opt/airflow/dags/flight_etl_dag.py", line 8, in <module>
    from extract import extract
  File "/opt/airflow/extract.py", line 21, in <module>
    extract()
  File "/opt/airflow/extract.py", line 7, in extract
    data=response.json()
  File "/home/airflow/.local/lib/python3.8/site-packages/requests/models.py", line 975, in json
    raise RequestsJSONDecodeError(e.msg, e.doc, e.pos)
requests.exceptions.JSONDecodeError: Expecting value: line 1 column 1 (char 0)
[2025-07-10T02:11:50.725+0000] {processor.py:842} WARNING - No viable dags retrieved from /opt/airflow/dags/flight_etl_dag.py
[2025-07-10T02:11:50.748+0000] {processor.py:183} INFO - Processing /opt/airflow/dags/flight_etl_dag.py took 0.744 seconds
[2025-07-10T02:14:02.052+0000] {processor.py:161} INFO - Started process (PID=60) to work on /opt/airflow/dags/flight_etl_dag.py
[2025-07-10T02:14:02.054+0000] {processor.py:830} INFO - Processing file /opt/airflow/dags/flight_etl_dag.py for tasks to queue
[2025-07-10T02:14:02.057+0000] {logging_mixin.py:188} INFO - [2025-07-10T02:14:02.056+0000] {dagbag.py:538} INFO - Filling up the DagBag from /opt/airflow/dags/flight_etl_dag.py
[2025-07-10T02:14:02.929+0000] {logging_mixin.py:188} INFO - [2025-07-10T02:14:02.907+0000] {dagbag.py:348} ERROR - Failed to import: /opt/airflow/dags/flight_etl_dag.py
Traceback (most recent call last):
  File "/home/airflow/.local/lib/python3.8/site-packages/requests/models.py", line 971, in json
    return complexjson.loads(self.text, **kwargs)
  File "/usr/local/lib/python3.8/json/__init__.py", line 357, in loads
    return _default_decoder.decode(s)
  File "/usr/local/lib/python3.8/json/decoder.py", line 337, in decode
    obj, end = self.raw_decode(s, idx=_w(s, 0).end())
  File "/usr/local/lib/python3.8/json/decoder.py", line 355, in raw_decode
    raise JSONDecodeError("Expecting value", s, err.value) from None
json.decoder.JSONDecodeError: Expecting value: line 1 column 1 (char 0)

During handling of the above exception, another exception occurred:

Traceback (most recent call last):
  File "/home/airflow/.local/lib/python3.8/site-packages/airflow/models/dagbag.py", line 344, in parse
    loader.exec_module(new_module)
  File "<frozen importlib._bootstrap_external>", line 843, in exec_module
  File "<frozen importlib._bootstrap>", line 219, in _call_with_frames_removed
  File "/opt/airflow/dags/flight_etl_dag.py", line 8, in <module>
    from extract import extract
  File "/opt/airflow/extract.py", line 21, in <module>
    extract()
  File "/opt/airflow/extract.py", line 7, in extract
    data=response.json()
  File "/home/airflow/.local/lib/python3.8/site-packages/requests/models.py", line 975, in json
    raise RequestsJSONDecodeError(e.msg, e.doc, e.pos)
requests.exceptions.JSONDecodeError: Expecting value: line 1 column 1 (char 0)
[2025-07-10T02:14:02.935+0000] {processor.py:842} WARNING - No viable dags retrieved from /opt/airflow/dags/flight_etl_dag.py
[2025-07-10T02:14:02.976+0000] {processor.py:183} INFO - Processing /opt/airflow/dags/flight_etl_dag.py took 0.927 seconds
[2025-07-10T02:14:33.298+0000] {processor.py:161} INFO - Started process (PID=122) to work on /opt/airflow/dags/flight_etl_dag.py
[2025-07-10T02:14:33.300+0000] {processor.py:830} INFO - Processing file /opt/airflow/dags/flight_etl_dag.py for tasks to queue
[2025-07-10T02:14:33.303+0000] {logging_mixin.py:188} INFO - [2025-07-10T02:14:33.302+0000] {dagbag.py:538} INFO - Filling up the DagBag from /opt/airflow/dags/flight_etl_dag.py
[2025-07-10T02:14:34.476+0000] {logging_mixin.py:188} INFO - [2025-07-10T02:14:34.449+0000] {dagbag.py:348} ERROR - Failed to import: /opt/airflow/dags/flight_etl_dag.py
Traceback (most recent call last):
  File "/home/airflow/.local/lib/python3.8/site-packages/requests/models.py", line 971, in json
    return complexjson.loads(self.text, **kwargs)
  File "/usr/local/lib/python3.8/json/__init__.py", line 357, in loads
    return _default_decoder.decode(s)
  File "/usr/local/lib/python3.8/json/decoder.py", line 337, in decode
    obj, end = self.raw_decode(s, idx=_w(s, 0).end())
  File "/usr/local/lib/python3.8/json/decoder.py", line 355, in raw_decode
    raise JSONDecodeError("Expecting value", s, err.value) from None
json.decoder.JSONDecodeError: Expecting value: line 1 column 1 (char 0)

During handling of the above exception, another exception occurred:

Traceback (most recent call last):
  File "/home/airflow/.local/lib/python3.8/site-packages/airflow/models/dagbag.py", line 344, in parse
    loader.exec_module(new_module)
  File "<frozen importlib._bootstrap_external>", line 843, in exec_module
  File "<frozen importlib._bootstrap>", line 219, in _call_with_frames_removed
  File "/opt/airflow/dags/flight_etl_dag.py", line 8, in <module>
    from extract import extract
  File "/opt/airflow/extract.py", line 21, in <module>
    extract()
  File "/opt/airflow/extract.py", line 7, in extract
    data=response.json()
  File "/home/airflow/.local/lib/python3.8/site-packages/requests/models.py", line 975, in json
    raise RequestsJSONDecodeError(e.msg, e.doc, e.pos)
requests.exceptions.JSONDecodeError: Expecting value: line 1 column 1 (char 0)
[2025-07-10T02:14:34.480+0000] {processor.py:842} WARNING - No viable dags retrieved from /opt/airflow/dags/flight_etl_dag.py
[2025-07-10T02:14:34.518+0000] {processor.py:183} INFO - Processing /opt/airflow/dags/flight_etl_dag.py took 1.224 seconds
[2025-07-10T02:15:04.635+0000] {processor.py:161} INFO - Started process (PID=185) to work on /opt/airflow/dags/flight_etl_dag.py
[2025-07-10T02:15:04.636+0000] {processor.py:830} INFO - Processing file /opt/airflow/dags/flight_etl_dag.py for tasks to queue
[2025-07-10T02:15:04.639+0000] {logging_mixin.py:188} INFO - [2025-07-10T02:15:04.638+0000] {dagbag.py:538} INFO - Filling up the DagBag from /opt/airflow/dags/flight_etl_dag.py
[2025-07-10T02:15:05.275+0000] {logging_mixin.py:188} INFO - [2025-07-10T02:15:05.254+0000] {dagbag.py:348} ERROR - Failed to import: /opt/airflow/dags/flight_etl_dag.py
Traceback (most recent call last):
  File "/home/airflow/.local/lib/python3.8/site-packages/requests/models.py", line 971, in json
    return complexjson.loads(self.text, **kwargs)
  File "/usr/local/lib/python3.8/json/__init__.py", line 357, in loads
    return _default_decoder.decode(s)
  File "/usr/local/lib/python3.8/json/decoder.py", line 337, in decode
    obj, end = self.raw_decode(s, idx=_w(s, 0).end())
  File "/usr/local/lib/python3.8/json/decoder.py", line 355, in raw_decode
    raise JSONDecodeError("Expecting value", s, err.value) from None
json.decoder.JSONDecodeError: Expecting value: line 1 column 1 (char 0)

During handling of the above exception, another exception occurred:

Traceback (most recent call last):
  File "/home/airflow/.local/lib/python3.8/site-packages/airflow/models/dagbag.py", line 344, in parse
    loader.exec_module(new_module)
  File "<frozen importlib._bootstrap_external>", line 843, in exec_module
  File "<frozen importlib._bootstrap>", line 219, in _call_with_frames_removed
  File "/opt/airflow/dags/flight_etl_dag.py", line 8, in <module>
    from extract import extract
  File "/opt/airflow/extract.py", line 21, in <module>
    extract()
  File "/opt/airflow/extract.py", line 7, in extract
    data=response.json()
  File "/home/airflow/.local/lib/python3.8/site-packages/requests/models.py", line 975, in json
    raise RequestsJSONDecodeError(e.msg, e.doc, e.pos)
requests.exceptions.JSONDecodeError: Expecting value: line 1 column 1 (char 0)
[2025-07-10T02:15:05.278+0000] {processor.py:842} WARNING - No viable dags retrieved from /opt/airflow/dags/flight_etl_dag.py
[2025-07-10T02:15:05.306+0000] {processor.py:183} INFO - Processing /opt/airflow/dags/flight_etl_dag.py took 0.675 seconds
[2025-07-10T02:15:35.447+0000] {processor.py:161} INFO - Started process (PID=241) to work on /opt/airflow/dags/flight_etl_dag.py
[2025-07-10T02:15:35.448+0000] {processor.py:830} INFO - Processing file /opt/airflow/dags/flight_etl_dag.py for tasks to queue
[2025-07-10T02:15:35.451+0000] {logging_mixin.py:188} INFO - [2025-07-10T02:15:35.451+0000] {dagbag.py:538} INFO - Filling up the DagBag from /opt/airflow/dags/flight_etl_dag.py
[2025-07-10T02:15:35.986+0000] {logging_mixin.py:188} INFO - [2025-07-10T02:15:35.969+0000] {dagbag.py:348} ERROR - Failed to import: /opt/airflow/dags/flight_etl_dag.py
Traceback (most recent call last):
  File "/home/airflow/.local/lib/python3.8/site-packages/requests/models.py", line 971, in json
    return complexjson.loads(self.text, **kwargs)
  File "/usr/local/lib/python3.8/json/__init__.py", line 357, in loads
    return _default_decoder.decode(s)
  File "/usr/local/lib/python3.8/json/decoder.py", line 337, in decode
    obj, end = self.raw_decode(s, idx=_w(s, 0).end())
  File "/usr/local/lib/python3.8/json/decoder.py", line 355, in raw_decode
    raise JSONDecodeError("Expecting value", s, err.value) from None
json.decoder.JSONDecodeError: Expecting value: line 1 column 1 (char 0)

During handling of the above exception, another exception occurred:

Traceback (most recent call last):
  File "/home/airflow/.local/lib/python3.8/site-packages/airflow/models/dagbag.py", line 344, in parse
    loader.exec_module(new_module)
  File "<frozen importlib._bootstrap_external>", line 843, in exec_module
  File "<frozen importlib._bootstrap>", line 219, in _call_with_frames_removed
  File "/opt/airflow/dags/flight_etl_dag.py", line 8, in <module>
    from extract import extract
  File "/opt/airflow/extract.py", line 21, in <module>
    extract()
  File "/opt/airflow/extract.py", line 7, in extract
    data=response.json()
  File "/home/airflow/.local/lib/python3.8/site-packages/requests/models.py", line 975, in json
    raise RequestsJSONDecodeError(e.msg, e.doc, e.pos)
requests.exceptions.JSONDecodeError: Expecting value: line 1 column 1 (char 0)
[2025-07-10T02:15:35.993+0000] {processor.py:842} WARNING - No viable dags retrieved from /opt/airflow/dags/flight_etl_dag.py
[2025-07-10T02:15:36.024+0000] {processor.py:183} INFO - Processing /opt/airflow/dags/flight_etl_dag.py took 0.582 seconds
[2025-07-10T02:16:36.702+0000] {processor.py:161} INFO - Started process (PID=60) to work on /opt/airflow/dags/flight_etl_dag.py
[2025-07-10T02:16:36.706+0000] {processor.py:830} INFO - Processing file /opt/airflow/dags/flight_etl_dag.py for tasks to queue
[2025-07-10T02:16:36.712+0000] {logging_mixin.py:188} INFO - [2025-07-10T02:16:36.711+0000] {dagbag.py:538} INFO - Filling up the DagBag from /opt/airflow/dags/flight_etl_dag.py
[2025-07-10T02:16:37.345+0000] {logging_mixin.py:188} INFO - [2025-07-10T02:16:37.314+0000] {dagbag.py:348} ERROR - Failed to import: /opt/airflow/dags/flight_etl_dag.py
Traceback (most recent call last):
  File "/home/airflow/.local/lib/python3.8/site-packages/requests/models.py", line 971, in json
    return complexjson.loads(self.text, **kwargs)
  File "/usr/local/lib/python3.8/json/__init__.py", line 357, in loads
    return _default_decoder.decode(s)
  File "/usr/local/lib/python3.8/json/decoder.py", line 337, in decode
    obj, end = self.raw_decode(s, idx=_w(s, 0).end())
  File "/usr/local/lib/python3.8/json/decoder.py", line 355, in raw_decode
    raise JSONDecodeError("Expecting value", s, err.value) from None
json.decoder.JSONDecodeError: Expecting value: line 1 column 1 (char 0)

During handling of the above exception, another exception occurred:

Traceback (most recent call last):
  File "/home/airflow/.local/lib/python3.8/site-packages/airflow/models/dagbag.py", line 344, in parse
    loader.exec_module(new_module)
  File "<frozen importlib._bootstrap_external>", line 843, in exec_module
  File "<frozen importlib._bootstrap>", line 219, in _call_with_frames_removed
  File "/opt/airflow/dags/flight_etl_dag.py", line 8, in <module>
    from extract import extract
  File "/opt/airflow/extract.py", line 21, in <module>
    extract()
  File "/opt/airflow/extract.py", line 7, in extract
    data=response.json()
  File "/home/airflow/.local/lib/python3.8/site-packages/requests/models.py", line 975, in json
    raise RequestsJSONDecodeError(e.msg, e.doc, e.pos)
requests.exceptions.JSONDecodeError: Expecting value: line 1 column 1 (char 0)
[2025-07-10T02:16:37.350+0000] {processor.py:842} WARNING - No viable dags retrieved from /opt/airflow/dags/flight_etl_dag.py
[2025-07-10T02:16:37.398+0000] {processor.py:183} INFO - Processing /opt/airflow/dags/flight_etl_dag.py took 0.703 seconds
[2025-07-10T02:17:07.747+0000] {processor.py:161} INFO - Started process (PID=122) to work on /opt/airflow/dags/flight_etl_dag.py
[2025-07-10T02:17:07.748+0000] {processor.py:830} INFO - Processing file /opt/airflow/dags/flight_etl_dag.py for tasks to queue
[2025-07-10T02:17:07.752+0000] {logging_mixin.py:188} INFO - [2025-07-10T02:17:07.751+0000] {dagbag.py:538} INFO - Filling up the DagBag from /opt/airflow/dags/flight_etl_dag.py
[2025-07-10T02:17:08.476+0000] {logging_mixin.py:188} INFO - [2025-07-10T02:17:08.459+0000] {dagbag.py:348} ERROR - Failed to import: /opt/airflow/dags/flight_etl_dag.py
Traceback (most recent call last):
  File "/home/airflow/.local/lib/python3.8/site-packages/requests/models.py", line 971, in json
    return complexjson.loads(self.text, **kwargs)
  File "/usr/local/lib/python3.8/json/__init__.py", line 357, in loads
    return _default_decoder.decode(s)
  File "/usr/local/lib/python3.8/json/decoder.py", line 337, in decode
    obj, end = self.raw_decode(s, idx=_w(s, 0).end())
  File "/usr/local/lib/python3.8/json/decoder.py", line 355, in raw_decode
    raise JSONDecodeError("Expecting value", s, err.value) from None
json.decoder.JSONDecodeError: Expecting value: line 1 column 1 (char 0)

During handling of the above exception, another exception occurred:

Traceback (most recent call last):
  File "/home/airflow/.local/lib/python3.8/site-packages/airflow/models/dagbag.py", line 344, in parse
    loader.exec_module(new_module)
  File "<frozen importlib._bootstrap_external>", line 843, in exec_module
  File "<frozen importlib._bootstrap>", line 219, in _call_with_frames_removed
  File "/opt/airflow/dags/flight_etl_dag.py", line 8, in <module>
    from extract import extract
  File "/opt/airflow/extract.py", line 21, in <module>
    extract()
  File "/opt/airflow/extract.py", line 7, in extract
    data=response.json()
  File "/home/airflow/.local/lib/python3.8/site-packages/requests/models.py", line 975, in json
    raise RequestsJSONDecodeError(e.msg, e.doc, e.pos)
requests.exceptions.JSONDecodeError: Expecting value: line 1 column 1 (char 0)
[2025-07-10T02:17:08.479+0000] {processor.py:842} WARNING - No viable dags retrieved from /opt/airflow/dags/flight_etl_dag.py
[2025-07-10T02:17:08.511+0000] {processor.py:183} INFO - Processing /opt/airflow/dags/flight_etl_dag.py took 0.769 seconds
