[2025-07-11T15:36:24.292+0000] {taskinstance.py:1956} INFO - Dependencies all met for dep_context=non-requeueable deps ti=<TaskInstance: flight_etl_dag.loading_data manual__2025-07-11T15:36:11.438544+00:00 [queued]>
[2025-07-11T15:36:24.311+0000] {taskinstance.py:1956} INFO - Dependencies all met for dep_context=requeueable deps ti=<TaskInstance: flight_etl_dag.loading_data manual__2025-07-11T15:36:11.438544+00:00 [queued]>
[2025-07-11T15:36:24.312+0000] {taskinstance.py:2170} INFO - Starting attempt 1 of 2
[2025-07-11T15:36:24.343+0000] {taskinstance.py:2191} INFO - Executing <Task(PythonOperator): loading_data> on 2025-07-11 15:36:11.438544+00:00
[2025-07-11T15:36:24.353+0000] {standard_task_runner.py:60} INFO - Started process 101 to run task
[2025-07-11T15:36:24.361+0000] {standard_task_runner.py:87} INFO - Running: ['airflow', 'tasks', 'run', 'flight_etl_dag', 'loading_data', 'manual__2025-07-11T15:36:11.438544+00:00', '--job-id', '42', '--raw', '--subdir', 'DAGS_FOLDER/flight_etl_dag.py', '--cfg-path', '/tmp/tmpknf9qyzf']
[2025-07-11T15:36:24.363+0000] {standard_task_runner.py:88} INFO - Job 42: Subtask loading_data
[2025-07-11T15:36:24.499+0000] {task_command.py:423} INFO - Running <TaskInstance: flight_etl_dag.loading_data manual__2025-07-11T15:36:11.438544+00:00 [running]> on host c93b05155523
[2025-07-11T15:36:24.602+0000] {taskinstance.py:2480} INFO - Exporting env vars: AIRFLOW_CTX_DAG_OWNER='airflow' AIRFLOW_CTX_DAG_ID='flight_etl_dag' AIRFLOW_CTX_TASK_ID='loading_data' AIRFLOW_CTX_EXECUTION_DATE='2025-07-11T15:36:11.438544+00:00' AIRFLOW_CTX_TRY_NUMBER='1' AIRFLOW_CTX_DAG_RUN_ID='manual__2025-07-11T15:36:11.438544+00:00'
[2025-07-11T15:36:24.651+0000] {taskinstance.py:2698} ERROR - Task failed with exception
Traceback (most recent call last):
  File "/home/airflow/.local/lib/python3.8/site-packages/airflow/models/taskinstance.py", line 433, in _execute_task
    result = execute_callable(context=context, **execute_callable_kwargs)
  File "/home/airflow/.local/lib/python3.8/site-packages/airflow/operators/python.py", line 199, in execute
    return_value = self.execute_callable()
  File "/home/airflow/.local/lib/python3.8/site-packages/airflow/operators/python.py", line 216, in execute_callable
    return self.python_callable(*self.op_args, **self.op_kwargs)
  File "/opt/airflow/load.py", line 13, in load_to_db
    create_tables(conn)
TypeError: create_tables() takes 0 positional arguments but 1 was given
[2025-07-11T15:36:24.670+0000] {taskinstance.py:1138} INFO - Marking task as UP_FOR_RETRY. dag_id=flight_etl_dag, task_id=loading_data, execution_date=20250711T153611, start_date=20250711T153624, end_date=20250711T153624
[2025-07-11T15:36:24.693+0000] {standard_task_runner.py:107} ERROR - Failed to execute job 42 for task loading_data (create_tables() takes 0 positional arguments but 1 was given; 101)
[2025-07-11T15:36:24.741+0000] {local_task_job_runner.py:234} INFO - Task exited with return code 1
[2025-07-11T15:36:24.760+0000] {taskinstance.py:3280} INFO - 0 downstream tasks scheduled from follow-on schedule check
