[2025-07-12T01:56:35.449+0000] {taskinstance.py:1956} INFO - Dependencies all met for dep_context=non-requeueable deps ti=<TaskInstance: flight_etl_dag.extracting_data scheduled__2025-07-11T00:00:00+00:00 [queued]>
[2025-07-12T01:56:35.460+0000] {taskinstance.py:1956} INFO - Dependencies all met for dep_context=requeueable deps ti=<TaskInstance: flight_etl_dag.extracting_data scheduled__2025-07-11T00:00:00+00:00 [queued]>
[2025-07-12T01:56:35.461+0000] {taskinstance.py:2170} INFO - Starting attempt 2 of 2
[2025-07-12T01:56:35.485+0000] {taskinstance.py:2191} INFO - Executing <Task(PythonOperator): extracting_data> on 2025-07-11 00:00:00+00:00
[2025-07-12T01:56:35.492+0000] {standard_task_runner.py:60} INFO - Started process 111 to run task
[2025-07-12T01:56:35.499+0000] {standard_task_runner.py:87} INFO - Running: ['airflow', 'tasks', 'run', 'flight_etl_dag', 'extracting_data', 'scheduled__2025-07-11T00:00:00+00:00', '--job-id', '6', '--raw', '--subdir', 'DAGS_FOLDER/flight_etl_dag.py', '--cfg-path', '/tmp/tmp7wn4oeca']
[2025-07-12T01:56:35.501+0000] {standard_task_runner.py:88} INFO - Job 6: Subtask extracting_data
[2025-07-12T01:56:35.594+0000] {task_command.py:423} INFO - Running <TaskInstance: flight_etl_dag.extracting_data scheduled__2025-07-11T00:00:00+00:00 [running]> on host b97efba67dd5
[2025-07-12T01:56:35.710+0000] {taskinstance.py:2480} INFO - Exporting env vars: AIRFLOW_CTX_DAG_OWNER='airflow' AIRFLOW_CTX_DAG_ID='flight_etl_dag' AIRFLOW_CTX_TASK_ID='extracting_data' AIRFLOW_CTX_EXECUTION_DATE='2025-07-11T00:00:00+00:00' AIRFLOW_CTX_TRY_NUMBER='2' AIRFLOW_CTX_DAG_RUN_ID='scheduled__2025-07-11T00:00:00+00:00'
[2025-07-12T01:56:37.497+0000] {taskinstance.py:2698} ERROR - Task failed with exception
Traceback (most recent call last):
  File "/home/airflow/.local/lib/python3.8/site-packages/airflow/models/taskinstance.py", line 433, in _execute_task
    result = execute_callable(context=context, **execute_callable_kwargs)
  File "/home/airflow/.local/lib/python3.8/site-packages/airflow/operators/python.py", line 199, in execute
    return_value = self.execute_callable()
  File "/home/airflow/.local/lib/python3.8/site-packages/airflow/operators/python.py", line 216, in execute_callable
    return self.python_callable(*self.op_args, **self.op_kwargs)
  File "/opt/airflow/extract.py", line 13, in extract
    raise ValueError(f"OpenSky API returned {response.status_code}")
ValueError: OpenSky API returned 429
[2025-07-12T01:56:37.520+0000] {taskinstance.py:1138} INFO - Marking task as FAILED. dag_id=flight_etl_dag, task_id=extracting_data, execution_date=20250711T000000, start_date=20250712T015635, end_date=20250712T015637
[2025-07-12T01:56:37.550+0000] {standard_task_runner.py:107} ERROR - Failed to execute job 6 for task extracting_data (OpenSky API returned 429; 111)
[2025-07-12T01:56:37.568+0000] {local_task_job_runner.py:234} INFO - Task exited with return code 1
[2025-07-12T01:56:37.598+0000] {taskinstance.py:3280} INFO - 0 downstream tasks scheduled from follow-on schedule check
