[2025-07-08T22:44:42.968+0000] {taskinstance.py:1956} INFO - Dependencies all met for dep_context=non-requeueable deps ti=<TaskInstance: flight_etl_dag.transforming_data manual__2025-07-08T22:44:13.757971+00:00 [queued]>
[2025-07-08T22:44:42.982+0000] {taskinstance.py:1956} INFO - Dependencies all met for dep_context=requeueable deps ti=<TaskInstance: flight_etl_dag.transforming_data manual__2025-07-08T22:44:13.757971+00:00 [queued]>
[2025-07-08T22:44:42.983+0000] {taskinstance.py:2170} INFO - Starting attempt 1 of 2
[2025-07-08T22:44:43.003+0000] {taskinstance.py:2191} INFO - Executing <Task(PythonOperator): transforming_data> on 2025-07-08 22:44:13.757971+00:00
[2025-07-08T22:44:43.013+0000] {standard_task_runner.py:60} INFO - Started process 156 to run task
[2025-07-08T22:44:43.018+0000] {standard_task_runner.py:87} INFO - Running: ['***', 'tasks', 'run', 'flight_etl_dag', 'transforming_data', 'manual__2025-07-08T22:44:13.757971+00:00', '--job-id', '28', '--raw', '--subdir', 'DAGS_FOLDER/flight_etl_dag.py', '--cfg-path', '/tmp/tmplkuvy6cl']
[2025-07-08T22:44:43.021+0000] {standard_task_runner.py:88} INFO - Job 28: Subtask transforming_data
[2025-07-08T22:44:43.128+0000] {task_command.py:423} INFO - Running <TaskInstance: flight_etl_dag.transforming_data manual__2025-07-08T22:44:13.757971+00:00 [running]> on host dd092c829c91
[2025-07-08T22:44:43.256+0000] {taskinstance.py:2480} INFO - Exporting env vars: AIRFLOW_CTX_DAG_OWNER='***' AIRFLOW_CTX_DAG_ID='flight_etl_dag' AIRFLOW_CTX_TASK_ID='transforming_data' AIRFLOW_CTX_EXECUTION_DATE='2025-07-08T22:44:13.757971+00:00' AIRFLOW_CTX_TRY_NUMBER='1' AIRFLOW_CTX_DAG_RUN_ID='manual__2025-07-08T22:44:13.757971+00:00'
[2025-07-08T22:44:43.262+0000] {taskinstance.py:2698} ERROR - Task failed with exception
Traceback (most recent call last):
  File "/home/airflow/.local/lib/python3.8/site-packages/airflow/models/taskinstance.py", line 433, in _execute_task
    result = execute_callable(context=context, **execute_callable_kwargs)
  File "/home/airflow/.local/lib/python3.8/site-packages/airflow/operators/python.py", line 199, in execute
    return_value = self.execute_callable()
  File "/home/airflow/.local/lib/python3.8/site-packages/airflow/operators/python.py", line 216, in execute_callable
    return self.python_callable(*self.op_args, **self.op_kwargs)
TypeError: transformed_data() missing 1 required positional argument: 'extract'
[2025-07-08T22:44:43.275+0000] {taskinstance.py:1138} INFO - Marking task as UP_FOR_RETRY. dag_id=flight_etl_dag, task_id=transforming_data, execution_date=20250708T224413, start_date=20250708T224442, end_date=20250708T224443
[2025-07-08T22:44:43.295+0000] {standard_task_runner.py:107} ERROR - Failed to execute job 28 for task transforming_data (transformed_data() missing 1 required positional argument: 'extract'; 156)
[2025-07-08T22:44:43.313+0000] {local_task_job_runner.py:234} INFO - Task exited with return code 1
[2025-07-08T22:44:43.347+0000] {taskinstance.py:3280} INFO - 0 downstream tasks scheduled from follow-on schedule check
