[2025-07-08T22:45:51.861+0000] {taskinstance.py:1956} INFO - Dependencies all met for dep_context=non-requeueable deps ti=<TaskInstance: flight_etl_dag.transforming_data manual__2025-07-08T22:44:13.757971+00:00 [queued]>
[2025-07-08T22:45:51.871+0000] {taskinstance.py:1956} INFO - Dependencies all met for dep_context=requeueable deps ti=<TaskInstance: flight_etl_dag.transforming_data manual__2025-07-08T22:44:13.757971+00:00 [queued]>
[2025-07-08T22:45:51.872+0000] {taskinstance.py:2170} INFO - Starting attempt 2 of 2
[2025-07-08T22:45:51.891+0000] {taskinstance.py:2191} INFO - Executing <Task(PythonOperator): transforming_data> on 2025-07-08 22:44:13.757971+00:00
[2025-07-08T22:45:51.899+0000] {standard_task_runner.py:60} INFO - Started process 175 to run task
[2025-07-08T22:45:51.907+0000] {standard_task_runner.py:87} INFO - Running: ['***', 'tasks', 'run', 'flight_etl_dag', 'transforming_data', 'manual__2025-07-08T22:44:13.757971+00:00', '--job-id', '29', '--raw', '--subdir', 'DAGS_FOLDER/flight_etl_dag.py', '--cfg-path', '/tmp/tmph1gagcox']
[2025-07-08T22:45:51.909+0000] {standard_task_runner.py:88} INFO - Job 29: Subtask transforming_data
[2025-07-08T22:45:51.999+0000] {task_command.py:423} INFO - Running <TaskInstance: flight_etl_dag.transforming_data manual__2025-07-08T22:44:13.757971+00:00 [running]> on host dd092c829c91
[2025-07-08T22:45:52.091+0000] {taskinstance.py:2480} INFO - Exporting env vars: AIRFLOW_CTX_DAG_OWNER='***' AIRFLOW_CTX_DAG_ID='flight_etl_dag' AIRFLOW_CTX_TASK_ID='transforming_data' AIRFLOW_CTX_EXECUTION_DATE='2025-07-08T22:44:13.757971+00:00' AIRFLOW_CTX_TRY_NUMBER='2' AIRFLOW_CTX_DAG_RUN_ID='manual__2025-07-08T22:44:13.757971+00:00'
[2025-07-08T22:45:52.094+0000] {taskinstance.py:2698} ERROR - Task failed with exception
Traceback (most recent call last):
  File "/home/airflow/.local/lib/python3.8/site-packages/airflow/models/taskinstance.py", line 433, in _execute_task
    result = execute_callable(context=context, **execute_callable_kwargs)
  File "/home/airflow/.local/lib/python3.8/site-packages/airflow/operators/python.py", line 199, in execute
    return_value = self.execute_callable()
  File "/home/airflow/.local/lib/python3.8/site-packages/airflow/operators/python.py", line 216, in execute_callable
    return self.python_callable(*self.op_args, **self.op_kwargs)
TypeError: transformed_data() missing 1 required positional argument: 'extract'
[2025-07-08T22:45:52.105+0000] {taskinstance.py:1138} INFO - Marking task as FAILED. dag_id=flight_etl_dag, task_id=transforming_data, execution_date=20250708T224413, start_date=20250708T224551, end_date=20250708T224552
[2025-07-08T22:45:52.123+0000] {standard_task_runner.py:107} ERROR - Failed to execute job 29 for task transforming_data (transformed_data() missing 1 required positional argument: 'extract'; 175)
[2025-07-08T22:45:52.160+0000] {local_task_job_runner.py:234} INFO - Task exited with return code 1
[2025-07-08T22:45:52.198+0000] {taskinstance.py:3280} INFO - 0 downstream tasks scheduled from follow-on schedule check
