[2025-07-09T19:57:47.021+0000] {taskinstance.py:1956} INFO - Dependencies all met for dep_context=non-requeueable deps ti=<TaskInstance: flight_etl_dag.loading_data scheduled__2025-07-08T00:00:00+00:00 [queued]>
[2025-07-09T19:57:47.035+0000] {taskinstance.py:1956} INFO - Dependencies all met for dep_context=requeueable deps ti=<TaskInstance: flight_etl_dag.loading_data scheduled__2025-07-08T00:00:00+00:00 [queued]>
[2025-07-09T19:57:47.036+0000] {taskinstance.py:2170} INFO - Starting attempt 1 of 2
[2025-07-09T19:57:47.069+0000] {taskinstance.py:2191} INFO - Executing <Task(PythonOperator): loading_data> on 2025-07-08 00:00:00+00:00
[2025-07-09T19:57:47.077+0000] {standard_task_runner.py:60} INFO - Started process 103 to run task
[2025-07-09T19:57:47.081+0000] {standard_task_runner.py:87} INFO - Running: ['***', 'tasks', 'run', 'flight_etl_dag', 'loading_data', 'scheduled__2025-07-08T00:00:00+00:00', '--job-id', '44', '--raw', '--subdir', 'DAGS_FOLDER/flight_etl_dag.py', '--cfg-path', '/tmp/tmpae2qoaf8']
[2025-07-09T19:57:47.083+0000] {standard_task_runner.py:88} INFO - Job 44: Subtask loading_data
[2025-07-09T19:57:47.172+0000] {task_command.py:423} INFO - Running <TaskInstance: flight_etl_dag.loading_data scheduled__2025-07-08T00:00:00+00:00 [running]> on host 114668798ca9
[2025-07-09T19:57:47.270+0000] {taskinstance.py:2480} INFO - Exporting env vars: AIRFLOW_CTX_DAG_OWNER='***' AIRFLOW_CTX_DAG_ID='flight_etl_dag' AIRFLOW_CTX_TASK_ID='loading_data' AIRFLOW_CTX_EXECUTION_DATE='2025-07-08T00:00:00+00:00' AIRFLOW_CTX_TRY_NUMBER='1' AIRFLOW_CTX_DAG_RUN_ID='scheduled__2025-07-08T00:00:00+00:00'
[2025-07-09T19:57:47.443+0000] {taskinstance.py:2698} ERROR - Task failed with exception
Traceback (most recent call last):
  File "/home/airflow/.local/lib/python3.8/site-packages/airflow/models/taskinstance.py", line 433, in _execute_task
    result = execute_callable(context=context, **execute_callable_kwargs)
  File "/home/airflow/.local/lib/python3.8/site-packages/airflow/operators/python.py", line 199, in execute
    return_value = self.execute_callable()
  File "/home/airflow/.local/lib/python3.8/site-packages/airflow/operators/python.py", line 216, in execute_callable
    return self.python_callable(*self.op_args, **self.op_kwargs)
  File "/opt/airflow/load.py", line 9, in load_to_db
    conn=psycopg2.connect(**DB_CONFIG)
  File "/home/airflow/.local/lib/python3.8/site-packages/psycopg2/__init__.py", line 122, in connect
    conn = _connect(dsn, connection_factory=connection_factory, **kwasync)
psycopg2.OperationalError: connection to server at "localhost" (::1), port 5432 failed: Connection refused
	Is the server running on that host and accepting TCP/IP connections?
connection to server at "localhost" (127.0.0.1), port 5432 failed: Connection refused
	Is the server running on that host and accepting TCP/IP connections?

[2025-07-09T19:57:47.463+0000] {taskinstance.py:1138} INFO - Marking task as UP_FOR_RETRY. dag_id=flight_etl_dag, task_id=loading_data, execution_date=20250708T000000, start_date=20250709T195747, end_date=20250709T195747
[2025-07-09T19:57:47.480+0000] {standard_task_runner.py:107} ERROR - Failed to execute job 44 for task loading_data (connection to server at "localhost" (::1), port 5432 failed: Connection refused
	Is the server running on that host and accepting TCP/IP connections?
connection to server at "localhost" (127.0.0.1), port 5432 failed: Connection refused
	Is the server running on that host and accepting TCP/IP connections?
; 103)
[2025-07-09T19:57:47.502+0000] {local_task_job_runner.py:234} INFO - Task exited with return code 1
[2025-07-09T19:57:47.522+0000] {taskinstance.py:3280} INFO - 0 downstream tasks scheduled from follow-on schedule check
[2025-07-09T23:03:01.662+0000] {taskinstance.py:1956} INFO - Dependencies all met for dep_context=non-requeueable deps ti=<TaskInstance: flight_etl_dag.loading_data scheduled__2025-07-08T00:00:00+00:00 [queued]>
[2025-07-09T23:03:01.674+0000] {taskinstance.py:1956} INFO - Dependencies all met for dep_context=requeueable deps ti=<TaskInstance: flight_etl_dag.loading_data scheduled__2025-07-08T00:00:00+00:00 [queued]>
[2025-07-09T23:03:01.675+0000] {taskinstance.py:2170} INFO - Starting attempt 1 of 2
[2025-07-09T23:03:01.698+0000] {taskinstance.py:2191} INFO - Executing <Task(PythonOperator): loading_data> on 2025-07-08 00:00:00+00:00
[2025-07-09T23:03:01.706+0000] {standard_task_runner.py:60} INFO - Started process 111 to run task
[2025-07-09T23:03:01.710+0000] {standard_task_runner.py:87} INFO - Running: ['***', 'tasks', 'run', 'flight_etl_dag', 'loading_data', 'scheduled__2025-07-08T00:00:00+00:00', '--job-id', '8', '--raw', '--subdir', 'DAGS_FOLDER/flight_etl_dag.py', '--cfg-path', '/tmp/tmpdx5jaob_']
[2025-07-09T23:03:01.713+0000] {standard_task_runner.py:88} INFO - Job 8: Subtask loading_data
[2025-07-09T23:03:01.822+0000] {task_command.py:423} INFO - Running <TaskInstance: flight_etl_dag.loading_data scheduled__2025-07-08T00:00:00+00:00 [running]> on host c1ae22876222
[2025-07-09T23:03:01.926+0000] {taskinstance.py:2480} INFO - Exporting env vars: AIRFLOW_CTX_DAG_OWNER='***' AIRFLOW_CTX_DAG_ID='flight_etl_dag' AIRFLOW_CTX_TASK_ID='loading_data' AIRFLOW_CTX_EXECUTION_DATE='2025-07-08T00:00:00+00:00' AIRFLOW_CTX_TRY_NUMBER='1' AIRFLOW_CTX_DAG_RUN_ID='scheduled__2025-07-08T00:00:00+00:00'
[2025-07-09T23:03:02.108+0000] {taskinstance.py:2698} ERROR - Task failed with exception
Traceback (most recent call last):
  File "/home/airflow/.local/lib/python3.8/site-packages/airflow/models/taskinstance.py", line 433, in _execute_task
    result = execute_callable(context=context, **execute_callable_kwargs)
  File "/home/airflow/.local/lib/python3.8/site-packages/airflow/operators/python.py", line 199, in execute
    return_value = self.execute_callable()
  File "/home/airflow/.local/lib/python3.8/site-packages/airflow/operators/python.py", line 216, in execute_callable
    return self.python_callable(*self.op_args, **self.op_kwargs)
  File "/opt/airflow/load.py", line 9, in load_to_db
    conn=psycopg2.connect(**DB_CONFIG)
  File "/home/airflow/.local/lib/python3.8/site-packages/psycopg2/__init__.py", line 122, in connect
    conn = _connect(dsn, connection_factory=connection_factory, **kwasync)
psycopg2.OperationalError: connection to server at "postgres" (172.18.0.2), port 5432 failed: FATAL:  password authentication failed for user "postgres"

[2025-07-09T23:03:02.127+0000] {taskinstance.py:1138} INFO - Marking task as UP_FOR_RETRY. dag_id=flight_etl_dag, task_id=loading_data, execution_date=20250708T000000, start_date=20250709T230301, end_date=20250709T230302
[2025-07-09T23:03:02.148+0000] {standard_task_runner.py:107} ERROR - Failed to execute job 8 for task loading_data (connection to server at "postgres" (172.18.0.2), port 5432 failed: FATAL:  password authentication failed for user "postgres"
; 111)
[2025-07-09T23:03:02.166+0000] {local_task_job_runner.py:234} INFO - Task exited with return code 1
[2025-07-09T23:03:02.188+0000] {taskinstance.py:3280} INFO - 0 downstream tasks scheduled from follow-on schedule check
[2025-07-09T23:55:48.417+0000] {taskinstance.py:1956} INFO - Dependencies all met for dep_context=non-requeueable deps ti=<TaskInstance: flight_etl_dag.loading_data scheduled__2025-07-08T00:00:00+00:00 [queued]>
[2025-07-09T23:55:48.429+0000] {taskinstance.py:1956} INFO - Dependencies all met for dep_context=requeueable deps ti=<TaskInstance: flight_etl_dag.loading_data scheduled__2025-07-08T00:00:00+00:00 [queued]>
[2025-07-09T23:55:48.430+0000] {taskinstance.py:2170} INFO - Starting attempt 1 of 2
[2025-07-09T23:55:48.451+0000] {taskinstance.py:2191} INFO - Executing <Task(PythonOperator): loading_data> on 2025-07-08 00:00:00+00:00
[2025-07-09T23:55:48.459+0000] {standard_task_runner.py:60} INFO - Started process 99 to run task
[2025-07-09T23:55:48.464+0000] {standard_task_runner.py:87} INFO - Running: ['airflow', 'tasks', 'run', 'flight_etl_dag', 'loading_data', 'scheduled__2025-07-08T00:00:00+00:00', '--job-id', '7', '--raw', '--subdir', 'DAGS_FOLDER/flight_etl_dag.py', '--cfg-path', '/tmp/tmp7qw1kawu']
[2025-07-09T23:55:48.465+0000] {standard_task_runner.py:88} INFO - Job 7: Subtask loading_data
[2025-07-09T23:55:48.565+0000] {task_command.py:423} INFO - Running <TaskInstance: flight_etl_dag.loading_data scheduled__2025-07-08T00:00:00+00:00 [running]> on host bd098a0b95e0
[2025-07-09T23:55:48.656+0000] {taskinstance.py:2480} INFO - Exporting env vars: AIRFLOW_CTX_DAG_OWNER='airflow' AIRFLOW_CTX_DAG_ID='flight_etl_dag' AIRFLOW_CTX_TASK_ID='loading_data' AIRFLOW_CTX_EXECUTION_DATE='2025-07-08T00:00:00+00:00' AIRFLOW_CTX_TRY_NUMBER='1' AIRFLOW_CTX_DAG_RUN_ID='scheduled__2025-07-08T00:00:00+00:00'
[2025-07-09T23:55:48.832+0000] {taskinstance.py:2698} ERROR - Task failed with exception
Traceback (most recent call last):
  File "/home/airflow/.local/lib/python3.8/site-packages/airflow/models/taskinstance.py", line 433, in _execute_task
    result = execute_callable(context=context, **execute_callable_kwargs)
  File "/home/airflow/.local/lib/python3.8/site-packages/airflow/operators/python.py", line 199, in execute
    return_value = self.execute_callable()
  File "/home/airflow/.local/lib/python3.8/site-packages/airflow/operators/python.py", line 216, in execute_callable
    return self.python_callable(*self.op_args, **self.op_kwargs)
  File "/opt/airflow/load.py", line 15, in load_to_db
    cursor.execute("""INSERT INTO aircraft(aircraft_id,origin_country)
psycopg2.errors.UndefinedTable: relation "aircraft" does not exist
LINE 1: INSERT INTO aircraft(aircraft_id,origin_country) 
                    ^

[2025-07-09T23:55:48.849+0000] {taskinstance.py:1138} INFO - Marking task as UP_FOR_RETRY. dag_id=flight_etl_dag, task_id=loading_data, execution_date=20250708T000000, start_date=20250709T235548, end_date=20250709T235548
[2025-07-09T23:55:48.876+0000] {standard_task_runner.py:107} ERROR - Failed to execute job 7 for task loading_data (relation "aircraft" does not exist
LINE 1: INSERT INTO aircraft(aircraft_id,origin_country) 
                    ^
; 99)
[2025-07-09T23:55:48.919+0000] {local_task_job_runner.py:234} INFO - Task exited with return code 1
[2025-07-09T23:55:48.944+0000] {taskinstance.py:3280} INFO - 0 downstream tasks scheduled from follow-on schedule check
