[2025-07-09T19:58:57.732+0000] {taskinstance.py:1956} INFO - Dependencies all met for dep_context=non-requeueable deps ti=<TaskInstance: flight_etl_dag.loading_data scheduled__2025-07-08T00:00:00+00:00 [queued]>
[2025-07-09T19:58:57.746+0000] {taskinstance.py:1956} INFO - Dependencies all met for dep_context=requeueable deps ti=<TaskInstance: flight_etl_dag.loading_data scheduled__2025-07-08T00:00:00+00:00 [queued]>
[2025-07-09T19:58:57.748+0000] {taskinstance.py:2170} INFO - Starting attempt 2 of 2
[2025-07-09T19:58:57.770+0000] {taskinstance.py:2191} INFO - Executing <Task(PythonOperator): loading_data> on 2025-07-08 00:00:00+00:00
[2025-07-09T19:58:57.780+0000] {standard_task_runner.py:60} INFO - Started process 128 to run task
[2025-07-09T19:58:57.786+0000] {standard_task_runner.py:87} INFO - Running: ['***', 'tasks', 'run', 'flight_etl_dag', 'loading_data', 'scheduled__2025-07-08T00:00:00+00:00', '--job-id', '47', '--raw', '--subdir', 'DAGS_FOLDER/flight_etl_dag.py', '--cfg-path', '/tmp/tmpzwwc46fw']
[2025-07-09T19:58:57.789+0000] {standard_task_runner.py:88} INFO - Job 47: Subtask loading_data
[2025-07-09T19:58:57.894+0000] {task_command.py:423} INFO - Running <TaskInstance: flight_etl_dag.loading_data scheduled__2025-07-08T00:00:00+00:00 [running]> on host 114668798ca9
[2025-07-09T19:58:58.012+0000] {taskinstance.py:2480} INFO - Exporting env vars: AIRFLOW_CTX_DAG_OWNER='***' AIRFLOW_CTX_DAG_ID='flight_etl_dag' AIRFLOW_CTX_TASK_ID='loading_data' AIRFLOW_CTX_EXECUTION_DATE='2025-07-08T00:00:00+00:00' AIRFLOW_CTX_TRY_NUMBER='2' AIRFLOW_CTX_DAG_RUN_ID='scheduled__2025-07-08T00:00:00+00:00'
[2025-07-09T19:58:58.237+0000] {taskinstance.py:2698} ERROR - Task failed with exception
Traceback (most recent call last):
  File "/home/airflow/.local/lib/python3.8/site-packages/airflow/models/taskinstance.py", line 433, in _execute_task
    result = execute_callable(context=context, **execute_callable_kwargs)
  File "/home/airflow/.local/lib/python3.8/site-packages/airflow/operators/python.py", line 199, in execute
    return_value = self.execute_callable()
  File "/home/airflow/.local/lib/python3.8/site-packages/airflow/operators/python.py", line 216, in execute_callable
    return self.python_callable(*self.op_args, **self.op_kwargs)
  File "/opt/airflow/load.py", line 9, in load_to_db
    conn=psycopg2.connect(**DB_CONFIG)
  File "/home/airflow/.local/lib/python3.8/site-packages/psycopg2/__init__.py", line 122, in connect
    conn = _connect(dsn, connection_factory=connection_factory, **kwasync)
psycopg2.OperationalError: connection to server at "localhost" (::1), port 5432 failed: Connection refused
	Is the server running on that host and accepting TCP/IP connections?
connection to server at "localhost" (127.0.0.1), port 5432 failed: Connection refused
	Is the server running on that host and accepting TCP/IP connections?

[2025-07-09T19:58:58.258+0000] {taskinstance.py:1138} INFO - Marking task as FAILED. dag_id=flight_etl_dag, task_id=loading_data, execution_date=20250708T000000, start_date=20250709T195857, end_date=20250709T195858
[2025-07-09T19:58:58.275+0000] {standard_task_runner.py:107} ERROR - Failed to execute job 47 for task loading_data (connection to server at "localhost" (::1), port 5432 failed: Connection refused
	Is the server running on that host and accepting TCP/IP connections?
connection to server at "localhost" (127.0.0.1), port 5432 failed: Connection refused
	Is the server running on that host and accepting TCP/IP connections?
; 128)
[2025-07-09T19:58:58.321+0000] {local_task_job_runner.py:234} INFO - Task exited with return code 1
[2025-07-09T19:58:58.344+0000] {taskinstance.py:3280} INFO - 0 downstream tasks scheduled from follow-on schedule check
[2025-07-09T23:04:05.868+0000] {taskinstance.py:1956} INFO - Dependencies all met for dep_context=non-requeueable deps ti=<TaskInstance: flight_etl_dag.loading_data scheduled__2025-07-08T00:00:00+00:00 [queued]>
[2025-07-09T23:04:05.880+0000] {taskinstance.py:1956} INFO - Dependencies all met for dep_context=requeueable deps ti=<TaskInstance: flight_etl_dag.loading_data scheduled__2025-07-08T00:00:00+00:00 [queued]>
[2025-07-09T23:04:05.881+0000] {taskinstance.py:2170} INFO - Starting attempt 2 of 2
[2025-07-09T23:04:05.904+0000] {taskinstance.py:2191} INFO - Executing <Task(PythonOperator): loading_data> on 2025-07-08 00:00:00+00:00
[2025-07-09T23:04:05.911+0000] {standard_task_runner.py:60} INFO - Started process 133 to run task
[2025-07-09T23:04:05.917+0000] {standard_task_runner.py:87} INFO - Running: ['***', 'tasks', 'run', 'flight_etl_dag', 'loading_data', 'scheduled__2025-07-08T00:00:00+00:00', '--job-id', '10', '--raw', '--subdir', 'DAGS_FOLDER/flight_etl_dag.py', '--cfg-path', '/tmp/tmptc9rr5f5']
[2025-07-09T23:04:05.920+0000] {standard_task_runner.py:88} INFO - Job 10: Subtask loading_data
[2025-07-09T23:04:06.036+0000] {task_command.py:423} INFO - Running <TaskInstance: flight_etl_dag.loading_data scheduled__2025-07-08T00:00:00+00:00 [running]> on host c1ae22876222
[2025-07-09T23:04:06.135+0000] {taskinstance.py:2480} INFO - Exporting env vars: AIRFLOW_CTX_DAG_OWNER='***' AIRFLOW_CTX_DAG_ID='flight_etl_dag' AIRFLOW_CTX_TASK_ID='loading_data' AIRFLOW_CTX_EXECUTION_DATE='2025-07-08T00:00:00+00:00' AIRFLOW_CTX_TRY_NUMBER='2' AIRFLOW_CTX_DAG_RUN_ID='scheduled__2025-07-08T00:00:00+00:00'
[2025-07-09T23:04:06.306+0000] {taskinstance.py:2698} ERROR - Task failed with exception
Traceback (most recent call last):
  File "/home/airflow/.local/lib/python3.8/site-packages/airflow/models/taskinstance.py", line 433, in _execute_task
    result = execute_callable(context=context, **execute_callable_kwargs)
  File "/home/airflow/.local/lib/python3.8/site-packages/airflow/operators/python.py", line 199, in execute
    return_value = self.execute_callable()
  File "/home/airflow/.local/lib/python3.8/site-packages/airflow/operators/python.py", line 216, in execute_callable
    return self.python_callable(*self.op_args, **self.op_kwargs)
  File "/opt/airflow/load.py", line 9, in load_to_db
    conn=psycopg2.connect(**DB_CONFIG)
  File "/home/airflow/.local/lib/python3.8/site-packages/psycopg2/__init__.py", line 122, in connect
    conn = _connect(dsn, connection_factory=connection_factory, **kwasync)
psycopg2.OperationalError: connection to server at "postgres" (172.18.0.2), port 5432 failed: FATAL:  password authentication failed for user "postgres"

[2025-07-09T23:04:06.326+0000] {taskinstance.py:1138} INFO - Marking task as FAILED. dag_id=flight_etl_dag, task_id=loading_data, execution_date=20250708T000000, start_date=20250709T230405, end_date=20250709T230406
[2025-07-09T23:04:06.350+0000] {standard_task_runner.py:107} ERROR - Failed to execute job 10 for task loading_data (connection to server at "postgres" (172.18.0.2), port 5432 failed: FATAL:  password authentication failed for user "postgres"
; 133)
[2025-07-09T23:04:06.372+0000] {local_task_job_runner.py:234} INFO - Task exited with return code 1
[2025-07-09T23:04:06.393+0000] {taskinstance.py:3280} INFO - 0 downstream tasks scheduled from follow-on schedule check
