[2025-07-09T23:55:48.496+0000] {taskinstance.py:1956} INFO - Dependencies all met for dep_context=non-requeueable deps ti=<TaskInstance: flight_etl_dag.loading_data manual__2025-07-09T23:55:17.701567+00:00 [queued]>
[2025-07-09T23:55:48.508+0000] {taskinstance.py:1956} INFO - Dependencies all met for dep_context=requeueable deps ti=<TaskInstance: flight_etl_dag.loading_data manual__2025-07-09T23:55:17.701567+00:00 [queued]>
[2025-07-09T23:55:48.509+0000] {taskinstance.py:2170} INFO - Starting attempt 1 of 2
[2025-07-09T23:55:48.530+0000] {taskinstance.py:2191} INFO - Executing <Task(PythonOperator): loading_data> on 2025-07-09 23:55:17.701567+00:00
[2025-07-09T23:55:48.539+0000] {standard_task_runner.py:60} INFO - Started process 100 to run task
[2025-07-09T23:55:48.545+0000] {standard_task_runner.py:87} INFO - Running: ['airflow', 'tasks', 'run', 'flight_etl_dag', 'loading_data', 'manual__2025-07-09T23:55:17.701567+00:00', '--job-id', '8', '--raw', '--subdir', 'DAGS_FOLDER/flight_etl_dag.py', '--cfg-path', '/tmp/tmpdiuip9te']
[2025-07-09T23:55:48.547+0000] {standard_task_runner.py:88} INFO - Job 8: Subtask loading_data
[2025-07-09T23:55:48.627+0000] {task_command.py:423} INFO - Running <TaskInstance: flight_etl_dag.loading_data manual__2025-07-09T23:55:17.701567+00:00 [running]> on host bd098a0b95e0
[2025-07-09T23:55:48.719+0000] {taskinstance.py:2480} INFO - Exporting env vars: AIRFLOW_CTX_DAG_OWNER='airflow' AIRFLOW_CTX_DAG_ID='flight_etl_dag' AIRFLOW_CTX_TASK_ID='loading_data' AIRFLOW_CTX_EXECUTION_DATE='2025-07-09T23:55:17.701567+00:00' AIRFLOW_CTX_TRY_NUMBER='1' AIRFLOW_CTX_DAG_RUN_ID='manual__2025-07-09T23:55:17.701567+00:00'
[2025-07-09T23:55:48.906+0000] {taskinstance.py:2698} ERROR - Task failed with exception
Traceback (most recent call last):
  File "/home/airflow/.local/lib/python3.8/site-packages/airflow/models/taskinstance.py", line 433, in _execute_task
    result = execute_callable(context=context, **execute_callable_kwargs)
  File "/home/airflow/.local/lib/python3.8/site-packages/airflow/operators/python.py", line 199, in execute
    return_value = self.execute_callable()
  File "/home/airflow/.local/lib/python3.8/site-packages/airflow/operators/python.py", line 216, in execute_callable
    return self.python_callable(*self.op_args, **self.op_kwargs)
  File "/opt/airflow/load.py", line 15, in load_to_db
    cursor.execute("""INSERT INTO aircraft(aircraft_id,origin_country)
psycopg2.errors.UndefinedTable: relation "aircraft" does not exist
LINE 1: INSERT INTO aircraft(aircraft_id,origin_country) 
                    ^

[2025-07-09T23:55:48.925+0000] {taskinstance.py:1138} INFO - Marking task as UP_FOR_RETRY. dag_id=flight_etl_dag, task_id=loading_data, execution_date=20250709T235517, start_date=20250709T235548, end_date=20250709T235548
[2025-07-09T23:55:48.945+0000] {standard_task_runner.py:107} ERROR - Failed to execute job 8 for task loading_data (relation "aircraft" does not exist
LINE 1: INSERT INTO aircraft(aircraft_id,origin_country) 
                    ^
; 100)
[2025-07-09T23:55:49.000+0000] {local_task_job_runner.py:234} INFO - Task exited with return code 1
[2025-07-09T23:55:49.021+0000] {taskinstance.py:3280} INFO - 0 downstream tasks scheduled from follow-on schedule check
