[2025-07-09T22:51:46.614+0000] {taskinstance.py:1956} INFO - Dependencies all met for dep_context=non-requeueable deps ti=<TaskInstance: flight_etl_dag.loading_data manual__2025-07-09T22:50:19.053246+00:00 [queued]>
[2025-07-09T22:51:46.625+0000] {taskinstance.py:1956} INFO - Dependencies all met for dep_context=requeueable deps ti=<TaskInstance: flight_etl_dag.loading_data manual__2025-07-09T22:50:19.053246+00:00 [queued]>
[2025-07-09T22:51:46.626+0000] {taskinstance.py:2170} INFO - Starting attempt 2 of 3
[2025-07-09T22:51:46.644+0000] {taskinstance.py:2191} INFO - Executing <Task(PythonOperator): loading_data> on 2025-07-09 22:50:19.053246+00:00
[2025-07-09T22:51:46.652+0000] {standard_task_runner.py:60} INFO - Started process 234 to run task
[2025-07-09T22:51:46.656+0000] {standard_task_runner.py:87} INFO - Running: ['***', 'tasks', 'run', 'flight_etl_dag', 'loading_data', 'manual__2025-07-09T22:50:19.053246+00:00', '--job-id', '58', '--raw', '--subdir', 'DAGS_FOLDER/flight_etl_dag.py', '--cfg-path', '/tmp/tmp1wmw7c0f']
[2025-07-09T22:51:46.658+0000] {standard_task_runner.py:88} INFO - Job 58: Subtask loading_data
[2025-07-09T22:51:46.754+0000] {task_command.py:423} INFO - Running <TaskInstance: flight_etl_dag.loading_data manual__2025-07-09T22:50:19.053246+00:00 [running]> on host 114668798ca9
[2025-07-09T22:51:46.849+0000] {taskinstance.py:2480} INFO - Exporting env vars: AIRFLOW_CTX_DAG_OWNER='***' AIRFLOW_CTX_DAG_ID='flight_etl_dag' AIRFLOW_CTX_TASK_ID='loading_data' AIRFLOW_CTX_EXECUTION_DATE='2025-07-09T22:50:19.053246+00:00' AIRFLOW_CTX_TRY_NUMBER='2' AIRFLOW_CTX_DAG_RUN_ID='manual__2025-07-09T22:50:19.053246+00:00'
[2025-07-09T22:51:47.014+0000] {taskinstance.py:2698} ERROR - Task failed with exception
Traceback (most recent call last):
  File "/home/airflow/.local/lib/python3.8/site-packages/airflow/models/taskinstance.py", line 433, in _execute_task
    result = execute_callable(context=context, **execute_callable_kwargs)
  File "/home/airflow/.local/lib/python3.8/site-packages/airflow/operators/python.py", line 199, in execute
    return_value = self.execute_callable()
  File "/home/airflow/.local/lib/python3.8/site-packages/airflow/operators/python.py", line 216, in execute_callable
    return self.python_callable(*self.op_args, **self.op_kwargs)
  File "/opt/airflow/load.py", line 9, in load_to_db
    conn=psycopg2.connect(**DB_CONFIG)
  File "/home/airflow/.local/lib/python3.8/site-packages/psycopg2/__init__.py", line 122, in connect
    conn = _connect(dsn, connection_factory=connection_factory, **kwasync)
psycopg2.OperationalError: connection to server at "localhost" (::1), port 5432 failed: Connection refused
	Is the server running on that host and accepting TCP/IP connections?
connection to server at "localhost" (127.0.0.1), port 5432 failed: Connection refused
	Is the server running on that host and accepting TCP/IP connections?

[2025-07-09T22:51:47.030+0000] {taskinstance.py:1138} INFO - Marking task as UP_FOR_RETRY. dag_id=flight_etl_dag, task_id=loading_data, execution_date=20250709T225019, start_date=20250709T225146, end_date=20250709T225147
[2025-07-09T22:51:47.048+0000] {standard_task_runner.py:107} ERROR - Failed to execute job 58 for task loading_data (connection to server at "localhost" (::1), port 5432 failed: Connection refused
	Is the server running on that host and accepting TCP/IP connections?
connection to server at "localhost" (127.0.0.1), port 5432 failed: Connection refused
	Is the server running on that host and accepting TCP/IP connections?
; 234)
[2025-07-09T22:51:47.070+0000] {local_task_job_runner.py:234} INFO - Task exited with return code 1
[2025-07-09T22:51:47.096+0000] {taskinstance.py:3280} INFO - 0 downstream tasks scheduled from follow-on schedule check
