[2025-07-09T19:58:58.683+0000] {taskinstance.py:1956} INFO - Dependencies all met for dep_context=non-requeueable deps ti=<TaskInstance: flight_etl_dag.loading_data manual__2025-07-09T19:56:26.718366+00:00 [queued]>
[2025-07-09T19:58:58.703+0000] {taskinstance.py:1956} INFO - Dependencies all met for dep_context=requeueable deps ti=<TaskInstance: flight_etl_dag.loading_data manual__2025-07-09T19:56:26.718366+00:00 [queued]>
[2025-07-09T19:58:58.709+0000] {taskinstance.py:2170} INFO - Starting attempt 2 of 2
[2025-07-09T19:58:58.739+0000] {taskinstance.py:2191} INFO - Executing <Task(PythonOperator): loading_data> on 2025-07-09 19:56:26.718366+00:00
[2025-07-09T19:58:58.749+0000] {standard_task_runner.py:60} INFO - Started process 129 to run task
[2025-07-09T19:58:58.755+0000] {standard_task_runner.py:87} INFO - Running: ['***', 'tasks', 'run', 'flight_etl_dag', 'loading_data', 'manual__2025-07-09T19:56:26.718366+00:00', '--job-id', '48', '--raw', '--subdir', 'DAGS_FOLDER/flight_etl_dag.py', '--cfg-path', '/tmp/tmpl2iv9gfm']
[2025-07-09T19:58:58.759+0000] {standard_task_runner.py:88} INFO - Job 48: Subtask loading_data
[2025-07-09T19:58:58.887+0000] {task_command.py:423} INFO - Running <TaskInstance: flight_etl_dag.loading_data manual__2025-07-09T19:56:26.718366+00:00 [running]> on host 114668798ca9
[2025-07-09T19:58:58.998+0000] {taskinstance.py:2480} INFO - Exporting env vars: AIRFLOW_CTX_DAG_OWNER='***' AIRFLOW_CTX_DAG_ID='flight_etl_dag' AIRFLOW_CTX_TASK_ID='loading_data' AIRFLOW_CTX_EXECUTION_DATE='2025-07-09T19:56:26.718366+00:00' AIRFLOW_CTX_TRY_NUMBER='2' AIRFLOW_CTX_DAG_RUN_ID='manual__2025-07-09T19:56:26.718366+00:00'
[2025-07-09T19:58:59.181+0000] {taskinstance.py:2698} ERROR - Task failed with exception
Traceback (most recent call last):
  File "/home/airflow/.local/lib/python3.8/site-packages/airflow/models/taskinstance.py", line 433, in _execute_task
    result = execute_callable(context=context, **execute_callable_kwargs)
  File "/home/airflow/.local/lib/python3.8/site-packages/airflow/operators/python.py", line 199, in execute
    return_value = self.execute_callable()
  File "/home/airflow/.local/lib/python3.8/site-packages/airflow/operators/python.py", line 216, in execute_callable
    return self.python_callable(*self.op_args, **self.op_kwargs)
  File "/opt/airflow/load.py", line 9, in load_to_db
    conn=psycopg2.connect(**DB_CONFIG)
  File "/home/airflow/.local/lib/python3.8/site-packages/psycopg2/__init__.py", line 122, in connect
    conn = _connect(dsn, connection_factory=connection_factory, **kwasync)
psycopg2.OperationalError: connection to server at "localhost" (::1), port 5432 failed: Connection refused
	Is the server running on that host and accepting TCP/IP connections?
connection to server at "localhost" (127.0.0.1), port 5432 failed: Connection refused
	Is the server running on that host and accepting TCP/IP connections?

[2025-07-09T19:58:59.200+0000] {taskinstance.py:1138} INFO - Marking task as FAILED. dag_id=flight_etl_dag, task_id=loading_data, execution_date=20250709T195626, start_date=20250709T195858, end_date=20250709T195859
[2025-07-09T19:58:59.217+0000] {standard_task_runner.py:107} ERROR - Failed to execute job 48 for task loading_data (connection to server at "localhost" (::1), port 5432 failed: Connection refused
	Is the server running on that host and accepting TCP/IP connections?
connection to server at "localhost" (127.0.0.1), port 5432 failed: Connection refused
	Is the server running on that host and accepting TCP/IP connections?
; 129)
[2025-07-09T19:58:59.249+0000] {local_task_job_runner.py:234} INFO - Task exited with return code 1
[2025-07-09T19:58:59.267+0000] {taskinstance.py:3280} INFO - 0 downstream tasks scheduled from follow-on schedule check
