[2025-07-11T16:00:59.393+0000] {taskinstance.py:1956} INFO - Dependencies all met for dep_context=non-requeueable deps ti=<TaskInstance: flight_etl_dag.loading_data manual__2025-07-11T16:00:48.984577+00:00 [queued]>
[2025-07-11T16:00:59.402+0000] {taskinstance.py:1956} INFO - Dependencies all met for dep_context=requeueable deps ti=<TaskInstance: flight_etl_dag.loading_data manual__2025-07-11T16:00:48.984577+00:00 [queued]>
[2025-07-11T16:00:59.403+0000] {taskinstance.py:2170} INFO - Starting attempt 1 of 2
[2025-07-11T16:00:59.419+0000] {taskinstance.py:2191} INFO - Executing <Task(PythonOperator): loading_data> on 2025-07-11 16:00:48.984577+00:00
[2025-07-11T16:00:59.425+0000] {standard_task_runner.py:60} INFO - Started process 93 to run task
[2025-07-11T16:00:59.429+0000] {standard_task_runner.py:87} INFO - Running: ['airflow', 'tasks', 'run', 'flight_etl_dag', 'loading_data', 'manual__2025-07-11T16:00:48.984577+00:00', '--job-id', '8', '--raw', '--subdir', 'DAGS_FOLDER/flight_etl_dag.py', '--cfg-path', '/tmp/tmpdn930t7b']
[2025-07-11T16:00:59.430+0000] {standard_task_runner.py:88} INFO - Job 8: Subtask loading_data
[2025-07-11T16:00:59.503+0000] {task_command.py:423} INFO - Running <TaskInstance: flight_etl_dag.loading_data manual__2025-07-11T16:00:48.984577+00:00 [running]> on host faee04e61171
[2025-07-11T16:00:59.576+0000] {taskinstance.py:2480} INFO - Exporting env vars: AIRFLOW_CTX_DAG_OWNER='airflow' AIRFLOW_CTX_DAG_ID='flight_etl_dag' AIRFLOW_CTX_TASK_ID='loading_data' AIRFLOW_CTX_EXECUTION_DATE='2025-07-11T16:00:48.984577+00:00' AIRFLOW_CTX_TRY_NUMBER='1' AIRFLOW_CTX_DAG_RUN_ID='manual__2025-07-11T16:00:48.984577+00:00'
[2025-07-11T16:00:59.590+0000] {logging_mixin.py:188} INFO - Data to load:
[2025-07-11T16:00:59.593+0000] {taskinstance.py:2698} ERROR - Task failed with exception
Traceback (most recent call last):
  File "/home/airflow/.local/lib/python3.8/site-packages/airflow/models/taskinstance.py", line 433, in _execute_task
    result = execute_callable(context=context, **execute_callable_kwargs)
  File "/home/airflow/.local/lib/python3.8/site-packages/airflow/operators/python.py", line 199, in execute
    return_value = self.execute_callable()
  File "/home/airflow/.local/lib/python3.8/site-packages/airflow/operators/python.py", line 216, in execute_callable
    return self.python_callable(*self.op_args, **self.op_kwargs)
  File "/opt/airflow/load.py", line 14, in load_to_db
    print(df.head())
UnboundLocalError: local variable 'df' referenced before assignment
[2025-07-11T16:00:59.608+0000] {taskinstance.py:1138} INFO - Marking task as UP_FOR_RETRY. dag_id=flight_etl_dag, task_id=loading_data, execution_date=20250711T160048, start_date=20250711T160059, end_date=20250711T160059
[2025-07-11T16:00:59.623+0000] {standard_task_runner.py:107} ERROR - Failed to execute job 8 for task loading_data (local variable 'df' referenced before assignment; 93)
[2025-07-11T16:00:59.641+0000] {local_task_job_runner.py:234} INFO - Task exited with return code 1
[2025-07-11T16:00:59.657+0000] {taskinstance.py:3280} INFO - 0 downstream tasks scheduled from follow-on schedule check
