[2025-07-12T01:56:57.258+0000] {taskinstance.py:1956} INFO - Dependencies all met for dep_context=non-requeueable deps ti=<TaskInstance: flight_etl_dag.extracting_data manual__2025-07-12T01:56:54.663043+00:00 [queued]>
[2025-07-12T01:56:57.268+0000] {taskinstance.py:1956} INFO - Dependencies all met for dep_context=requeueable deps ti=<TaskInstance: flight_etl_dag.extracting_data manual__2025-07-12T01:56:54.663043+00:00 [queued]>
[2025-07-12T01:56:57.269+0000] {taskinstance.py:2170} INFO - Starting attempt 1 of 2
[2025-07-12T01:56:57.288+0000] {taskinstance.py:2191} INFO - Executing <Task(PythonOperator): extracting_data> on 2025-07-12 01:56:54.663043+00:00
[2025-07-12T01:56:57.295+0000] {standard_task_runner.py:60} INFO - Started process 114 to run task
[2025-07-12T01:56:57.300+0000] {standard_task_runner.py:87} INFO - Running: ['airflow', 'tasks', 'run', 'flight_etl_dag', 'extracting_data', 'manual__2025-07-12T01:56:54.663043+00:00', '--job-id', '7', '--raw', '--subdir', 'DAGS_FOLDER/flight_etl_dag.py', '--cfg-path', '/tmp/tmpqm7lg7nc']
[2025-07-12T01:56:57.302+0000] {standard_task_runner.py:88} INFO - Job 7: Subtask extracting_data
[2025-07-12T01:56:57.392+0000] {task_command.py:423} INFO - Running <TaskInstance: flight_etl_dag.extracting_data manual__2025-07-12T01:56:54.663043+00:00 [running]> on host b97efba67dd5
[2025-07-12T01:56:57.484+0000] {taskinstance.py:2480} INFO - Exporting env vars: AIRFLOW_CTX_DAG_OWNER='airflow' AIRFLOW_CTX_DAG_ID='flight_etl_dag' AIRFLOW_CTX_TASK_ID='extracting_data' AIRFLOW_CTX_EXECUTION_DATE='2025-07-12T01:56:54.663043+00:00' AIRFLOW_CTX_TRY_NUMBER='1' AIRFLOW_CTX_DAG_RUN_ID='manual__2025-07-12T01:56:54.663043+00:00'
[2025-07-12T01:56:58.159+0000] {taskinstance.py:2698} ERROR - Task failed with exception
Traceback (most recent call last):
  File "/home/airflow/.local/lib/python3.8/site-packages/airflow/models/taskinstance.py", line 433, in _execute_task
    result = execute_callable(context=context, **execute_callable_kwargs)
  File "/home/airflow/.local/lib/python3.8/site-packages/airflow/operators/python.py", line 199, in execute
    return_value = self.execute_callable()
  File "/home/airflow/.local/lib/python3.8/site-packages/airflow/operators/python.py", line 216, in execute_callable
    return self.python_callable(*self.op_args, **self.op_kwargs)
  File "/opt/airflow/extract.py", line 13, in extract
    raise ValueError(f"OpenSky API returned {response.status_code}")
ValueError: OpenSky API returned 429
[2025-07-12T01:56:58.176+0000] {taskinstance.py:1138} INFO - Marking task as UP_FOR_RETRY. dag_id=flight_etl_dag, task_id=extracting_data, execution_date=20250712T015654, start_date=20250712T015657, end_date=20250712T015658
[2025-07-12T01:56:58.196+0000] {standard_task_runner.py:107} ERROR - Failed to execute job 7 for task extracting_data (OpenSky API returned 429; 114)
[2025-07-12T01:56:58.236+0000] {local_task_job_runner.py:234} INFO - Task exited with return code 1
[2025-07-12T01:56:58.264+0000] {taskinstance.py:3280} INFO - 0 downstream tasks scheduled from follow-on schedule check
