[2025-07-11T15:37:28.101+0000] {taskinstance.py:1956} INFO - Dependencies all met for dep_context=non-requeueable deps ti=<TaskInstance: flight_etl_dag.loading_data scheduled__2025-07-10T00:00:00+00:00 [queued]>
[2025-07-11T15:37:28.112+0000] {taskinstance.py:1956} INFO - Dependencies all met for dep_context=requeueable deps ti=<TaskInstance: flight_etl_dag.loading_data scheduled__2025-07-10T00:00:00+00:00 [queued]>
[2025-07-11T15:37:28.113+0000] {taskinstance.py:2170} INFO - Starting attempt 2 of 2
[2025-07-11T15:37:28.128+0000] {taskinstance.py:2191} INFO - Executing <Task(PythonOperator): loading_data> on 2025-07-10 00:00:00+00:00
[2025-07-11T15:37:28.135+0000] {standard_task_runner.py:60} INFO - Started process 124 to run task
[2025-07-11T15:37:28.139+0000] {standard_task_runner.py:87} INFO - Running: ['airflow', 'tasks', 'run', 'flight_etl_dag', 'loading_data', 'scheduled__2025-07-10T00:00:00+00:00', '--job-id', '45', '--raw', '--subdir', 'DAGS_FOLDER/flight_etl_dag.py', '--cfg-path', '/tmp/tmp1ef9y670']
[2025-07-11T15:37:28.140+0000] {standard_task_runner.py:88} INFO - Job 45: Subtask loading_data
[2025-07-11T15:37:28.212+0000] {task_command.py:423} INFO - Running <TaskInstance: flight_etl_dag.loading_data scheduled__2025-07-10T00:00:00+00:00 [running]> on host c93b05155523
[2025-07-11T15:37:28.291+0000] {taskinstance.py:2480} INFO - Exporting env vars: AIRFLOW_CTX_DAG_OWNER='airflow' AIRFLOW_CTX_DAG_ID='flight_etl_dag' AIRFLOW_CTX_TASK_ID='loading_data' AIRFLOW_CTX_EXECUTION_DATE='2025-07-10T00:00:00+00:00' AIRFLOW_CTX_TRY_NUMBER='2' AIRFLOW_CTX_DAG_RUN_ID='scheduled__2025-07-10T00:00:00+00:00'
[2025-07-11T15:37:28.328+0000] {taskinstance.py:2698} ERROR - Task failed with exception
Traceback (most recent call last):
  File "/home/airflow/.local/lib/python3.8/site-packages/airflow/models/taskinstance.py", line 433, in _execute_task
    result = execute_callable(context=context, **execute_callable_kwargs)
  File "/home/airflow/.local/lib/python3.8/site-packages/airflow/operators/python.py", line 199, in execute
    return_value = self.execute_callable()
  File "/home/airflow/.local/lib/python3.8/site-packages/airflow/operators/python.py", line 216, in execute_callable
    return self.python_callable(*self.op_args, **self.op_kwargs)
  File "/opt/airflow/load.py", line 13, in load_to_db
    create_tables(conn)
TypeError: create_tables() takes 0 positional arguments but 1 was given
[2025-07-11T15:37:28.345+0000] {taskinstance.py:1138} INFO - Marking task as FAILED. dag_id=flight_etl_dag, task_id=loading_data, execution_date=20250710T000000, start_date=20250711T153728, end_date=20250711T153728
[2025-07-11T15:37:28.358+0000] {standard_task_runner.py:107} ERROR - Failed to execute job 45 for task loading_data (create_tables() takes 0 positional arguments but 1 was given; 124)
[2025-07-11T15:37:28.393+0000] {local_task_job_runner.py:234} INFO - Task exited with return code 1
[2025-07-11T15:37:28.409+0000] {taskinstance.py:3280} INFO - 0 downstream tasks scheduled from follow-on schedule check
[2025-07-11T16:02:02.260+0000] {taskinstance.py:1956} INFO - Dependencies all met for dep_context=non-requeueable deps ti=<TaskInstance: flight_etl_dag.loading_data scheduled__2025-07-10T00:00:00+00:00 [queued]>
[2025-07-11T16:02:02.282+0000] {taskinstance.py:1956} INFO - Dependencies all met for dep_context=requeueable deps ti=<TaskInstance: flight_etl_dag.loading_data scheduled__2025-07-10T00:00:00+00:00 [queued]>
[2025-07-11T16:02:02.287+0000] {taskinstance.py:2170} INFO - Starting attempt 2 of 2
[2025-07-11T16:02:02.317+0000] {taskinstance.py:2191} INFO - Executing <Task(PythonOperator): loading_data> on 2025-07-10 00:00:00+00:00
[2025-07-11T16:02:02.328+0000] {standard_task_runner.py:60} INFO - Started process 117 to run task
[2025-07-11T16:02:02.334+0000] {standard_task_runner.py:87} INFO - Running: ['airflow', 'tasks', 'run', 'flight_etl_dag', 'loading_data', 'scheduled__2025-07-10T00:00:00+00:00', '--job-id', '10', '--raw', '--subdir', 'DAGS_FOLDER/flight_etl_dag.py', '--cfg-path', '/tmp/tmp_n29x0o_']
[2025-07-11T16:02:02.336+0000] {standard_task_runner.py:88} INFO - Job 10: Subtask loading_data
[2025-07-11T16:02:02.448+0000] {task_command.py:423} INFO - Running <TaskInstance: flight_etl_dag.loading_data scheduled__2025-07-10T00:00:00+00:00 [running]> on host faee04e61171
[2025-07-11T16:02:02.547+0000] {taskinstance.py:2480} INFO - Exporting env vars: AIRFLOW_CTX_DAG_OWNER='airflow' AIRFLOW_CTX_DAG_ID='flight_etl_dag' AIRFLOW_CTX_TASK_ID='loading_data' AIRFLOW_CTX_EXECUTION_DATE='2025-07-10T00:00:00+00:00' AIRFLOW_CTX_TRY_NUMBER='2' AIRFLOW_CTX_DAG_RUN_ID='scheduled__2025-07-10T00:00:00+00:00'
[2025-07-11T16:02:02.599+0000] {logging_mixin.py:188} INFO - Data to load:
[2025-07-11T16:02:02.638+0000] {logging_mixin.py:188} INFO -   aircraft_id flight_number origin_country  ...  position_source      time       date
0      a34215                United States  ...            ADS-B  11:00:08 2025-07-11
1      39de42      TVF96ZB          France  ...            ADS-B  11:00:08 2025-07-11
2      3c5ee3                      Germany  ...            ADS-B  10:59:34 2025-07-11
3      a3428e                United States  ...            ADS-B  10:59:58 2025-07-11
4      4aca83                       Sweden  ...            ADS-B  10:58:35 2025-07-11

[5 rows x 11 columns]
[2025-07-11T16:02:02.700+0000] {logging_mixin.py:188} INFO - Tables created successfully.
[2025-07-11T16:02:02.952+0000] {python.py:201} INFO - Done. Returned value was: None
[2025-07-11T16:02:02.966+0000] {taskinstance.py:1138} INFO - Marking task as SUCCESS. dag_id=flight_etl_dag, task_id=loading_data, execution_date=20250710T000000, start_date=20250711T160202, end_date=20250711T160202
[2025-07-11T16:02:03.031+0000] {local_task_job_runner.py:234} INFO - Task exited with return code 0
[2025-07-11T16:02:03.105+0000] {taskinstance.py:3280} INFO - 0 downstream tasks scheduled from follow-on schedule check
