[2025-07-08T22:56:14.757+0000] {taskinstance.py:1956} INFO - Dependencies all met for dep_context=non-requeueable deps ti=<TaskInstance: flight_etl_dag.loading_data manual__2025-07-08T22:54:15.587647+00:00 [queued]>
[2025-07-08T22:56:14.767+0000] {taskinstance.py:1956} INFO - Dependencies all met for dep_context=requeueable deps ti=<TaskInstance: flight_etl_dag.loading_data manual__2025-07-08T22:54:15.587647+00:00 [queued]>
[2025-07-08T22:56:14.768+0000] {taskinstance.py:2170} INFO - Starting attempt 2 of 2
[2025-07-08T22:56:14.787+0000] {taskinstance.py:2191} INFO - Executing <Task(PythonOperator): loading_data> on 2025-07-08 22:54:15.587647+00:00
[2025-07-08T22:56:14.793+0000] {standard_task_runner.py:60} INFO - Started process 135 to run task
[2025-07-08T22:56:14.798+0000] {standard_task_runner.py:87} INFO - Running: ['***', 'tasks', 'run', 'flight_etl_dag', 'loading_data', 'manual__2025-07-08T22:54:15.587647+00:00', '--job-id', '35', '--raw', '--subdir', 'DAGS_FOLDER/flight_etl_dag.py', '--cfg-path', '/tmp/tmpbm_nj046']
[2025-07-08T22:56:14.801+0000] {standard_task_runner.py:88} INFO - Job 35: Subtask loading_data
[2025-07-08T22:56:14.931+0000] {task_command.py:423} INFO - Running <TaskInstance: flight_etl_dag.loading_data manual__2025-07-08T22:54:15.587647+00:00 [running]> on host d9b176541658
[2025-07-08T22:56:15.076+0000] {taskinstance.py:2480} INFO - Exporting env vars: AIRFLOW_CTX_DAG_OWNER='***' AIRFLOW_CTX_DAG_ID='flight_etl_dag' AIRFLOW_CTX_TASK_ID='loading_data' AIRFLOW_CTX_EXECUTION_DATE='2025-07-08T22:54:15.587647+00:00' AIRFLOW_CTX_TRY_NUMBER='2' AIRFLOW_CTX_DAG_RUN_ID='manual__2025-07-08T22:54:15.587647+00:00'
[2025-07-08T22:56:15.080+0000] {taskinstance.py:2698} ERROR - Task failed with exception
Traceback (most recent call last):
  File "/home/airflow/.local/lib/python3.8/site-packages/airflow/models/taskinstance.py", line 433, in _execute_task
    result = execute_callable(context=context, **execute_callable_kwargs)
  File "/home/airflow/.local/lib/python3.8/site-packages/airflow/operators/python.py", line 199, in execute
    return_value = self.execute_callable()
  File "/home/airflow/.local/lib/python3.8/site-packages/airflow/operators/python.py", line 216, in execute_callable
    return self.python_callable(*self.op_args, **self.op_kwargs)
TypeError: load_to_db() missing 1 required positional argument: 'df'
[2025-07-08T22:56:15.095+0000] {taskinstance.py:1138} INFO - Marking task as FAILED. dag_id=flight_etl_dag, task_id=loading_data, execution_date=20250708T225415, start_date=20250708T225614, end_date=20250708T225615
[2025-07-08T22:56:15.123+0000] {standard_task_runner.py:107} ERROR - Failed to execute job 35 for task loading_data (load_to_db() missing 1 required positional argument: 'df'; 135)
[2025-07-08T22:56:15.173+0000] {local_task_job_runner.py:234} INFO - Task exited with return code 1
[2025-07-08T22:56:15.205+0000] {taskinstance.py:3280} INFO - 0 downstream tasks scheduled from follow-on schedule check
